
# Created by Ruins mod version 17.1 Ingame Parser
# authoring Player: Willfon


weight=100
embed_into_distance=1
random_height_offset=0,0
# whitelist/blacklist of block types on which template may be built
# specify one, not both; leave the other empty (both empty = allow all)
acceptable_target_blocks=
unacceptable_target_blocks=flowing_water,water,flowing_lava,lava
# size of template (#layers, #rows per layer, #blocks per row)
dimensions=9,35,17
# max number of missing blocks allowed in surface beneath template
allowable_overhang=5
# depth/height limit affected by terrain leveling
# also maximum bumpiness tolerated in surface beneath template
max_leveling=10
# padding applied to all sides of template horizontal footprint
# expands area affected by terrain leveling (-1 = no leveling)
leveling_buffer=10
# do not rotate template randomly when built (1 = no rotation)
preventRotation=0
# treat water/lava blocks as air and protect them from rule0 (1 = yes)
preserve_water=0
preserve_lava=0
preserve_plants=0
# minimum distance this template must have from instances of itself
uniqueMinDistance=1000
# min/max distances this template can be from world spawn (0 = no limit)
# only applies to overworld--i.e., dimension 0
spawnMinDistance=0
spawnMaxDistance=0
# other template built nearby whenever this one is
# syntax: <name>;<relativeX>;<maxYdifference>;<relativeZ>[;<chance>]
# may be used more than once to specify multiple neighbors
adjoining_template=

rule1=0,100,minecraft:stone-5
rule2=0,100,minecraft:stone-6
rule3=0,100,MobSpawner:Skeleton,MobSpawner:Zombie,MobSpawner:Spider,minecraft:stone-6,ChestGenHook:chests/simple_dungeon:5-4
rule4=0,100,minecraft:jukebox-0
rule5=0,100,minecraft:sand-0
rule6=0,100,minecraft:stone_slab-0
rule7=0,100,minecraft:concrete-0
rule8=0,100,minecraft:quartz_stairs-3
rule9=0,100,minecraft:quartz_stairs-5
rule10=0,100,IInventory;minecraft:furnace;minecraft:coal#1#0#1+minecraft:coal#1#1#2,IInventory;minecraft:furnace;minecraft:coal#1#1#2,IInventory;minecraft:furnace;minecraft:coal#2#1#2-5
rule11=0,100,minecraft:acacia_stairs-5
rule12=0,100,minecraft:quartz_stairs-6
rule13=0,100,minecraft:trapdoor-11
rule14=0,100,minecraft:double_stone_slab-7
rule15=0,100,minecraft:iron_bars-0
rule16=0,100,minecraft:quartz_stairs-4
rule17=0,100,minecraft:quartz_stairs-2
rule18=0,100,minecraft:quartz_stairs-0
rule19=0,100,minecraft:acacia_door-6
rule20=0,100,minecraft:double_stone_slab-0
rule21=0,100,minecraft:stained_glass_pane-8
rule22=0,100,ChestGenHook:chests/simple_dungeon:5-5
rule23=0,100,teBlock;minecraft:wall_banner;{x:0,y:0,z:0,id:"minecraft:banner",Patterns:[{Pattern:"gra",Color:0},{Pattern:"flo",Color:15},{Pattern:"moj",Color:15},{Pattern:"sku",Color:15},{Pattern:"mc",Color:11}],Base:8}-5
rule24=0,100,teBlock;minecraft:wall_banner;{x:0,y:0,z:0,id:"minecraft:banner",Patterns:[{Pattern:"gra",Color:0},{Pattern:"flo",Color:15},{Pattern:"moj",Color:15},{Pattern:"sku",Color:15},{Pattern:"mc",Color:11}],Base:8}-4
rule25=0,100,minecraft:acacia_door-9
rule26=0,100,teBlock;minecraft:wall_banner;{x:0,y:0,z:0,id:"minecraft:banner",Patterns:[{Pattern:"gra",Color:0},{Pattern:"flo",Color:15},{Pattern:"moj",Color:15},{Pattern:"sku",Color:15},{Pattern:"mc",Color:11}],Base:8}-2
rule27=0,100,minecraft:nether_brick_fence-0
rule28=0,100,IInventory;minecraft:dropper;minecraft:paper#7#0#0-2
rule29=0,100,teBlock;minecraft:wall_banner;{x:0,y:0,z:0,id:"minecraft:banner",Patterns:[{Pattern:"gra",Color:0},{Pattern:"flo",Color:15},{Pattern:"moj",Color:15},{Pattern:"sku",Color:15},{Pattern:"mc",Color:11}],Base:8}-3
rule30=0,100,minecraft:quartz_stairs-7
rule31=0,100,minecraft:quartz_stairs-1
rule32=0,100,minecraft:wooden_slab-12
rule33=0,100,minecraft:lime_glazed_terracotta-0
rule34=0,100,minecraft:lime_glazed_terracotta-3
rule35=0,100,minecraft:air,sea_lantern-0
rule36=0,100,minecraft:stone_slab-7
rule37=0,100,minecraft:concrete-5
rule38=0,100,minecraft:lime_glazed_terracotta-2
rule39=0,100,teBlock;minecraft:wall_banner;{x:0,y:0,z:0,id:"minecraft:banner",Patterns:[{Pattern:"gru",Color:4},{Pattern:"gra",Color:5},{Pattern:"flo",Color:11},{Pattern:"mc",Color:14}],Base:15}-2
rule40=0,100,teBlock;minecraft:wall_banner;{x:0,y:0,z:0,id:"minecraft:banner",Patterns:[{Pattern:"gru",Color:4},{Pattern:"gra",Color:5},{Pattern:"flo",Color:11},{Pattern:"mc",Color:14}],Base:15}-3
rule41=0,100,teBlock;minecraft:wall_banner;{x:0,y:0,z:0,id:"minecraft:banner",Patterns:[{Pattern:"gru",Color:4},{Pattern:"gra",Color:5},{Pattern:"flo",Color:11},{Pattern:"mc",Color:14}],Base:15}-4
rule42=0,100,teBlock;minecraft:wall_banner;{x:0,y:0,z:0,id:"minecraft:banner",Patterns:[{Pattern:"gru",Color:4},{Pattern:"gra",Color:5},{Pattern:"flo",Color:11},{Pattern:"mc",Color:14}],Base:15}-5
rule43=0,100,MobSpawner:Skeleton,MobSpawner:Zombie,MobSpawner:Spider,minecraft:stone-6,minecraft:stone-6
rule44=2,100,minecraft:stone_button-1
rule45=2,100,minecraft:stone_button-2
rule46=0,100,minecraft:stained_glass-1,minecraft:stained_glass-7,IInventory;minecraft:chest;minecraft:rotten_flesh#4#0#0+minecraft:paper#2#0#0-5,IInventory;minecraft:chest;minecraft:rotten_flesh#1#0#0+minecraft:paper#1#0#1+minecraft:poisonous_potato#1#0#2+minecraft:string#1#0#3+minecraft:glass_bottle#1#0#4-5,IInventory;minecraft:chest;minecraft:rotten_flesh#2#0#0+minecraft:paper#1#0#1+minecraft:bone#1#0#2+minecraft:string#1#0#3+minecraft:potion#{Potion:"minecraft:water"}#0#5+minecraft:potion#{Potion:"minecraft:awkward"}#0#7-5
rule47=0,100,minecraft:stone_slab-7,air



# rule46=0,100,IInventory;minecraft:chest;minecraft:rotten_flesh#4#0#0+minecraft:paper#2#0#0-5
# rule47=0,100,IInventory;minecraft:chest;minecraft:rotten_flesh#1#0#0+minecraft:paper#1#0#1+minecraft:poisonous_potato#1#0#2+minecraft:string#1#0#3+minecraft:glass_bottle#1#0#4-5
# rule48=0,100,IInventory;minecraft:chest;minecraft:rotten_flesh#2#0#0+minecraft:paper#1#0#1+minecraft:bone#1#0#2+minecraft:string#1#0#3+minecraft:potion#{Potion:"minecraft:water"}#0#5+minecraft:potion#{Potion:"minecraft:awkward"}#0#7-5



layer
1,1,1,1,1,1,1,1,1,1,1,1,1,1,1,1,1
1,1,1,1,1,1,1,1,1,1,1,1,1,1,1,1,1
1,1,1,1,1,1,1,1,1,1,1,1,1,1,1,1,1
1,1,1,1,1,1,1,1,1,1,1,1,1,1,1,1,1
1,1,1,1,1,1,1,1,1,1,1,1,1,1,1,1,1
1,1,1,1,2,2,2,2,2,2,2,2,2,1,1,1,1
1,1,1,1,2,2,2,2,2,2,2,2,2,1,1,1,1
1,1,1,1,2,2,2,2,2,2,2,2,2,1,1,1,1
1,1,1,1,2,2,2,2,2,3,4,3,2,1,1,1,1
1,1,1,1,2,2,2,2,2,2,2,2,2,1,1,1,1
1,1,1,1,2,2,2,2,2,2,2,2,2,1,1,1,1
1,1,1,1,2,2,2,2,2,2,2,2,2,1,1,1,1
1,1,1,1,2,2,2,2,2,2,2,2,2,1,1,1,1
1,1,1,1,2,2,2,2,2,2,2,2,2,1,1,1,1
1,1,1,1,1,1,1,1,1,1,1,1,1,1,1,1,1
1,1,1,1,1,1,1,1,1,1,1,1,1,1,1,1,1
1,1,1,1,1,1,1,1,1,1,1,1,1,1,1,1,1
1,1,1,1,1,1,1,1,1,1,1,1,1,1,1,1,1
1,1,1,1,1,1,1,1,1,1,1,1,1,1,1,1,1
1,1,1,1,1,1,1,1,1,1,1,1,1,1,1,1,1
1,1,1,1,1,1,1,1,1,1,1,1,1,1,1,1,1
1,1,1,1,1,1,1,1,1,1,1,1,1,1,1,1,1
1,1,1,1,1,1,1,1,1,1,1,1,1,1,1,1,1
1,1,1,1,1,1,1,1,1,1,1,1,1,1,1,1,1
1,1,1,1,1,1,1,1,1,1,1,1,1,1,1,1,1
1,1,1,1,1,1,1,1,1,1,1,1,1,1,1,1,1
1,1,1,1,1,1,1,1,1,1,1,1,1,1,1,1,1
1,1,1,1,1,1,1,1,1,1,1,1,1,1,1,1,1
1,1,1,1,1,1,1,1,1,1,1,1,1,1,1,1,1
1,1,1,1,1,1,1,1,1,1,1,1,1,1,1,1,1
1,1,1,1,1,1,1,1,1,1,1,1,1,1,1,1,1
1,1,1,1,1,1,1,1,1,1,1,1,1,1,1,1,1
1,1,1,1,1,1,1,1,1,1,1,1,1,1,1,1,1
5,5,1,1,1,1,5,5,5,5,5,1,1,1,1,5,5
5,5,1,1,1,1,5,5,5,5,5,1,1,1,1,5,5
endlayer

layer
6,6,6,6,6,6,6,6,6,6,6,6,6,6,6,6,6
6,0,0,0,0,0,0,0,0,0,0,0,0,0,0,0,6
6,0,0,0,0,0,0,0,0,0,0,0,0,0,0,0,6
6,0,0,0,0,0,0,0,0,0,0,0,0,0,0,0,6
6,0,0,0,7,7,7,7,7,7,7,7,7,0,0,0,6
6,0,0,0,14,13,13,12,0,11,10,9,14,0,0,0,6
6,0,0,0,14,15,0,12,0,0,0,0,8,0,0,0,6
6,0,0,0,14,0,0,0,0,0,0,0,8,0,0,0,6
6,0,0,0,7,0,0,14,16,16,16,16,7,0,0,0,6
6,0,0,0,17,0,0,0,0,0,0,0,8,0,0,0,6
6,0,0,0,17,0,0,0,0,0,0,0,8,0,0,0,6
6,0,0,0,17,0,0,0,0,0,0,0,8,0,0,0,6
6,0,0,0,17,0,0,0,0,0,0,0,8,0,0,0,6
6,0,0,0,7,18,18,7,19,7,18,18,7,0,0,0,6
6,0,0,0,0,0,0,0,0,0,0,0,0,0,0,0,6
6,0,0,0,0,0,0,0,0,0,0,0,0,0,0,0,6
6,0,0,0,0,0,0,0,0,0,0,0,0,0,0,0,6
6,0,0,0,0,0,0,0,0,0,0,0,0,0,0,0,6
6,0,0,0,0,0,0,0,0,0,0,0,0,0,0,0,6
6,0,0,0,0,0,20,6,20,6,20,0,0,0,0,0,6
6,0,0,0,0,0,0,0,0,0,0,0,0,0,0,0,6
6,0,0,0,0,0,0,0,0,0,0,0,0,0,0,0,6
6,0,0,0,0,0,0,0,0,0,0,0,0,0,0,0,6
6,0,0,0,0,0,0,0,0,0,0,0,0,0,0,0,6
6,0,0,0,0,0,0,0,0,0,0,0,0,0,0,0,6
6,0,0,0,0,0,20,6,20,6,20,0,0,0,0,0,6
6,0,0,0,0,0,0,0,0,0,0,0,0,0,0,0,6
6,0,0,0,0,0,0,0,0,0,0,0,0,0,0,0,6
6,0,0,0,0,0,0,0,0,0,0,0,0,0,0,0,20
6,0,0,0,0,0,0,0,0,0,0,0,0,0,0,0,20
6,0,0,0,0,0,0,0,0,0,0,0,0,0,0,0,6
6,0,0,0,0,0,0,0,0,0,0,0,0,0,0,0,6
6,6,0,0,0,0,0,0,0,0,0,0,0,0,0,6,6
0,0,0,0,0,0,0,0,0,0,0,0,0,0,0,0,0
0,0,0,0,0,0,0,0,0,0,0,0,0,0,0,0,0
endlayer

layer
0,0,0,0,0,0,0,0,0,0,0,0,0,0,0,0,0
0,0,0,0,0,0,0,0,0,0,0,0,0,0,0,0,0
0,0,0,0,0,0,0,0,0,0,0,0,0,0,0,0,0
0,0,0,0,0,0,0,0,0,0,0,0,0,0,0,0,0
0,0,0,0,7,21,21,21,21,7,7,21,7,0,0,0,0
0,0,0,0,21,0,0,0,0,46,0,0,21,0,0,0,0
0,0,0,0,21,0,0,15,0,0,0,0,21,0,0,0,0
0,0,0,0,21,0,0,0,0,0,0,0,21,0,0,0,0
0,0,0,0,7,0,0,15,0,0,0,15,7,0,0,0,0
0,0,0,0,21,0,0,23,0,0,0,42,21,0,0,0,0
0,0,0,0,21,0,0,0,0,0,0,0,21,0,0,0,0
0,0,0,0,21,0,0,0,0,0,0,0,21,0,0,0,0
0,0,0,0,21,0,0,24,0,41,0,0,21,0,0,0,0
0,0,0,0,7,21,21,7,25,7,21,21,7,0,0,0,0
0,0,0,0,23,0,0,42,0,23,0,0,42,0,0,0,0
0,0,0,0,0,0,0,0,0,0,0,0,0,0,0,0,0
0,0,0,0,0,0,0,0,0,0,0,0,0,0,0,0,0
0,0,0,0,0,0,0,0,0,0,0,0,0,0,0,0,0
0,0,0,0,0,0,0,0,45,0,0,0,0,0,0,0,0
0,0,0,0,0,29,27,15,28,0,27,39,0,0,0,0,0
0,0,0,0,0,0,0,0,44,0,0,0,0,0,0,0,0
0,0,0,0,0,0,0,0,0,0,0,0,0,0,0,0,0
0,0,0,0,0,0,0,0,0,0,0,0,0,0,0,0,0
0,0,0,0,0,0,0,0,0,0,0,0,0,0,0,0,0
0,0,0,0,0,0,0,0,45,0,0,0,0,0,0,0,0
0,0,0,0,0,29,27,15,28,0,27,39,0,0,0,0,0
0,0,0,0,0,0,0,0,44,0,0,0,0,0,0,0,0
0,0,0,0,0,0,0,0,0,0,0,0,0,0,0,0,0
0,0,0,0,0,0,0,0,0,0,0,0,0,0,0,0,27
0,0,0,0,0,0,0,0,0,0,0,0,0,0,0,0,27
0,0,0,0,0,0,0,0,0,0,0,0,0,0,0,0,0
0,0,0,0,0,0,0,0,0,0,0,0,0,0,0,0,0
0,0,0,0,0,0,0,0,0,0,0,0,0,0,0,0,0
0,0,0,0,0,0,0,0,0,0,0,0,0,0,0,0,0
0,0,0,0,0,0,0,0,0,0,0,0,0,0,0,0,0
endlayer

layer
0,0,0,0,0,0,0,0,0,0,0,0,0,0,0,0,0
0,0,0,0,0,0,0,0,0,0,0,0,0,0,0,0,0
0,0,0,0,0,0,0,0,0,0,0,0,0,0,0,0,0
0,0,0,0,0,0,0,0,0,0,0,0,0,0,0,0,0
0,0,0,0,7,7,7,7,7,7,7,7,7,0,0,0,0
0,0,0,0,12,0,0,32,0,11,31,31,30,0,0,0,0
0,0,0,0,12,0,0,33,0,0,0,0,30,0,0,0,0
0,0,0,0,12,0,0,32,0,0,0,0,30,0,0,0,0
0,0,0,0,7,0,0,34,32,32,32,33,7,0,0,0,0
0,0,0,0,12,0,0,0,0,0,0,0,30,0,0,0,0
0,0,0,0,12,0,0,0,0,0,0,0,30,0,0,0,0
0,0,0,0,12,0,0,0,0,0,0,0,30,0,0,0,0
0,0,0,0,12,0,0,0,0,0,0,0,30,0,0,0,0
0,0,0,0,33,35,35,33,38,34,35,35,34,0,0,0,0
0,0,0,0,0,0,0,0,0,0,0,0,0,0,0,0,0
0,0,0,0,0,0,0,0,0,0,0,0,0,0,0,0,0
0,0,0,0,0,0,0,0,0,0,0,0,0,0,0,0,0
0,0,0,0,0,0,0,0,0,0,0,0,0,0,0,0,0
0,0,0,0,0,0,0,0,0,0,0,0,0,0,0,0,0
0,0,0,0,0,0,27,0,0,0,27,0,0,0,0,0,0
0,0,0,0,0,0,0,0,0,0,0,0,0,0,0,0,0
0,0,0,0,0,0,0,0,0,0,0,0,0,0,0,0,0
0,0,0,0,0,0,0,0,0,0,0,0,0,0,0,0,0
0,0,0,0,0,0,0,0,0,0,0,0,0,0,0,0,0
0,0,0,0,0,0,0,0,0,0,0,0,0,0,0,0,0
0,0,0,0,0,0,27,0,0,0,27,0,0,0,0,0,0
0,0,0,0,0,0,0,0,0,0,0,0,0,0,0,0,0
0,0,0,0,0,0,0,0,0,0,0,0,0,0,0,0,0
0,0,0,0,0,0,0,0,0,0,0,0,0,0,0,0,27
0,0,0,0,0,0,0,0,0,0,0,0,0,0,0,0,27
0,0,0,0,0,0,0,0,0,0,0,0,0,0,0,0,0
0,0,0,0,0,0,0,0,0,0,0,0,0,0,0,0,0
0,0,0,0,0,0,0,0,0,0,0,0,0,0,0,0,0
0,0,0,0,0,0,0,0,0,0,0,0,0,0,0,0,0
0,0,0,0,0,0,0,0,0,0,0,0,0,0,0,0,0
endlayer

layer
0,0,0,0,0,0,0,0,0,0,0,0,0,0,0,0,0
0,0,0,0,0,0,0,0,0,0,0,0,0,0,0,0,0
0,0,0,0,0,0,0,0,0,0,0,0,0,0,0,0,0
0,0,0,0,0,0,0,0,0,0,0,0,0,0,0,0,0
0,0,0,0,36,36,36,36,36,36,36,36,36,0,0,0,0
0,0,0,0,36,36,36,36,36,36,36,36,36,0,0,0,0
0,0,0,0,36,36,35,36,36,36,35,47,36,0,0,0,0
0,0,0,0,36,47,36,36,36,36,36,36,36,0,0,0,0
0,0,0,0,36,36,36,36,36,36,36,36,36,0,0,0,0
0,0,0,0,36,36,36,36,47,36,36,36,36,0,0,0,0
0,0,0,0,36,36,36,36,36,36,36,36,36,0,0,0,0
0,0,0,0,36,36,47,36,36,36,35,36,36,0,0,0,0
0,0,0,0,36,36,36,36,36,36,36,36,36,0,0,0,0
0,0,0,0,36,36,36,36,36,36,36,36,36,0,0,0,0
0,0,0,0,0,0,0,0,0,0,0,0,0,0,0,0,0
0,0,0,0,0,0,0,0,0,0,0,0,0,0,0,0,0
0,0,0,0,0,0,0,0,0,0,0,0,0,0,0,0,0
0,0,0,0,0,0,0,0,0,0,0,0,0,0,0,0,0
0,0,0,0,0,0,0,0,0,0,0,0,0,0,0,0,0
0,0,0,0,0,0,27,0,0,0,27,0,0,0,0,0,0
0,0,0,0,0,0,0,0,0,0,0,0,0,0,0,0,0
0,0,0,0,0,0,0,0,0,0,0,0,0,0,0,0,0
0,0,0,0,0,0,0,0,0,0,0,0,0,0,0,0,0
0,0,0,0,0,0,0,0,0,0,0,0,0,0,0,0,0
0,0,0,0,0,0,0,0,0,0,0,0,0,0,0,0,0
0,0,0,0,0,0,27,0,0,0,27,0,0,0,0,0,0
0,0,0,0,0,0,0,0,0,0,0,0,0,0,0,0,0
0,0,0,0,0,0,0,0,0,0,0,0,0,0,0,0,0
0,0,0,0,0,0,0,0,0,0,0,0,0,0,0,0,27
0,0,0,0,0,0,0,0,0,0,0,0,0,0,0,0,27
0,0,0,0,0,0,0,0,0,0,0,0,0,0,0,0,0
0,0,0,0,0,0,0,0,0,0,0,0,0,0,0,0,0
0,0,0,0,0,0,0,0,0,0,0,0,0,0,0,0,0
0,0,0,0,0,0,0,0,0,0,0,0,0,0,0,0,0
0,0,0,0,0,0,0,0,0,0,0,0,0,0,0,0,0
endlayer

layer
0,0,0,0,0,0,0,0,0,0,0,0,0,0,0,0,0
0,0,0,0,0,0,0,0,0,0,0,0,0,0,0,0,0
0,0,0,0,0,0,0,0,0,0,0,0,0,0,0,0,0
0,0,0,0,0,0,0,0,0,0,0,0,0,0,0,0,0
0,0,0,0,0,0,0,0,0,0,0,0,0,0,0,0,0
0,0,0,0,0,0,0,0,0,0,0,0,0,0,0,0,0
0,0,0,0,0,0,0,0,0,0,0,0,0,0,0,0,0
0,0,0,0,0,0,0,0,0,0,0,0,0,0,0,0,0
0,0,0,0,0,0,0,0,0,0,0,0,0,0,0,0,0
0,0,0,0,0,0,0,0,0,0,0,0,0,0,0,0,0
0,0,0,0,0,0,0,0,0,0,0,0,0,0,0,0,0
0,0,0,0,0,0,0,0,0,0,0,0,0,0,0,0,0
0,0,0,0,0,0,0,0,0,0,0,0,0,0,0,0,0
0,0,0,0,0,0,0,0,0,0,0,0,0,0,0,0,0
0,0,0,0,0,0,0,0,0,0,0,0,0,0,0,0,0
0,0,0,0,0,0,0,0,0,0,0,0,0,0,0,0,0
0,0,0,0,0,0,0,0,0,0,0,0,0,0,0,0,0
0,0,0,0,0,47,47,47,47,47,47,36,47,0,0,0,0
0,0,0,0,0,36,36,36,36,36,36,36,47,0,0,0,0
0,0,0,0,0,47,36,36,35,36,36,36,47,0,0,0,0
0,0,0,0,0,47,36,36,36,36,36,36,47,0,0,0,0
0,0,0,0,0,47,36,36,36,36,36,36,47,0,0,0,0
0,0,0,0,0,47,36,36,36,36,36,36,47,0,0,0,0
0,0,0,0,0,47,36,36,36,36,36,36,47,0,0,0,0
0,0,0,0,0,47,36,36,36,36,36,36,47,0,0,0,0
0,0,0,0,0,47,36,36,35,36,36,36,47,0,0,0,0
0,0,0,0,0,36,36,36,36,36,36,36,36,0,0,0,0
0,0,0,0,0,47,47,47,47,47,47,47,47,0,0,0,0
0,0,0,0,0,0,0,0,0,0,0,0,0,0,0,0,37
0,0,0,0,0,0,0,0,0,0,0,0,0,0,0,0,37
0,0,0,0,0,0,0,0,0,0,0,0,0,0,0,0,0
0,0,0,0,0,0,0,0,0,0,0,0,0,0,0,0,0
0,0,0,0,0,0,0,0,0,0,0,0,0,0,0,0,0
0,0,0,0,0,0,0,0,0,0,0,0,0,0,0,0,0
0,0,0,0,0,0,0,0,0,0,0,0,0,0,0,0,0
endlayer

layer
0,0,0,0,0,0,0,0,0,0,0,0,0,0,0,0,0
0,0,0,0,0,0,0,0,0,0,0,0,0,0,0,0,0
0,0,0,0,0,0,0,0,0,0,0,0,0,0,0,0,0
0,0,0,0,0,0,0,0,0,0,0,0,0,0,0,0,0
0,0,0,0,0,0,0,0,0,0,0,0,0,0,0,0,0
0,0,0,0,0,0,0,0,0,0,0,0,0,0,0,0,0
0,0,0,0,0,0,0,0,0,0,0,0,0,0,0,0,0
0,0,0,0,0,0,0,0,0,0,0,0,0,0,0,0,0
0,0,0,0,0,0,0,0,0,0,0,0,0,0,0,0,0
0,0,0,0,0,0,0,0,0,0,0,0,0,0,0,0,0
0,0,0,0,0,0,0,0,0,0,0,0,0,0,0,0,0
0,0,0,0,0,0,0,0,0,0,0,0,0,0,0,0,0
0,0,0,0,0,0,0,0,0,0,0,0,0,0,0,0,0
0,0,0,0,0,0,0,0,0,0,0,0,0,0,0,0,0
0,0,0,0,0,0,0,0,0,0,0,0,0,0,0,0,0
0,0,0,0,0,0,0,0,0,0,0,0,0,0,0,0,0
0,0,0,0,0,0,0,0,0,0,0,0,0,0,0,0,0
0,0,0,0,0,0,0,0,0,0,0,0,0,0,0,0,0
0,0,0,0,0,0,0,0,0,0,0,0,0,0,0,0,0
0,0,0,0,0,0,0,0,0,0,0,0,0,0,0,0,0
0,0,0,0,0,0,0,0,0,0,0,0,0,0,0,0,0
0,0,0,0,0,0,0,0,0,0,0,0,0,0,0,0,0
0,0,0,0,0,0,0,0,0,0,0,0,0,0,0,0,0
0,0,0,0,0,0,0,0,0,0,0,0,0,0,0,0,0
0,0,0,0,0,0,0,0,0,0,0,0,0,0,0,0,0
0,0,0,0,0,0,0,0,0,0,0,0,0,0,0,0,0
0,0,0,0,0,0,0,0,0,0,0,0,0,0,0,0,0
0,0,0,0,0,0,0,0,0,0,0,0,0,0,0,0,0
0,0,0,0,0,0,0,0,0,0,0,0,0,0,0,0,37
0,0,0,0,0,0,0,0,0,0,0,0,0,0,0,0,37
0,0,0,0,0,0,0,0,0,0,0,0,0,0,0,0,0
0,0,0,0,0,0,0,0,0,0,0,0,0,0,0,0,0
0,0,0,0,0,0,0,0,0,0,0,0,0,0,0,0,0
0,0,0,0,0,0,0,0,0,0,0,0,0,0,0,0,0
0,0,0,0,0,0,0,0,0,0,0,0,0,0,0,0,0
endlayer

layer
0,0,0,0,0,0,0,0,0,0,0,0,0,0,0,0,0
0,0,0,0,0,0,0,0,0,0,0,0,0,0,0,0,0
0,0,0,0,0,0,0,0,0,0,0,0,0,0,0,0,0
0,0,0,0,0,0,0,0,0,0,0,0,0,0,0,0,0
0,0,0,0,0,0,0,0,0,0,0,0,0,0,0,0,0
0,0,0,0,0,0,0,0,0,0,0,0,0,0,0,0,0
0,0,0,0,0,0,0,0,0,0,0,0,0,0,0,0,0
0,0,0,0,0,0,0,0,0,0,0,0,0,0,0,0,0
0,0,0,0,0,0,0,0,0,0,0,0,0,0,0,0,0
0,0,0,0,0,0,0,0,0,0,0,0,0,0,0,0,0
0,0,0,0,0,0,0,0,0,0,0,0,0,0,0,0,0
0,0,0,0,0,0,0,0,0,0,0,0,0,0,0,0,0
0,0,0,0,0,0,0,0,0,0,0,0,0,0,0,0,0
0,0,0,0,0,0,0,0,0,0,0,0,0,0,0,0,0
0,0,0,0,0,0,0,0,0,0,0,0,0,0,0,0,0
0,0,0,0,0,0,0,0,0,0,0,0,0,0,0,0,0
0,0,0,0,0,0,0,0,0,0,0,0,0,0,0,0,0
0,0,0,0,0,0,0,0,0,0,0,0,0,0,0,0,0
0,0,0,0,0,0,0,0,0,0,0,0,0,0,0,0,0
0,0,0,0,0,0,0,0,0,0,0,0,0,0,0,0,0
0,0,0,0,0,0,0,0,0,0,0,0,0,0,0,0,0
0,0,0,0,0,0,0,0,0,0,0,0,0,0,0,0,0
0,0,0,0,0,0,0,0,0,0,0,0,0,0,0,0,0
0,0,0,0,0,0,0,0,0,0,0,0,0,0,0,0,0
0,0,0,0,0,0,0,0,0,0,0,0,0,0,0,0,0
0,0,0,0,0,0,0,0,0,0,0,0,0,0,0,0,0
0,0,0,0,0,0,0,0,0,0,0,0,0,0,0,0,0
0,0,0,0,0,0,0,0,0,0,0,0,0,0,0,0,0
0,0,0,0,0,0,0,0,0,0,0,0,0,0,0,0,38
0,0,0,0,0,0,0,0,0,0,0,0,0,0,0,0,38
0,0,0,0,0,0,0,0,0,0,0,0,0,0,0,0,0
0,0,0,0,0,0,0,0,0,0,0,0,0,0,0,0,0
0,0,0,0,0,0,0,0,0,0,0,0,0,0,0,0,0
0,0,0,0,0,0,0,0,0,0,0,0,0,0,0,0,0
0,0,0,0,0,0,0,0,0,0,0,0,0,0,0,0,0
endlayer

layer
0,0,0,0,0,0,0,0,0,0,0,0,0,0,0,0,0
0,0,0,0,0,0,0,0,0,0,0,0,0,0,0,0,0
0,0,0,0,0,0,0,0,0,0,0,0,0,0,0,0,0
0,0,0,0,0,0,0,0,0,0,0,0,0,0,0,0,0
0,0,0,0,0,0,0,0,0,0,0,0,0,0,0,0,0
0,0,0,0,0,0,0,0,0,0,0,0,0,0,0,0,0
0,0,0,0,0,0,0,0,0,0,0,0,0,0,0,0,0
0,0,0,0,0,0,0,0,0,0,0,0,0,0,0,0,0
0,0,0,0,0,0,0,0,0,0,0,0,0,0,0,0,0
0,0,0,0,0,0,0,0,0,0,0,0,0,0,0,0,0
0,0,0,0,0,0,0,0,0,0,0,0,0,0,0,0,0
0,0,0,0,0,0,0,0,0,0,0,0,0,0,0,0,0
0,0,0,0,0,0,0,0,0,0,0,0,0,0,0,0,0
0,0,0,0,0,0,0,0,0,0,0,0,0,0,0,0,0
0,0,0,0,0,0,0,0,0,0,0,0,0,0,0,0,0
0,0,0,0,0,0,0,0,0,0,0,0,0,0,0,0,0
0,0,0,0,0,0,0,0,0,0,0,0,0,0,0,0,0
0,0,0,0,0,0,0,0,0,0,0,0,0,0,0,0,0
0,0,0,0,0,0,0,0,0,0,0,0,0,0,0,0,0
0,0,0,0,0,0,0,0,0,0,0,0,0,0,0,0,0
0,0,0,0,0,0,0,0,0,0,0,0,0,0,0,0,0
0,0,0,0,0,0,0,0,0,0,0,0,0,0,0,0,0
0,0,0,0,0,0,0,0,0,0,0,0,0,0,0,0,0
0,0,0,0,0,0,0,0,0,0,0,0,0,0,0,0,0
0,0,0,0,0,0,0,0,0,0,0,0,0,0,0,0,0
0,0,0,0,0,0,0,0,0,0,0,0,0,0,0,0,0
0,0,0,0,0,0,0,0,0,0,0,0,0,0,0,0,0
0,0,0,0,0,0,0,0,0,0,0,0,0,0,0,0,0
0,0,0,0,0,0,0,0,0,0,0,0,0,0,0,0,38
0,0,0,0,0,0,0,0,0,0,0,0,0,0,0,0,38
0,0,0,0,0,0,0,0,0,0,0,0,0,0,0,0,0
0,0,0,0,0,0,0,0,0,0,0,0,0,0,0,0,0
0,0,0,0,0,0,0,0,0,0,0,0,0,0,0,0,0
0,0,0,0,0,0,0,0,0,0,0,0,0,0,0,0,0
0,0,0,0,0,0,0,0,0,0,0,0,0,0,0,0,0
endlayer

