
# Created by Ruins mod version 17.1 Ingame Parser
# authoring Player: Nemsun

# criterion expression specifying mod ids required to load template
# may include plus (AND), minus (AND NOT), comma (OR), and parentheses
# all required mods listed must be present; no prohibited mods can be
requiredMods=
# likelihood this template will be chosen relative to all others
# e.g., a weight=6 template is chosen 3X as often as one with weight=2
weight=1
# list of other biomes in which this template may spawn
# biome corresponding to directory is always assumed, listed or not
# generic templates should leave this list empty
biomesToSpawnIn=
# criterion expression specifying types of biome where template spawns
# this is in addition to those explicitly listed as biomesToSpawnIn
# generic templates should leave this list empty
biomeTypesToSpawnIn=
# list of biomes in which this template may not spawn
# takes precedence over biomeTypesToSpawnIn, but NOT biomesToSpawnIn
# should be empty if biomeTypesToSpawnIn is empty
biomesToNotSpawnIn=
# depth template is pushed down into the surface when built
# offset is min/max range of random additional bury depth
embed_into_distance=5
random_height_offset=0,0
# whitelist/blacklist of block types on which template may be built
# specify one, not both; leave the other empty (both empty = allow all)
acceptable_target_blocks=
unacceptable_target_blocks=flowing_water,water,flowing_lava,lava
# size of template (#layers, #rows per layer, #blocks per row)
dimensions=18,16,29
# max number of missing blocks allowed in surface beneath template
allowable_overhang=0
# depth/height limit affected by terrain leveling
# also maximum bumpiness tolerated in surface beneath template
max_leveling=2
# padding applied to all sides of template horizontal footprint
# expands area affected by terrain leveling (-1 = no leveling)
leveling_buffer=0
# do not rotate template randomly when built (1 = no rotation)
preventRotation=0
# treat water/lava blocks as air and protect them from rule0 (1 = yes)
preserve_water=0
preserve_lava=0
# minimum distance this template must have from instances of itself
uniqueMinDistance=500
# min/max distances this template can be from world spawn (0 = no limit)
# only applies to overworld--i.e., dimension 0
spawnMinDistance=0
spawnMaxDistance=0
# other template built nearby whenever this one is
# syntax: <name>;<relativeX>;<maxYdifference>;<relativeZ>[;<chance>]
# may be used more than once to specify multiple neighbors
adjoining_template=

rule1=0,100,minecraft:stone-0
rule2=0,100,minecraft:log-0
rule3=0,100,minecraft:cobblestone-0
rule4=0,100,minecraft:stone_stairs-0
rule5=0,100,minecraft:monster_egg-0
rule6=0,100,minecraft:glass-0
rule7=2,100,minecraft:torch-3
rule8=0,100,minecraft:double_stone_slab-0
rule9=0,100,minecraft:stone_slab-8
rule10=0,100,minecraft:furnace-4
rule11=0,100,minecraft:crafting_table-0
rule12=0,100,minecraft:furnace-2
rule13=0,100,minecraft:furnace-3
rule14=0,100,minecraft:hopper-0
rule15=0,100,minecraft:furnace-5
rule16=0,100,minecraft:stone_stairs-7
rule17=0,100,minecraft:stone_stairs-6
rule18=0,100,minecraft:fence-0
rule19=0,100,contenttweaker:nb5-0
rule20=0,100,minecraft:trapped_chest-5
rule21=0,100,minecraft:planks-2
rule22=0,100,minecraft:trapped_chest-4
rule23=0,100,ChestGenHook:chests/simple_dungeon:5-4
rule24=0,100,ChestGenHook:chests/simple_dungeon:5-5
rule25=0,100,minecraft:stone_stairs-2
rule26=0,100,minecraft:anvil-7
rule27=0,100,minecraft:stone_stairs-1
rule28=0,100,minecraft:spruce_stairs-3
rule29=1,100,minecraft:torch-5
rule30=0,100,minecraft:dirt-0
rule31=0,100,minecraft:grass-0
rule32=0,100,minecraft:stone_stairs-3
rule33=2,100,WallSign:Deliver to:NemGo:Warehouse:null-5
rule34=0,100,minecraft:glass_pane-0
rule35=0,100,minecraft:spruce_stairs-6
rule36=2,100,minecraft:torch-4
rule37=0,100,ChestGenHook:chests/simple_dungeon:5-2
rule38=0,100,minecraft:stonebrick-0
rule39=2,100,WallSign:null:null:null:null-4
rule40=0,100,minecraft:stone_brick_stairs-1
rule41=2,100,minecraft:torch-1
rule42=0,100,minecraft:stone_brick_stairs-3
rule43=0,100,minecraft:stone_brick_stairs-2
rule44=2,100,minecraft:torch-2
rule45=0,100,minecraft:stone_stairs-4
rule46=2,100,WallSign:null:IRON ARMOUR:null:null-2
rule47=0,100,minecraft:stone_stairs-5
rule48=0,100,minecraft:vine-4
rule49=0,100,minecraft:vine-12
rule50=0,100,minecraft:carpet-0
rule51=0,100,minecraft:cobblestone_wall-0
rule52=0,100,minecraft:leaves-4
rule53=0,100,minecraft:spruce_stairs-0
rule54=0,100,minecraft:planks-1
rule55=0,100,minecraft:spruce_stairs-5
rule56=0,100,minecraft:spruce_stairs-7
rule57=0,100,minecraft:vine-2
rule58=0,100,minecraft:spruce_stairs-4
rule59=0,100,minecraft:hopper-3
rule60=0,100,minecraft:hopper-5
rule61=0,100,minecraft:hopper-2
rule62=2,100,WallSign:null:BOWS & ARROWS:null:null-2
rule63=0,100,minecraft:vine-6
rule64=0,100,minecraft:hopper-4
rule65=0,100,minecraft:yellow_flower-0
rule66=0,100,minecraft:leaves-5
rule67=0,100,minecraft:wooden_slab-9
rule68=0,100,minecraft:wooden_door-2
rule69=0,100,minecraft:double_wooden_slab-1
rule70=0,100,minecraft:spruce_stairs-2
rule71=0,100,minecraft:spruce_stairs-1
rule72=0,100,minecraft:carpet-1
rule73=0,100,minecraft:carpet-10
rule74=2,100,WallSign:Wanted:Andystarzz:head:-Gecko-2
rule75=0,100,minecraft:carpet-14
rule76=0,100,minecraft:wooden_door-9
rule77=0,100,minecraft:wooden_door-8
rule78=0,100,minecraft:ladder-2
rule79=0,100,minecraft:ender_chest-2
rule80=0,100,minecraft:bed-3
rule81=0,100,minecraft:bed-11
rule82=0,100,minecraft:stone_brick_stairs-4
rule83=0,100,ChestGenHook:chests/simple_dungeon:5-3
rule84=2,100,WallSign:null:LIVE:'Till I Die':null-2
rule85=0,100,minecraft:trapdoor-10
rule86=0,100,minecraft:stone_slab-13
rule87=0,100,minecraft:glowstone-0
rule88=0,100,minecraft:trapdoor-11
rule89=2,100,WallSign:AMIGOS NOTICE:BOARD:null:null-2
rule90=0,100,minecraft:stone_brick_stairs-0
rule91=0,100,minecraft:stone_brick_stairs-7
rule92=0,100,minecraft:stone_brick_stairs-6
rule93=0,100,minecraft:stone_slab-5
rule94=0,100,minecraft:stone_brick_stairs-5
rule95=0,100,minecraft:log-4
rule96=0,100,minecraft:bed-0
rule97=0,100,minecraft:bed-8
rule98=0,100,minecraft:birch_stairs-2
rule99=0,100,minecraft:birch_stairs-3
rule100=0,100,minecraft:unpowered_repeater-1
rule101=2,100,minecraft:redstone_torch-2
rule102=2,100,minecraft:redstone_torch-1
rule103=0,100,minecraft:unpowered_repeater-3
rule104=0,100,minecraft:redstone_wire-0
rule105=0,100,minecraft:hopper-12
rule106=0,100,minecraft:hopper-10
rule107=0,100,minecraft:hopper-13
rule108=0,100,minecraft:vine-14
rule109=0,100,minecraft:unpowered_comparator-3
rule110=0,100,minecraft:unpowered_comparator-1
rule111=0,100,minecraft:birch_stairs-6
rule112=0,100,minecraft:birch_stairs-7
rule113=0,100,minecraft:double_stone_slab-5
rule114=0,100,minecraft:sandstone-0

layer
1,1,1,1,1,1,1,1,1,1,1,1,1,1,1,1,1,1,1,1,1,1,1,0,0,0,1,1,1
1,1,1,1,1,1,1,1,1,1,1,1,1,1,1,1,1,1,1,1,1,1,1,0,0,0,1,1,1
1,1,1,1,1,1,1,1,1,1,1,1,1,1,1,1,1,1,1,1,1,1,2,0,0,0,2,1,1
1,1,1,1,1,1,1,1,1,1,1,1,1,1,1,1,1,1,1,1,1,1,3,0,0,0,3,1,1
1,1,1,1,1,1,1,1,1,1,1,1,1,1,1,1,1,1,1,1,1,1,3,4,4,4,3,1,1
1,1,1,1,1,1,1,1,1,1,1,1,1,1,1,1,1,1,1,1,1,1,1,1,1,1,1,1,1
1,1,1,1,1,5,1,1,1,1,1,1,1,1,1,1,1,1,1,1,1,1,1,1,1,1,1,1,1
1,1,1,1,1,1,5,1,1,1,1,1,1,1,1,1,1,1,1,1,1,1,1,1,1,1,1,1,1
1,1,1,1,1,1,1,1,6,6,6,1,1,1,1,1,1,1,1,1,1,1,1,1,1,1,1,1,1
1,1,1,1,1,1,1,1,6,6,6,1,1,1,1,1,1,1,1,1,1,1,1,1,1,1,1,1,1
1,1,1,1,1,1,1,1,6,6,6,1,1,1,1,1,1,1,1,1,1,1,1,1,1,1,1,1,1
1,1,1,1,1,1,1,1,1,1,1,1,1,1,1,1,1,1,1,1,1,1,1,1,1,1,1,1,1
1,1,1,1,1,1,1,1,1,1,1,1,1,1,1,1,1,1,1,1,1,1,1,1,1,1,1,1,1
1,1,1,1,1,1,1,1,1,1,1,1,1,1,1,1,1,1,1,1,1,1,1,1,1,1,1,1,1
1,1,1,1,1,1,1,1,1,1,1,1,1,1,1,1,1,1,1,1,1,1,1,1,1,1,1,1,1
1,1,1,1,1,1,1,1,1,1,1,1,1,1,1,1,1,1,1,1,1,1,1,1,1,1,1,1,1
endlayer

layer
1,1,1,1,1,1,1,1,1,1,1,1,1,1,1,1,1,1,1,1,1,1,1,0,0,0,1,1,1
1,1,1,1,1,1,1,1,1,1,1,1,1,1,1,1,1,1,1,1,1,1,1,0,0,0,1,1,1
1,1,1,1,1,1,1,1,1,1,1,1,1,1,1,1,1,1,1,1,1,1,2,0,0,7,2,1,1
1,1,1,1,9,1,9,1,9,1,9,1,9,1,9,1,9,1,9,1,9,1,8,0,0,0,3,1,1
1,1,1,1,1,9,1,9,1,9,1,9,1,9,1,9,1,9,1,9,1,9,1,0,0,0,3,1,1
1,1,1,1,9,1,9,1,9,1,9,1,9,1,9,1,9,1,9,1,9,1,8,4,4,4,3,1,1
1,1,1,1,1,9,1,1,1,1,1,1,1,1,1,9,1,9,1,10,11,10,1,8,1,8,1,1,1
1,1,1,1,9,1,9,1,1,1,1,1,9,1,9,1,9,1,13,1,1,1,12,1,9,1,1,1,1
1,1,1,8,1,9,1,1,6,6,6,1,1,11,1,9,1,9,11,3,14,1,11,9,1,9,1,1,1
1,1,1,1,9,1,9,1,6,6,6,1,9,1,9,1,9,1,13,1,1,1,12,1,9,1,1,1,1
1,1,1,1,1,9,1,1,6,6,6,1,1,1,1,9,1,9,1,15,11,15,1,9,1,9,1,1,1
1,1,1,1,9,1,9,1,1,1,1,1,9,1,9,1,9,1,9,1,9,1,9,1,9,1,1,1,1
1,1,1,1,1,8,1,9,1,1,1,1,1,11,1,9,1,9,1,9,1,9,1,9,1,9,1,1,1
1,1,1,1,9,1,9,1,1,1,1,1,8,1,9,1,9,1,9,1,9,1,9,1,8,1,1,1,1
1,1,1,1,1,1,1,1,1,1,1,1,1,1,1,1,1,1,1,1,1,1,1,1,1,1,1,1,1
1,1,1,1,1,1,1,1,1,1,1,1,1,1,1,1,1,1,1,1,1,1,1,1,1,1,1,1,1
endlayer

layer
1,1,1,1,1,1,1,1,1,1,1,1,1,1,1,1,1,1,1,1,1,1,1,0,0,0,1,1,1
1,1,1,1,1,1,1,1,1,1,1,1,1,1,1,1,1,1,1,1,1,1,1,0,0,0,1,1,1
1,1,1,3,3,3,3,2,3,3,3,2,3,3,2,3,3,3,2,3,3,3,2,17,0,16,3,1,1
1,1,1,3,0,0,0,0,0,0,0,0,0,0,0,19,19,19,20,20,19,19,18,0,0,0,3,1,1
1,1,1,3,0,0,0,0,0,0,0,0,0,0,0,0,0,0,0,0,0,0,18,0,0,0,3,1,1
1,1,1,3,0,0,0,0,0,0,0,0,0,0,0,0,0,0,0,0,0,0,18,0,0,0,3,1,1
1,1,1,2,0,0,0,2,22,23,22,2,21,21,2,0,0,0,0,0,0,0,0,0,0,0,2,1,1
1,1,1,3,0,0,0,21,21,21,21,21,24,24,0,0,0,0,0,2,4,2,0,0,0,0,3,1,1
1,1,2,26,0,0,0,21,6,6,6,21,0,0,0,0,0,0,0,0,14,25,0,0,0,0,2,1,1
1,1,1,3,0,0,0,21,6,6,6,21,23,23,0,0,0,0,0,2,27,2,0,0,0,0,3,1,1
1,1,1,2,0,0,0,2,6,6,6,2,21,21,2,0,0,0,0,0,0,0,0,0,0,0,2,1,1
1,1,1,3,0,0,0,0,28,21,21,21,24,24,0,0,0,0,0,0,0,0,0,0,0,0,3,1,1
1,1,1,3,0,0,0,0,28,29,21,21,0,0,0,0,0,0,0,0,0,0,0,0,0,0,3,1,1
1,1,1,3,0,0,0,0,28,0,21,21,23,23,0,0,0,0,0,0,0,0,0,0,0,0,3,1,1
1,1,1,1,3,3,3,2,3,1,1,1,3,3,2,3,3,3,2,3,3,3,2,3,3,3,1,1,1
1,1,1,1,1,1,1,1,1,1,1,1,1,1,1,1,1,1,1,1,1,1,1,1,1,1,1,1,1
endlayer

layer
30,30,30,30,30,30,30,30,30,30,30,2,0,0,2,30,30,30,30,30,30,30,30,1,1,1,30,30,30
30,30,30,30,30,31,30,1,30,31,30,30,30,30,30,30,31,30,1,1,30,1,1,1,1,1,1,1,1
30,30,30,3,3,27,3,2,3,27,3,2,3,3,2,3,27,3,2,3,27,3,2,3,27,3,3,1,1
30,30,30,3,0,0,0,0,0,0,0,0,0,0,0,19,0,19,0,0,0,19,0,0,0,0,3,1,30
30,30,31,25,0,0,0,0,0,0,0,0,0,0,0,0,0,33,0,0,0,0,0,0,0,0,32,31,30
30,30,30,3,0,0,0,0,0,0,0,0,0,0,0,0,0,0,0,0,0,0,0,0,0,0,3,30,30
30,30,30,2,0,0,0,2,22,23,22,2,21,21,2,0,0,0,0,0,0,0,0,0,0,0,2,30,30
30,30,30,3,0,0,0,21,21,21,21,21,35,0,0,0,0,0,0,2,34,2,0,0,0,0,3,30,30
30,30,2,37,0,0,0,21,6,6,6,21,36,0,0,0,0,0,0,0,14,34,0,0,0,0,2,30,30
30,30,30,3,0,0,0,21,6,6,6,21,35,0,0,0,0,0,0,2,34,2,0,0,0,0,3,30,30
30,31,30,2,0,0,0,2,6,6,6,2,21,21,2,0,0,0,0,0,0,0,0,0,0,0,2,30,30
30,31,31,3,0,0,0,0,0,28,21,21,35,0,0,0,0,0,0,0,0,0,0,0,0,0,3,30,30
30,31,31,25,0,0,0,0,0,28,21,21,36,0,0,0,0,0,0,0,0,0,0,0,0,0,32,31,30
30,31,31,3,0,0,0,0,0,28,21,21,35,0,0,0,0,0,0,0,0,0,0,0,0,0,3,30,30
30,31,30,30,3,4,3,2,3,4,3,30,3,3,2,3,4,3,2,3,4,3,2,3,4,3,30,30,30
30,31,38,2,38,38,38,30,38,38,38,30,38,38,30,31,31,31,2,38,38,38,2,38,38,38,30,30,30
endlayer

layer
31,31,31,31,31,31,31,31,31,31,31,2,39,39,2,31,31,31,31,31,31,31,31,31,31,31,31,31,31
31,31,38,30,38,40,38,30,38,40,38,30,31,31,30,38,40,38,30,38,40,38,1,38,40,38,1,38,31
31,31,30,3,3,34,3,2,3,34,3,2,3,3,2,3,34,3,2,3,34,3,2,3,34,3,3,1,31
31,31,38,3,0,0,0,41,0,0,0,41,0,0,41,0,0,0,41,0,0,0,41,0,0,0,3,38,31
31,31,43,34,0,0,0,0,0,0,0,0,0,0,0,0,0,0,0,0,0,0,0,0,0,0,34,42,31
31,31,38,3,0,0,0,44,0,0,0,44,0,0,44,0,0,0,0,0,0,0,0,0,0,0,3,38,31
31,31,30,2,36,0,0,2,22,23,22,2,21,21,2,0,0,0,0,0,0,0,0,0,0,7,2,30,31
31,31,31,3,0,0,0,21,21,21,21,21,37,0,0,0,0,0,0,2,45,2,0,0,0,0,3,38,31
31,31,2,37,46,0,0,21,6,6,6,21,0,0,0,0,0,0,0,16,14,17,0,0,0,7,2,30,31
31,31,31,3,0,0,0,21,6,6,6,21,37,0,0,0,0,0,0,2,47,2,0,0,0,0,3,38,31
31,0,2,2,36,0,0,2,6,6,6,2,21,21,2,0,0,0,0,0,0,0,0,0,0,7,2,30,31
31,0,0,3,0,0,0,0,0,0,28,21,37,0,0,0,0,0,0,0,0,0,0,0,0,0,3,38,31
31,0,48,34,0,0,0,0,0,0,28,21,0,0,0,0,0,0,0,0,0,0,0,0,0,0,34,42,31
31,0,49,3,0,0,0,44,0,0,28,21,37,0,0,0,0,0,44,0,0,0,44,0,0,0,3,38,31
31,29,2,2,3,34,3,2,3,34,3,30,3,3,2,3,34,3,2,3,34,3,2,3,34,3,30,30,31
31,0,18,2,0,0,0,2,0,0,0,2,0,0,2,0,0,0,2,0,0,0,2,0,0,0,2,38,31
endlayer

layer
0,0,0,0,0,52,18,52,18,52,51,18,50,50,18,0,0,0,0,0,0,0,0,0,0,0,0,0,0
0,0,18,2,0,0,52,2,29,52,51,2,53,53,2,0,0,0,2,0,0,0,2,0,0,0,2,18,0
0,48,2,2,3,45,3,2,3,45,3,2,54,54,2,3,45,3,2,3,45,3,2,3,45,3,2,2,0
0,0,57,3,0,0,0,0,0,0,0,56,54,54,35,0,0,0,55,0,0,0,55,0,0,0,3,0,0
0,29,0,16,0,0,0,0,0,0,0,56,54,54,35,0,0,0,0,0,0,0,0,0,0,0,17,0,0
0,0,0,3,0,0,0,0,0,0,0,56,54,54,35,0,0,0,0,0,0,0,0,0,0,0,3,0,0
0,48,2,2,0,0,0,2,22,23,22,2,54,54,2,35,0,0,0,58,58,58,0,0,0,56,2,2,0
0,48,0,3,0,0,0,21,21,21,21,21,58,56,35,0,0,0,56,60,60,59,35,0,0,0,3,0,0
0,63,2,37,62,0,0,21,6,6,6,21,54,54,35,0,0,0,56,61,14,59,35,0,0,56,2,2,0
0,65,0,3,0,0,0,21,6,6,6,21,55,56,35,0,0,0,56,64,64,59,35,0,0,0,3,0,0
0,0,2,2,0,0,0,2,6,6,6,2,54,54,2,35,0,0,0,55,55,55,0,0,0,56,2,2,0
0,0,0,3,0,0,0,0,0,0,0,28,58,56,35,0,0,0,0,0,0,0,0,0,0,0,3,0,0
0,0,48,16,0,0,0,0,0,0,0,28,54,54,35,0,0,0,0,0,0,0,0,0,0,0,17,0,0
0,0,49,3,0,0,0,0,0,0,0,28,55,56,35,0,0,0,58,0,0,0,58,0,0,0,3,0,0
0,48,2,2,3,47,3,2,3,47,3,2,3,3,2,3,47,3,2,3,47,3,2,3,47,3,2,2,0
0,0,18,2,0,0,0,2,0,0,0,2,0,0,2,0,0,0,2,0,0,0,2,0,0,0,2,18,0
endlayer

layer
0,0,0,0,0,0,52,52,66,0,0,18,0,0,18,0,0,0,0,0,0,0,0,0,0,0,0,0,0
0,0,18,2,58,67,58,2,58,67,58,2,0,0,2,58,67,58,2,58,67,58,2,58,67,58,2,18,0
0,48,2,2,3,3,3,2,3,3,3,2,68,68,2,3,3,3,2,3,3,3,2,3,3,3,2,2,0
0,0,56,3,54,54,54,54,54,54,54,70,0,0,28,69,69,54,54,54,54,54,54,54,54,54,3,35,0
0,0,67,3,54,54,54,54,54,54,54,70,0,0,28,69,54,54,54,54,54,54,54,54,54,54,3,67,0
0,0,56,3,54,54,54,54,54,54,54,70,0,0,28,69,69,54,54,54,54,54,54,54,54,54,3,35,0
0,48,2,2,54,54,54,54,55,55,55,2,0,0,2,11,69,69,54,71,71,71,54,54,54,54,2,2,0
0,48,56,3,54,54,54,21,21,21,21,21,74,0,28,69,69,69,70,72,73,72,28,54,54,54,3,35,0
0,63,2,56,54,54,54,21,6,6,6,21,0,0,28,69,69,69,70,73,75,73,28,54,54,54,2,2,0
0,48,56,3,54,54,54,21,6,6,6,21,0,0,28,69,69,69,70,72,73,72,28,54,54,54,3,35,0
0,0,2,2,54,54,54,2,6,6,6,2,0,0,2,11,69,69,54,53,53,53,54,69,69,54,2,2,0
0,0,56,3,54,54,54,54,35,0,0,0,0,0,28,69,69,69,69,69,69,69,69,69,69,69,3,35,0
0,0,67,3,54,54,54,54,35,0,0,0,0,0,28,69,69,69,54,54,69,54,54,69,54,54,3,67,0
0,0,56,3,54,54,54,54,35,0,0,0,0,0,28,69,69,69,54,54,69,54,54,69,54,54,3,35,0
0,48,2,2,3,3,3,2,3,3,3,2,3,3,2,3,3,3,2,3,3,3,2,3,3,3,2,2,0
0,0,18,2,55,67,55,2,55,67,55,2,55,55,2,55,67,55,2,55,67,55,2,55,67,55,2,18,0
endlayer

layer
0,0,0,0,0,0,0,52,0,0,0,18,0,0,18,0,0,0,0,0,0,0,0,0,0,0,0,0,0
0,0,18,2,0,0,52,2,52,0,0,2,0,0,2,0,0,0,2,0,0,0,2,0,0,0,2,18,0
0,48,2,2,21,21,21,2,21,21,21,2,77,76,2,21,21,21,24,21,21,21,24,21,21,21,14,2,0
0,0,48,21,11,0,0,0,0,0,0,0,0,0,0,0,0,0,0,0,0,0,0,0,0,0,21,0,0
0,0,0,21,0,0,0,0,0,0,0,0,0,0,0,0,0,0,0,0,0,0,0,0,0,0,21,29,0
0,0,0,21,0,0,0,0,0,0,0,0,0,0,0,0,0,0,0,0,0,0,0,0,0,0,21,0,0
0,48,2,2,0,0,0,2,10,10,10,2,0,0,2,0,0,0,0,0,0,0,0,0,0,0,2,2,0
0,48,48,21,0,0,0,21,21,21,21,21,0,0,0,0,0,0,0,0,0,0,0,0,0,0,21,29,0
0,63,2,78,0,0,0,21,6,6,6,21,0,0,0,0,0,0,0,0,0,0,0,0,0,0,2,2,0
0,48,0,21,0,0,0,21,6,6,6,21,0,0,0,0,0,0,0,0,0,0,0,0,0,0,21,29,0
0,0,2,2,0,0,0,2,6,6,6,2,0,0,2,0,0,0,0,0,0,0,0,0,0,0,2,2,0
0,0,0,21,0,0,0,21,0,0,0,0,0,0,0,0,0,0,0,0,0,0,0,0,0,0,21,0,0
0,0,48,21,0,80,0,21,79,0,0,0,0,0,0,0,0,0,0,0,0,0,0,0,0,0,21,29,0
0,0,48,21,23,81,23,21,0,0,0,0,0,0,0,0,0,0,0,0,0,0,0,0,0,0,21,0,0
0,48,2,2,21,21,21,2,21,21,21,2,34,34,2,21,21,21,23,21,21,21,23,21,21,21,14,2,0
0,0,18,2,0,0,0,2,0,0,0,2,0,0,2,0,0,0,2,0,0,0,2,0,0,0,2,18,0
endlayer

layer
0,0,0,0,0,0,0,66,0,0,0,42,82,82,43,0,0,0,0,0,0,0,0,0,0,0,0,0,0
0,0,18,2,0,0,0,2,52,0,0,28,35,56,70,0,0,0,2,0,0,0,2,0,0,0,2,18,0
0,48,2,2,21,34,21,2,21,34,21,2,54,54,2,21,34,21,14,21,34,21,14,21,34,21,14,2,0
0,0,48,21,0,0,0,41,0,0,0,0,0,0,0,0,0,41,0,41,0,41,0,41,0,0,21,0,0
0,0,0,34,0,0,0,0,0,0,0,0,0,0,0,0,0,0,0,0,0,0,0,0,0,0,34,0,0
0,0,0,21,0,0,0,0,0,0,0,0,0,0,0,0,0,0,0,0,0,0,0,0,0,7,21,0,0
0,48,2,2,36,0,0,2,10,10,10,2,0,0,2,36,0,0,0,0,0,0,0,0,0,0,83,2,0
0,48,48,21,0,0,0,21,21,21,21,21,0,0,0,0,0,0,0,0,0,0,0,0,0,7,21,0,0
0,63,2,78,0,0,0,21,6,6,6,21,0,0,0,0,0,0,0,0,0,0,0,0,0,0,83,2,0
0,48,0,21,0,0,0,21,6,6,6,21,84,0,0,0,0,0,0,0,0,0,0,0,0,7,21,0,0
0,0,2,2,36,0,0,2,6,6,6,2,0,0,2,36,0,0,0,0,0,0,0,0,0,0,83,2,0
0,0,0,21,0,0,0,21,0,0,0,0,0,0,0,0,0,0,0,0,0,0,0,0,0,7,21,0,0
0,0,48,34,0,0,0,21,0,0,0,0,0,0,0,0,0,0,0,0,0,0,0,0,0,0,34,0,0
0,0,48,21,85,0,85,21,0,0,0,44,0,0,44,0,0,44,0,44,0,44,0,44,0,0,21,0,0
0,48,2,2,21,34,21,2,21,34,21,2,34,34,2,21,34,21,14,21,34,21,14,21,34,21,14,2,0
0,0,18,2,0,0,0,2,0,0,0,2,0,0,2,0,0,0,2,0,0,0,2,0,0,0,2,18,0
endlayer

layer
0,0,0,0,0,0,0,66,0,0,0,0,42,43,0,0,0,0,0,0,0,0,0,0,0,0,0,0,0
0,86,18,2,0,0,0,2,0,0,0,0,28,70,0,0,0,0,2,0,0,0,2,0,0,0,2,18,86
0,48,2,2,21,21,21,2,21,21,21,2,87,87,2,21,21,21,24,21,21,21,24,21,21,21,14,2,0
0,0,48,21,0,0,0,0,0,0,0,0,88,88,55,67,67,67,55,67,67,67,55,67,67,67,21,0,0
0,0,0,21,0,0,0,0,0,0,0,0,0,0,0,0,0,0,0,0,0,0,0,0,0,67,21,0,0
0,0,0,21,0,0,0,44,0,0,0,44,0,0,0,0,0,0,0,0,0,0,0,0,0,67,21,0,0
0,48,2,2,0,0,0,2,10,10,10,2,0,7,2,0,0,0,0,0,0,0,0,0,0,56,14,2,0
0,48,48,21,0,0,0,21,21,21,21,21,0,0,0,0,0,0,0,0,0,0,0,0,0,67,21,0,0
0,63,2,78,0,0,0,21,6,6,6,21,89,0,0,0,0,0,0,0,0,0,0,0,0,56,14,2,0
0,48,0,21,0,0,0,21,6,6,6,21,0,0,0,0,0,0,0,0,0,0,0,0,0,67,21,0,0
0,0,2,2,0,0,0,2,6,6,6,2,0,7,2,0,0,0,0,0,0,0,0,0,0,56,14,2,0
0,0,0,21,0,0,0,21,0,0,0,0,0,0,0,0,0,0,0,0,0,0,0,0,0,67,21,0,0
0,0,48,21,0,0,0,21,0,0,0,0,0,0,0,0,0,0,0,0,0,0,0,0,0,67,21,0,0
0,0,48,21,23,58,23,21,0,0,0,0,0,0,58,67,67,67,58,67,67,67,58,67,67,67,21,0,0
0,48,2,2,21,21,21,2,21,21,21,2,34,34,2,21,21,21,23,21,21,21,23,21,21,21,14,2,0
0,86,18,2,0,0,0,2,0,0,0,2,0,0,2,0,0,0,2,0,0,0,2,0,0,0,2,18,86
endlayer

layer
0,0,0,0,0,0,0,0,0,0,0,0,0,0,0,0,0,0,0,0,0,0,0,0,0,0,0,0,0
0,90,90,90,92,82,91,90,92,82,91,90,93,93,90,92,82,82,90,92,82,91,90,92,82,91,90,90,90
0,94,2,2,21,21,21,2,21,21,21,2,38,38,2,21,21,21,14,21,21,21,14,21,21,21,14,2,94
0,0,56,54,54,54,54,54,54,54,54,54,54,54,69,54,54,54,64,54,54,54,64,54,54,0,64,35,0
0,0,56,54,54,54,54,54,54,54,54,54,54,54,54,54,54,54,54,54,54,54,54,54,54,54,21,35,0
0,0,56,54,54,54,54,54,54,54,54,54,54,54,54,54,54,54,54,54,54,54,54,54,54,54,21,35,0
0,48,2,54,54,54,54,54,54,54,54,54,54,54,54,54,54,54,54,54,54,54,54,54,54,54,14,2,0
0,48,56,54,54,54,54,54,54,54,54,54,54,54,54,54,54,54,54,54,54,54,54,54,54,54,21,35,0
0,63,2,0,54,54,54,54,6,6,6,54,54,54,54,54,54,54,54,54,54,54,54,54,54,54,83,2,0
0,48,56,54,54,54,54,54,6,6,6,54,54,54,54,54,54,54,54,54,54,54,54,54,54,54,21,35,0
0,0,2,54,54,54,54,54,6,6,6,54,54,54,54,54,54,54,54,54,54,54,54,54,54,54,83,2,0
0,0,56,54,54,54,54,54,54,54,54,54,54,54,54,54,54,54,54,54,54,54,54,54,54,54,21,35,0
0,0,56,54,54,54,54,54,54,54,54,54,54,54,54,54,54,54,54,54,54,54,54,54,54,54,21,35,0
0,0,56,54,55,54,55,54,54,54,54,54,54,54,54,69,69,69,69,54,61,61,60,54,54,0,60,35,0
0,82,2,21,21,21,21,21,21,21,21,2,21,21,95,21,21,21,2,21,21,21,14,21,21,21,14,2,82
0,40,40,40,92,94,91,40,92,94,91,40,94,94,40,92,94,91,40,92,94,91,40,92,94,91,40,40,40
endlayer

layer
0,0,0,0,0,0,0,0,0,0,0,0,0,0,0,0,0,0,0,0,0,0,0,0,0,0,0,0,0
0,0,0,0,0,0,0,0,0,29,0,0,0,0,0,0,29,0,0,0,29,0,0,0,29,0,0,0,0
0,90,53,53,53,53,53,53,53,53,53,53,53,53,53,53,53,53,53,53,53,53,53,53,53,53,53,53,90
0,94,21,0,0,0,0,0,0,0,0,0,61,61,61,61,61,24,24,61,61,24,24,61,61,24,24,21,94
0,0,21,0,0,0,29,0,0,0,0,0,64,0,61,61,61,61,61,64,61,61,61,64,29,0,29,21,0
0,0,21,0,0,0,0,0,0,0,29,0,64,29,64,29,61,61,61,61,64,61,61,61,61,60,0,21,0
0,48,2,97,96,29,0,0,0,0,0,0,64,0,64,0,64,0,61,61,61,64,0,29,0,23,23,2,0
0,48,99,0,0,0,0,0,29,0,0,0,0,0,0,0,0,0,64,21,21,21,21,21,21,29,0,98,0
0,63,2,0,0,0,0,0,6,6,6,0,0,0,29,0,0,29,0,100,100,100,100,100,100,0,14,2,0
0,48,99,0,0,29,0,0,6,6,6,101,101,101,101,101,101,101,101,21,21,21,21,21,21,0,0,98,0
0,0,2,0,0,0,0,0,6,6,6,21,21,21,21,21,21,21,21,102,102,102,102,102,102,29,14,2,0
0,0,21,0,0,0,0,0,0,29,0,103,103,103,103,103,103,103,103,0,0,0,0,0,0,61,64,21,0
0,0,21,0,0,0,29,0,0,0,0,21,21,21,21,21,21,21,21,61,60,29,61,61,61,60,0,21,0
0,82,21,0,0,0,0,0,0,0,0,0,0,29,0,0,0,0,0,0,14,0,0,0,0,23,23,21,82
0,40,71,71,71,71,71,71,71,71,71,71,71,71,71,71,71,71,71,71,71,71,71,71,71,71,71,71,40
0,0,0,0,0,0,0,0,0,0,0,0,0,0,0,0,0,0,0,0,0,0,0,0,0,0,0,0,0
endlayer

layer
0,0,0,0,0,0,0,0,0,0,0,0,0,0,0,0,0,0,0,0,0,0,0,0,0,0,0,0,0
0,0,0,0,0,0,0,0,0,0,0,0,0,0,0,0,0,0,0,0,0,0,0,0,0,0,0,0,0
0,0,0,0,0,0,0,0,0,0,0,0,0,0,0,0,0,0,0,0,0,0,0,0,0,0,0,0,0
0,90,53,53,53,53,53,53,53,53,53,53,53,53,53,53,53,53,53,53,53,53,53,53,53,53,53,53,90
0,94,21,0,0,0,0,0,0,0,0,0,0,0,0,0,0,0,0,0,0,0,0,0,0,0,0,21,94
0,0,21,0,0,0,0,0,0,0,0,0,0,0,0,0,0,0,0,0,0,0,0,0,0,0,0,21,0
0,0,2,0,0,0,0,0,0,0,0,0,83,0,83,0,83,0,0,0,0,0,0,0,0,0,0,2,0
0,48,34,0,0,0,0,0,0,0,0,0,83,0,83,0,83,0,83,104,104,104,104,104,104,0,0,34,0
0,63,2,0,0,0,0,0,6,6,6,61,64,61,64,61,64,61,83,21,21,21,21,21,21,0,83,2,0
0,48,34,0,0,0,0,0,6,6,6,105,105,105,105,106,105,105,105,21,21,21,21,21,21,0,0,34,0
0,0,2,0,0,0,0,0,6,6,6,21,21,21,21,21,21,21,21,107,107,107,107,107,107,0,0,2,0
0,0,21,0,0,0,0,0,0,0,0,21,21,21,21,21,21,21,21,37,59,61,83,61,24,24,0,21,0
0,82,21,0,0,0,0,0,0,0,0,104,104,104,104,104,104,104,104,37,0,0,83,0,0,0,0,21,82
0,40,71,71,71,71,71,71,71,71,71,71,71,71,71,71,71,71,71,71,71,71,71,71,71,71,71,71,40
0,0,0,0,0,0,0,0,0,0,0,0,0,0,0,0,0,0,0,0,0,0,0,0,0,0,0,0,0
0,0,0,0,0,0,0,0,0,0,0,0,0,0,0,0,0,0,0,0,0,0,0,0,0,0,0,0,0
endlayer

layer
0,0,0,0,0,0,0,0,0,0,0,0,0,0,0,0,0,0,0,0,0,0,0,0,0,0,0,0,0
0,0,0,0,0,0,0,0,0,0,0,0,0,0,0,0,0,0,0,0,0,0,0,0,0,0,0,0,0
0,0,0,0,0,0,0,0,0,0,0,0,0,0,0,0,0,0,0,0,0,0,0,0,0,0,0,0,0
0,0,0,0,0,0,0,0,0,0,0,0,0,0,0,0,0,0,0,0,0,0,0,0,0,0,0,0,0
0,90,53,53,53,53,53,53,53,53,53,53,53,53,53,53,53,53,53,53,53,53,53,53,53,53,53,53,90
0,94,21,0,0,0,0,0,0,0,0,0,0,0,0,0,0,0,0,0,0,0,0,0,0,0,0,21,94
0,0,2,0,0,0,0,0,0,0,0,0,0,0,0,0,0,0,0,0,0,0,0,0,0,0,0,2,0
0,48,34,0,0,0,0,0,0,0,0,0,0,0,0,0,0,0,0,0,0,0,0,0,0,0,0,34,0
0,108,2,0,0,0,0,0,6,6,6,6,0,0,0,0,0,0,0,104,104,104,104,104,104,0,14,2,0
0,48,34,0,0,0,0,0,6,6,6,60,60,60,60,60,60,60,60,109,109,109,109,109,109,0,0,34,0
0,0,2,0,0,0,0,0,6,6,6,110,110,110,110,110,110,110,110,64,64,64,64,64,64,0,0,2,0
0,82,21,0,0,0,0,0,0,0,0,104,104,104,104,104,104,104,104,0,0,0,0,0,0,0,0,21,82
0,40,71,71,71,71,71,71,71,71,71,71,71,71,71,71,71,71,71,71,71,71,71,71,71,71,71,71,40
0,0,0,0,0,0,0,0,0,0,0,0,0,0,0,0,0,0,0,0,0,0,0,0,0,0,0,0,0
0,0,0,0,0,0,0,0,0,0,0,0,0,0,0,0,0,0,0,0,0,0,0,0,0,0,0,0,0
0,0,0,0,0,0,0,0,0,0,0,0,0,0,0,0,0,0,0,0,0,0,0,0,0,0,0,0,0
endlayer

layer
0,0,0,0,0,0,0,0,0,0,0,0,0,0,0,0,0,0,0,0,0,0,0,0,0,0,0,0,0
0,0,0,0,0,0,0,0,0,0,0,0,0,0,0,0,0,0,0,0,0,0,0,0,0,0,0,0,0
0,0,0,0,0,0,0,0,0,0,0,0,0,0,0,0,0,0,0,0,0,0,0,0,0,0,0,0,0
0,0,0,0,0,0,0,0,0,0,0,0,0,0,0,0,0,0,0,0,0,0,0,0,0,0,0,0,0
0,0,0,0,0,0,0,0,0,0,0,0,0,0,0,0,0,0,0,0,0,0,0,0,0,0,0,0,0
0,90,53,53,53,53,53,53,53,53,53,53,53,53,53,53,53,53,53,53,53,53,53,53,53,53,53,53,90
0,94,2,0,0,0,0,0,0,0,0,0,0,0,0,0,0,0,0,0,0,0,0,0,0,0,0,2,94
0,48,112,0,0,0,0,0,0,0,0,0,0,0,0,0,0,0,0,0,0,0,0,0,0,0,0,111,0
0,108,2,0,0,0,0,0,61,61,60,0,0,0,0,0,0,0,0,0,0,0,0,0,0,61,83,2,0
0,48,112,0,0,0,0,0,61,61,61,61,61,61,61,61,61,61,61,60,0,0,0,0,0,64,0,111,0
0,82,2,0,0,0,0,0,61,61,64,0,0,0,0,0,0,14,0,61,61,61,61,61,61,64,0,2,82
0,40,71,71,71,71,71,71,71,71,71,71,71,71,71,71,71,71,71,71,71,71,71,71,71,71,71,71,40
0,0,0,0,0,0,0,0,0,0,0,0,0,0,0,0,0,0,0,0,0,0,0,0,0,0,0,0,0
0,0,0,0,0,0,0,0,0,0,0,0,0,0,0,0,0,0,0,0,0,0,0,0,0,0,0,0,0
0,0,0,0,0,0,0,0,0,0,0,0,0,0,0,0,0,0,0,0,0,0,0,0,0,0,0,0,0
0,0,0,0,0,0,0,0,0,0,0,0,0,0,0,0,0,0,0,0,0,0,0,0,0,0,0,0,0
endlayer

layer
0,0,0,0,0,0,0,0,0,0,0,0,0,0,0,0,0,0,0,0,0,0,0,0,0,0,0,0,0
0,0,0,0,0,0,0,0,0,0,0,0,0,0,0,0,0,0,0,0,0,0,0,0,0,0,0,0,0
0,0,0,0,0,0,0,0,0,0,0,0,0,0,0,0,0,0,0,0,0,0,0,0,0,0,0,0,0
0,0,0,0,0,0,0,0,0,0,0,0,0,0,0,0,0,0,0,0,0,0,0,0,0,0,0,0,0
0,0,0,0,0,0,0,0,0,0,0,0,0,0,0,0,0,0,0,0,0,0,0,0,0,0,0,0,0
0,0,0,0,0,0,0,0,0,0,0,0,0,0,0,0,0,0,0,0,0,0,0,0,0,0,0,0,0
0,90,53,53,53,53,53,53,53,53,53,53,53,53,53,53,53,53,53,53,53,53,53,53,53,53,53,53,90
0,94,21,0,0,0,0,0,0,0,0,0,0,0,0,0,0,0,0,0,0,0,0,0,0,0,0,21,94
0,108,2,0,0,0,0,0,0,0,0,0,0,0,0,0,0,0,0,0,0,0,0,0,0,0,0,2,0
0,82,21,0,0,0,0,0,0,0,0,0,0,0,0,0,0,0,0,0,0,0,0,0,0,0,0,21,82
0,40,71,71,71,71,71,71,71,71,71,71,71,71,71,71,71,71,71,71,71,71,71,71,71,71,71,71,40
0,0,0,0,0,0,0,0,0,0,0,0,0,0,0,0,0,0,0,0,0,0,0,0,0,0,0,0,0
0,0,0,0,0,0,0,0,0,0,0,0,0,0,0,0,0,0,0,0,0,0,0,0,0,0,0,0,0
0,0,0,0,0,0,0,0,0,0,0,0,0,0,0,0,0,0,0,0,0,0,0,0,0,0,0,0,0
0,0,0,0,0,0,0,0,0,0,0,0,0,0,0,0,0,0,0,0,0,0,0,0,0,0,0,0,0
0,0,0,0,0,0,0,0,0,0,0,0,0,0,0,0,0,0,0,0,0,0,0,0,0,0,0,0,0
endlayer

layer
0,0,0,0,0,0,0,0,0,0,0,0,0,0,0,0,0,0,0,0,0,0,0,0,0,0,0,0,0
0,0,0,0,0,0,0,0,0,0,0,0,0,0,0,0,0,0,0,0,0,0,0,0,0,0,0,0,0
0,0,0,0,0,0,0,0,0,0,0,0,0,0,0,0,0,0,0,0,0,0,0,0,0,0,0,0,0
0,0,0,0,0,0,0,0,0,0,0,0,0,0,0,0,0,0,0,0,0,0,0,0,0,0,0,0,0
0,0,0,0,0,0,0,0,0,0,0,0,0,0,0,0,0,0,0,0,0,0,0,0,0,0,0,0,0
0,0,0,0,0,0,0,0,0,0,0,0,0,0,0,0,0,0,0,0,0,0,0,0,0,0,0,0,0
0,0,0,0,0,0,0,0,0,0,0,0,0,0,0,0,0,0,0,0,0,0,0,0,0,0,0,0,0
0,90,53,53,53,53,53,53,53,53,53,53,53,53,53,53,53,53,53,53,53,53,53,53,53,53,53,53,90
0,91,87,114,114,114,114,114,114,114,114,114,114,114,114,114,114,114,114,114,114,114,114,114,114,114,114,87,113
0,40,71,71,71,71,71,71,71,71,71,71,71,71,71,71,71,71,71,71,71,71,71,71,71,71,71,71,40
0,0,0,0,0,0,0,0,0,0,0,0,0,0,0,0,0,0,0,0,0,0,0,0,0,0,0,0,0
0,0,0,0,0,0,0,0,0,0,0,0,0,0,0,0,0,0,0,0,0,0,0,0,0,0,0,0,0
0,0,0,0,0,0,0,0,0,0,0,0,0,0,0,0,0,0,0,0,0,0,0,0,0,0,0,0,0
0,0,0,0,0,0,0,0,0,0,0,0,0,0,0,0,0,0,0,0,0,0,0,0,0,0,0,0,0
0,0,0,0,0,0,0,0,0,0,0,0,0,0,0,0,0,0,0,0,0,0,0,0,0,0,0,0,0
0,0,0,0,0,0,0,0,0,0,0,0,0,0,0,0,0,0,0,0,0,0,0,0,0,0,0,0,0
endlayer

layer
0,0,0,0,0,0,0,0,0,0,0,0,0,0,0,0,0,0,0,0,0,0,0,0,0,0,0,0,0
0,0,0,0,0,0,0,0,0,0,0,0,0,0,0,0,0,0,0,0,0,0,0,0,0,0,0,0,0
0,0,0,0,0,0,0,0,0,0,0,0,0,0,0,0,0,0,0,0,0,0,0,0,0,0,0,0,0
0,0,0,0,0,0,0,0,0,0,0,0,0,0,0,0,0,0,0,0,0,0,0,0,0,0,0,0,0
0,0,0,0,0,0,0,0,0,0,0,0,0,0,0,0,0,0,0,0,0,0,0,0,0,0,0,0,0
0,0,0,0,0,0,0,0,0,0,0,0,0,0,0,0,0,0,0,0,0,0,0,0,0,0,0,0,0
0,0,0,0,0,0,0,0,0,0,0,0,0,0,0,0,0,0,0,0,0,0,0,0,0,0,0,0,0
0,0,0,0,0,0,0,0,0,0,0,0,0,0,0,0,0,0,0,0,0,0,0,0,0,0,0,0,0
0,93,93,93,93,93,93,93,93,93,93,93,93,93,93,93,93,93,93,93,93,93,93,93,93,93,93,93,93
0,0,0,0,0,0,0,0,0,0,0,0,0,0,0,0,0,0,0,0,0,0,0,0,0,0,0,0,0
0,0,0,0,0,0,0,0,0,0,0,0,0,0,0,0,0,0,0,0,0,0,0,0,0,0,0,0,0
0,0,0,0,0,0,0,0,0,0,0,0,0,0,0,0,0,0,0,0,0,0,0,0,0,0,0,0,0
0,0,0,0,0,0,0,0,0,0,0,0,0,0,0,0,0,0,0,0,0,0,0,0,0,0,0,0,0
0,0,0,0,0,0,0,0,0,0,0,0,0,0,0,0,0,0,0,0,0,0,0,0,0,0,0,0,0
0,0,0,0,0,0,0,0,0,0,0,0,0,0,0,0,0,0,0,0,0,0,0,0,0,0,0,0,0
0,0,0,0,0,0,0,0,0,0,0,0,0,0,0,0,0,0,0,0,0,0,0,0,0,0,0,0,0
endlayer

