
# Created by Ruins mod version 17.1 Ingame Parser
# authoring Player: Nemsun

# criterion expression specifying mod ids required to load template
# may include plus (AND), minus (AND NOT), comma (OR), and parentheses
# all required mods listed must be present; no prohibited mods can be
requiredMods=
# likelihood this template will be chosen relative to all others
# e.g., a weight=6 template is chosen 3X as often as one with weight=2
weight=1
# list of other biomes in which this template may spawn
# biome corresponding to directory is always assumed, listed or not
# generic templates should leave this list empty
biomesToSpawnIn=
# criterion expression specifying types of biome where template spawns
# this is in addition to those explicitly listed as biomesToSpawnIn
# generic templates should leave this list empty
biomeTypesToSpawnIn=
# list of biomes in which this template may not spawn
# takes precedence over biomeTypesToSpawnIn, but NOT biomesToSpawnIn
# should be empty if biomeTypesToSpawnIn is empty
biomesToNotSpawnIn=
# depth template is pushed down into the surface when built
# offset is min/max range of random additional bury depth
embed_into_distance=6
random_height_offset=0,0
# whitelist/blacklist of block types on which template may be built
# specify one, not both; leave the other empty (both empty = allow all)
acceptable_target_blocks=
unacceptable_target_blocks=flowing_water,water,flowing_lava,lava
# size of template (#layers, #rows per layer, #blocks per row)
dimensions=11,11,13
# max number of missing blocks allowed in surface beneath template
allowable_overhang=0
# depth/height limit affected by terrain leveling
# also maximum bumpiness tolerated in surface beneath template
max_leveling=2
# padding applied to all sides of template horizontal footprint
# expands area affected by terrain leveling (-1 = no leveling)
leveling_buffer=2
# do not rotate template randomly when built (1 = no rotation)
preventRotation=0
# treat water/lava blocks as air and protect them from rule0 (1 = yes)
preserve_water=0
preserve_lava=0
# minimum distance this template must have from instances of itself
uniqueMinDistance=100
# min/max distances this template can be from world spawn (0 = no limit)
# only applies to overworld--i.e., dimension 0
spawnMinDistance=0
spawnMaxDistance=0
# other template built nearby whenever this one is
# syntax: <name>;<relativeX>;<maxYdifference>;<relativeZ>[;<chance>]
# may be used more than once to specify multiple neighbors
adjoining_template=

rule1=0,100,minecraft:stone-0
rule2=0,100,minecraft:dirt-0
rule3=0,100,minecraft:wooden_slab-0
rule4=0,100,minecraft:log-0
rule5=0,100,minecraft:red_mushroom-0
rule6=0,100,minecraft:brown_mushroom-0
rule7=0,100,minecraft:ladder-4
rule8=0,100,minecraft:oak_stairs-7
rule9=0,100,minecraft:wooden_slab-8
rule10=0,100,minecraft:oak_stairs-6
rule11=0,100,minecraft:oak_stairs-4
rule12=0,100,minecraft:farmland-7
rule13=0,100,minecraft:grass_path-0
rule14=0,100,minecraft:water-0
rule15=0,100,minecraft:planks-0
rule16=0,100,minecraft:planks-2
rule17=0,100,minecraft:crafting_table-0
rule18=0,100,minecraft:trapdoor-11
rule19=0,100,minecraft:potatoes-7
rule20=0,100,minecraft:carrots-7
rule21=0,100,minecraft:wheat-7
rule22=0,100,minecraft:wooden_door-2
rule23=0,100,ChestGenHook:chests/simple_dungeon:5-5
rule24=0,100,contenttweaker:nb2-0
rule25=0,100,minecraft:furnace-5
rule26=0,100,minecraft:wooden_door-3
rule27=2,100,WallSign:Deliver to:NemGo:Farmhouse:null-5
rule28=0,100,minecraft:wooden_door-1
rule29=0,100,ChestGenHook:chests/simple_dungeon:5-3
rule30=2,100,minecraft:torch-2
rule31=2,100,minecraft:torch-4
rule32=0,100,minecraft:wooden_door-8
rule33=0,100,minecraft:glass_pane-0
rule34=2,100,minecraft:torch-3
rule35=2,100,WallSign:null:THE:FARMHOUSE:null-2
rule36=2,100,WallSign:null:Other Farming:MISC:null-5
rule37=2,100,WallSign:null:ANIMAL:FEED:null-5
rule38=2,100,WallSign:null:BRITISH:FOOD:null-5
rule39=2,100,WallSign:null:BONEMEAL:(Please Donate):null-3
rule40=2,100,WallSign:null:THE:FARMHOUSE:null-3
rule41=2,100,minecraft:torch-1
rule42=0,100,minecraft:double_wooden_slab-0

layer
1,1,1,1,1,1,1,1,1,1,1,1,1
1,1,1,1,1,1,1,1,1,1,1,1,1
1,1,1,1,1,1,1,1,1,1,1,1,1
1,1,1,1,1,1,1,1,1,1,1,1,1
1,1,1,1,1,1,1,1,1,1,1,1,1
1,1,1,1,1,1,1,1,1,1,1,1,1
1,1,1,1,1,1,1,1,1,1,1,1,1
1,1,1,1,1,1,1,1,1,1,1,1,1
1,1,1,1,1,1,1,1,1,1,1,1,1
1,1,1,1,1,1,1,1,1,1,1,1,1
1,1,1,1,1,1,1,1,1,1,1,1,1
endlayer

layer
1,1,2,2,2,2,2,2,2,1,1,1,1
1,1,2,2,2,2,2,2,2,1,1,1,1
1,1,2,3,3,3,3,3,2,1,1,1,1
1,1,2,2,2,3,2,2,2,1,1,1,1
1,1,2,3,3,3,3,3,2,1,1,1,1
1,1,2,3,2,3,2,3,2,1,1,1,1
1,1,2,2,2,3,2,2,2,1,1,1,1
1,1,1,1,1,4,1,1,1,1,1,1,1
1,1,1,1,1,1,1,1,1,1,1,1,1
1,1,1,1,1,1,1,1,1,1,1,1,1
1,1,1,1,1,1,1,1,1,1,1,1,1
endlayer

layer
2,2,2,2,2,2,2,2,2,2,2,1,1
2,2,0,0,0,0,0,0,0,2,2,1,1
2,2,0,0,0,0,0,0,0,2,2,1,1
2,2,0,0,0,0,0,0,0,2,2,1,1
2,2,0,0,0,0,0,0,0,2,2,1,1
2,2,6,0,0,0,0,0,5,2,2,1,1
2,2,6,6,0,7,0,5,5,2,2,1,1
1,1,2,2,2,4,2,2,2,2,2,1,1
1,1,1,1,1,1,1,1,1,2,2,1,1
1,1,1,1,1,1,1,1,1,1,1,1,1
1,1,1,1,1,1,1,1,1,1,1,1,1
endlayer

layer
2,2,2,2,2,2,2,2,2,2,2,2,2
2,2,2,2,2,2,2,2,2,2,2,2,2
2,2,10,9,9,9,9,9,8,2,2,2,2
2,2,10,9,9,9,9,9,8,2,2,2,2
2,2,10,9,9,9,9,9,8,2,2,2,2
2,2,10,9,9,9,9,9,8,2,2,2,2
2,2,11,11,11,7,11,11,11,2,2,2,2
2,2,2,2,2,4,2,2,2,2,2,2,2
2,2,2,2,2,2,2,2,2,2,2,2,2
2,2,2,2,2,2,2,2,2,2,2,2,2
2,2,2,2,2,2,2,2,2,2,2,2,2
endlayer

layer
2,2,2,2,2,2,2,2,2,2,2,2,2
2,2,2,2,2,2,2,2,2,2,2,2,2
2,2,2,2,2,2,2,2,2,2,2,2,2
2,2,2,2,2,2,2,2,2,2,2,2,2
2,2,2,2,2,2,2,2,2,2,2,2,2
2,2,2,2,2,2,2,2,2,2,2,2,2
2,2,2,2,2,7,2,2,2,2,2,2,2
2,2,2,2,2,4,2,2,2,2,2,2,2
2,2,2,2,2,2,2,2,2,2,2,2,2
2,2,2,2,2,2,2,2,2,2,2,2,2
2,2,2,2,2,2,2,2,2,2,2,2,2
endlayer

layer
12,12,12,12,12,12,12,13,12,12,12,12,12
12,12,12,12,12,12,12,13,12,12,12,12,12
12,12,12,12,12,12,12,13,12,12,12,12,12
12,2,2,14,2,2,2,15,2,14,12,12,12
12,2,16,16,16,16,16,16,16,2,12,12,12
13,15,16,16,16,16,16,17,16,15,13,13,13
12,2,16,16,16,18,16,16,16,2,12,12,12
12,14,1,1,1,4,1,1,1,14,12,12,12
12,12,12,12,12,12,12,12,12,12,12,12,12
12,12,12,12,12,12,12,12,12,12,12,12,12
12,12,12,12,12,12,12,12,12,12,12,12,12
endlayer

layer
21,19,20,19,21,21,21,0,21,21,20,19,19
19,21,19,21,19,19,19,0,21,21,21,21,19
21,19,20,21,20,21,19,0,21,20,21,20,21
20,4,1,1,1,4,1,22,1,4,21,21,19
21,1,23,24,25,24,23,0,0,1,19,20,21
0,28,0,0,0,27,0,0,0,26,0,0,0
21,1,0,0,0,0,0,0,29,1,19,19,21
20,4,1,1,1,4,1,1,1,4,19,21,20
19,21,21,20,21,19,21,21,19,21,20,19,19
21,19,19,19,19,21,19,19,19,21,20,21,19
20,21,21,21,19,21,21,19,19,21,19,20,21
endlayer

layer
0,0,0,0,0,0,0,0,0,0,0,0,0
0,0,0,0,0,0,0,0,0,0,0,0,0
0,30,0,0,0,30,0,0,0,30,0,0,0
34,4,1,33,1,4,1,32,1,4,31,0,0
0,1,38,0,0,0,37,0,36,1,35,0,0
0,32,0,0,0,0,0,0,0,32,0,0,0
40,1,0,0,0,30,0,0,39,1,0,0,0
34,4,1,33,1,4,1,33,1,4,31,0,0
0,0,0,0,0,41,0,0,0,41,0,0,0
0,0,0,0,0,0,0,0,0,0,0,0,0
0,0,0,0,0,0,0,0,0,0,0,0,0
endlayer

layer
0,0,0,0,0,0,0,0,0,0,0,0,0
0,0,0,0,0,0,0,0,0,0,0,0,0
0,0,0,0,0,0,0,0,0,0,0,0,0
0,4,1,1,1,4,1,1,1,4,0,0,0
0,1,0,0,0,0,0,0,0,1,0,0,0
0,1,0,0,0,0,0,0,0,1,0,0,0
0,1,0,0,0,0,0,0,0,1,0,0,0
0,4,1,1,1,4,1,1,1,4,0,0,0
0,0,0,0,0,0,0,0,0,0,0,0,0
0,0,0,0,0,0,0,0,0,0,0,0,0
0,0,0,0,0,0,0,0,0,0,0,0,0
endlayer

layer
0,0,0,0,0,0,0,0,0,0,0,0,0
0,0,0,0,0,0,0,0,0,0,0,0,0
3,3,3,3,3,3,3,3,3,3,3,0,0
3,42,42,42,42,42,42,42,42,42,3,0,0
3,42,9,0,0,0,0,0,9,42,3,0,0
3,42,0,0,0,0,0,0,0,42,3,0,0
3,42,9,0,0,0,0,0,9,42,3,0,0
3,42,42,42,42,42,42,42,42,42,3,0,0
3,3,3,3,3,3,3,3,3,3,3,0,0
0,0,0,0,0,0,0,0,0,0,0,0,0
0,0,0,0,0,0,0,0,0,0,0,0,0
endlayer

layer
0,0,0,0,0,0,0,0,0,0,0,0,0
0,0,0,0,0,0,0,0,0,0,0,0,0
0,0,0,0,0,0,0,0,0,0,0,0,0
0,0,0,0,0,0,0,0,0,0,0,0,0
0,0,3,3,3,3,3,3,3,0,0,0,0
0,0,3,3,3,3,3,3,3,0,0,0,0
0,0,3,3,3,3,3,3,3,0,0,0,0
0,0,0,0,0,0,0,0,0,0,0,0,0
0,0,0,0,0,0,0,0,0,0,0,0,0
0,0,0,0,0,0,0,0,0,0,0,0,0
0,0,0,0,0,0,0,0,0,0,0,0,0
endlayer

