
# Created by Ruins mod version 17.1 Ingame Parser
# authoring Player: Nemsun

# criterion expression specifying mod ids required to load template
# may include plus (AND), minus (AND NOT), comma (OR), and parentheses
# all required mods listed must be present; no prohibited mods can be
requiredMods=
# likelihood this template will be chosen relative to all others
# e.g., a weight=6 template is chosen 3X as often as one with weight=2
weight=1
# list of other biomes in which this template may spawn
# biome corresponding to directory is always assumed, listed or not
# generic templates should leave this list empty
biomesToSpawnIn=
# criterion expression specifying types of biome where template spawns
# this is in addition to those explicitly listed as biomesToSpawnIn
# generic templates should leave this list empty
biomeTypesToSpawnIn=
# list of biomes in which this template may not spawn
# takes precedence over biomeTypesToSpawnIn, but NOT biomesToSpawnIn
# should be empty if biomeTypesToSpawnIn is empty
biomesToNotSpawnIn=
# depth template is pushed down into the surface when built
# offset is min/max range of random additional bury depth
embed_into_distance=0
random_height_offset=0,0
# whitelist/blacklist of block types on which template may be built
# specify one, not both; leave the other empty (both empty = allow all)
acceptable_target_blocks=
unacceptable_target_blocks=flowing_water,water,flowing_lava,lava
# size of template (#layers, #rows per layer, #blocks per row)
dimensions=8,18,17
# max number of missing blocks allowed in surface beneath template
allowable_overhang=0
# depth/height limit affected by terrain leveling
# also maximum bumpiness tolerated in surface beneath template
max_leveling=2
# padding applied to all sides of template horizontal footprint
# expands area affected by terrain leveling (-1 = no leveling)
leveling_buffer=0
# do not rotate template randomly when built (1 = no rotation)
preventRotation=0
# treat water/lava blocks as air and protect them from rule0 (1 = yes)
preserve_water=0
preserve_lava=0
# minimum distance this template must have from instances of itself
uniqueMinDistance=0
# min/max distances this template can be from world spawn (0 = no limit)
# only applies to overworld--i.e., dimension 0
spawnMinDistance=0
spawnMaxDistance=0
# other template built nearby whenever this one is
# syntax: <name>;<relativeX>;<maxYdifference>;<relativeZ>[;<chance>]
# may be used more than once to specify multiple neighbors
adjoining_template=

rule1=0,100,minecraft:sandstone-0
rule2=0,100,minecraft:sand-0
rule3=0,100,minecraft:sandstone_stairs-0
rule4=0,100,minecraft:cactus-4
rule5=0,100,minecraft:wooden_slab-9
rule6=0,100,minecraft:sandstone_stairs-3
rule7=1,100,minecraft:torch-5
rule8=0,100,minecraft:cactus-1
rule9=0,100,minecraft:planks-1
rule10=0,100,minecraft:crafting_table-0
rule11=0,100,minecraft:cactus-3
rule12=0,100,minecraft:sandstone_stairs-1
rule13=0,100,minecraft:sandstone-2
rule14=0,100,minecraft:cactus-0
rule15=0,100,minecraft:fence-0
rule16=0,100,minecraft:leaves-4
rule17=0,100,minecraft:cactus-8
rule18=0,100,ChestGenHook:chests/simple_dungeon:5-3
rule19=0,100,minecraft:fence_gate-3
rule20=0,100,minecraft:spruce_stairs-6
rule21=0,100,ChestGenHook:chests/simple_dungeon:5-5
rule22=0,100,minecraft:wooden_pressure_plate-0
rule23=0,100,minecraft:spruce_stairs-4
rule24=0,100,minecraft:flower_pot-0
rule25=0,100,minecraft:sandstone_stairs-2
rule26=0,100,ChestGenHook:chests/simple_dungeon:5-2
rule27=0,100,minecraft:spruce_stairs-5
rule28=0,100,minecraft:spruce_stairs-3
rule29=0,100,minecraft:bed-10
rule30=0,100,minecraft:bed-2
rule31=0,100,minecraft:spruce_stairs-2
rule32=2,100,minecraft:torch-4
rule33=0,100,contenttweaker:nb8-0
rule34=0,100,ChestGenHook:chests/simple_dungeon:5-4
rule35=0,100,minecraft:spruce_stairs-7
rule36=0,100,minecraft:cactus-2
rule37=0,100,minecraft:fence_gate-1
rule38=2,100,minecraft:torch-1
rule39=2,100,WallSign:Deliver to:NemGo:Desert House:null-4
rule40=2,100,minecraft:wooden_button-2
rule41=2,100,minecraft:wooden_button-4
rule42=2,100,minecraft:wooden_button-3
rule43=0,100,minecraft:sandstone_stairs-4
rule44=0,100,minecraft:spruce_stairs-1
rule45=0,100,minecraft:spruce_stairs-0
rule46=0,100,minecraft:double_wooden_slab-1
rule47=0,100,minecraft:sandstone_stairs-6
rule48=0,100,minecraft:sandstone_stairs-7
rule49=2,100,minecraft:wooden_button-1
rule50=0,100,minecraft:sandstone_stairs-5
rule51=0,100,minecraft:wooden_slab-1
rule52=0,100,minecraft:fence_gate-2
rule53=0,100,minecraft:trapdoor-1
rule54=0,100,minecraft:trapdoor-3
rule55=0,100,minecraft:trapdoor-0

layer
1,1,1,1,1,1,1,1,1,1,1,1,1,1,1,1,1
1,1,1,1,1,1,1,1,1,1,1,1,1,1,1,1,1
1,1,1,1,1,1,1,1,1,1,1,1,1,1,1,1,1
1,1,1,1,1,1,1,1,1,1,1,1,1,1,1,1,1
1,1,1,1,1,1,1,1,1,1,1,1,1,1,1,1,1
1,1,1,1,1,1,1,1,1,1,1,1,1,1,1,1,1
1,1,1,1,1,1,1,1,1,1,1,1,1,1,1,1,1
1,1,1,1,1,1,1,1,1,1,1,1,1,1,1,1,1
1,1,1,1,1,1,1,1,1,1,1,1,1,1,1,1,1
1,1,1,1,1,1,1,1,1,1,1,1,1,1,1,1,1
1,1,1,1,1,1,1,1,1,1,1,1,1,1,1,1,1
1,1,1,1,1,1,1,1,1,1,1,1,1,1,1,1,1
1,1,1,1,1,1,1,1,1,1,1,1,1,1,1,1,1
1,1,1,1,1,1,1,1,1,1,1,1,1,1,1,1,1
1,1,1,1,1,1,1,1,1,1,1,1,1,1,1,1,1
1,1,1,1,1,1,1,1,1,1,1,1,1,1,1,1,1
1,1,1,1,1,1,1,1,1,1,1,1,1,1,1,1,1
1,1,1,1,1,1,1,1,1,1,1,1,1,1,1,1,1
endlayer

layer
2,2,2,2,2,2,2,2,2,2,2,2,2,2,2,2,2
2,2,2,2,2,2,2,2,2,2,2,2,2,2,2,2,2
2,2,2,2,2,2,2,2,2,2,2,2,2,2,1,2,2
2,2,2,2,2,2,2,2,2,2,2,2,2,2,2,2,2
2,2,2,2,2,2,2,2,2,2,2,2,2,2,2,2,2
2,2,2,2,2,2,2,2,2,2,2,2,2,2,2,2,2
2,2,2,2,2,2,2,2,2,2,2,2,2,2,2,2,2
2,2,2,2,2,2,2,2,2,2,2,2,2,2,2,2,2
2,2,2,2,2,2,2,2,2,2,2,2,2,2,2,2,2
2,2,2,2,2,2,2,2,2,2,2,2,2,2,2,2,2
2,2,2,2,2,2,2,2,2,2,2,2,2,2,2,2,2
2,2,2,2,2,2,2,2,2,2,2,2,2,2,2,2,2
2,2,2,2,2,2,2,2,2,2,2,2,2,2,2,2,2
2,2,2,2,2,2,2,2,2,2,2,2,2,2,2,2,2
2,2,2,2,2,2,2,2,2,2,2,2,2,2,2,2,2
2,2,2,2,2,2,2,2,2,2,2,2,2,2,2,2,2
2,2,2,2,2,2,2,2,2,2,2,2,2,2,2,2,2
2,2,2,2,2,2,2,2,2,2,2,2,2,2,2,2,2
endlayer

layer
4,0,1,3,3,3,1,0,0,0,0,0,0,0,0,0,0
0,0,5,1,1,1,5,0,0,0,0,0,0,0,0,0,0
1,5,1,1,1,1,1,5,5,5,1,5,5,5,1,0,0
6,1,1,1,1,1,1,1,1,1,1,1,1,1,5,0,0
6,1,1,1,1,1,1,1,1,1,1,1,1,1,5,7,0
1,5,1,1,1,1,1,5,5,5,1,5,5,5,1,0,0
0,0,0,1,9,1,5,1,1,1,5,1,1,1,0,8,0
1,0,1,5,5,5,5,5,5,5,5,5,5,5,1,0,1
5,1,5,5,5,5,5,5,5,5,10,5,5,5,5,1,5
5,1,5,5,5,5,5,5,5,5,5,5,5,5,5,1,5
5,1,5,5,5,5,5,5,5,5,5,5,5,5,5,1,5
1,5,5,5,5,5,5,5,5,5,5,5,5,5,5,5,1
5,1,5,5,5,5,5,5,5,5,5,5,5,5,5,1,5
5,1,5,5,5,5,5,5,5,5,5,5,5,5,5,1,5
5,1,5,5,5,5,5,5,5,5,5,5,5,5,5,1,5
1,0,1,5,5,5,5,5,5,5,5,5,5,5,1,0,1
0,11,0,1,1,1,5,1,9,1,5,1,1,1,0,8,0
0,0,1,5,5,5,1,12,12,12,1,5,5,5,1,0,0
endlayer

layer
14,0,13,0,0,0,13,0,0,0,0,0,0,0,0,0,0
0,0,15,0,0,0,15,0,0,0,0,0,0,0,0,0,0
13,15,13,0,0,0,13,15,15,15,13,15,15,15,13,0,0
0,0,0,0,0,0,0,0,0,0,0,0,0,0,15,16,0
0,0,0,0,0,0,0,0,0,0,0,0,0,0,15,0,0
13,15,13,0,0,0,13,0,0,0,13,0,16,16,13,0,0
0,0,0,13,19,13,0,2,3,2,18,2,3,2,0,17,0
13,0,13,0,22,0,13,9,21,9,18,9,21,20,13,0,13
24,2,23,0,0,0,23,0,0,0,0,0,0,0,23,2,0
0,6,26,0,0,0,0,0,0,0,0,0,0,0,18,25,24
0,2,27,0,0,0,0,0,0,0,0,0,0,0,27,2,0
13,32,2,31,0,0,0,0,30,29,0,0,0,28,2,7,13
0,2,23,0,0,0,33,0,0,0,0,0,0,0,23,2,0
0,6,26,0,0,33,33,0,0,0,0,0,0,0,18,25,0
24,2,27,0,0,0,0,0,0,0,0,0,0,0,27,2,24
13,0,13,35,34,20,0,0,22,0,0,35,34,20,13,0,13
0,36,0,2,12,2,23,13,37,13,23,2,12,2,0,36,0
0,0,13,0,0,24,13,0,0,0,13,0,24,0,13,0,0
endlayer

layer
14,0,15,0,0,0,15,0,0,0,0,0,0,0,0,0,0
0,0,15,0,0,0,15,0,0,0,0,0,0,0,0,0,0
15,15,2,0,0,0,2,0,0,0,2,0,0,0,2,0,0
0,0,0,0,0,0,0,0,0,0,0,0,0,0,16,16,0
0,0,0,0,0,0,0,0,0,0,0,0,0,0,0,0,0
15,15,2,0,0,0,2,0,0,0,2,0,0,16,2,0,0
0,0,0,2,0,2,0,2,15,2,18,2,15,2,16,0,0
2,0,2,38,0,38,2,9,15,9,18,9,15,9,2,16,2
0,2,9,0,0,0,9,0,0,0,0,0,0,0,9,2,0
0,15,15,0,0,0,0,0,0,0,0,0,0,0,15,15,0
0,2,0,0,0,0,0,0,0,0,0,0,0,0,0,2,0
2,0,8,0,0,0,0,0,0,0,0,0,0,0,14,0,2
0,2,0,0,0,0,39,0,0,0,0,0,0,0,0,2,0
0,15,15,0,0,0,33,0,0,0,0,0,0,0,15,15,0
0,2,9,0,0,0,0,0,0,0,0,0,0,0,9,2,0
2,0,2,9,15,9,0,0,0,0,0,9,15,9,2,0,2
0,14,0,2,15,2,7,2,0,2,24,2,15,2,0,14,0
0,0,2,0,0,0,2,0,0,0,2,0,0,0,2,0,0
endlayer

layer
0,0,7,0,0,0,7,0,0,0,0,0,0,0,0,0,0
0,0,9,0,0,0,9,0,0,0,40,0,0,0,40,0,0
7,42,13,0,0,0,13,0,0,0,13,0,0,0,13,41,0
0,0,0,0,0,0,0,0,0,0,0,0,0,0,16,16,0
0,0,0,0,0,0,0,0,0,0,0,16,0,16,16,0,0
7,42,13,0,0,0,13,0,0,0,13,16,16,16,13,41,0
0,0,0,13,13,13,0,2,43,2,44,2,43,2,16,16,40
13,0,13,13,13,13,13,28,7,31,0,28,7,31,13,16,13
0,2,31,46,46,46,28,0,0,0,0,0,0,0,45,2,0
0,48,7,0,0,0,0,0,0,0,0,0,0,0,7,47,0
0,2,44,0,0,0,0,0,0,0,0,0,0,0,44,2,0
13,20,46,0,0,0,0,0,0,0,0,0,0,0,46,35,13
0,2,45,0,0,0,0,0,0,0,0,0,0,0,45,2,0
0,48,7,0,0,0,0,0,0,0,0,0,0,0,7,47,0
0,2,44,0,0,0,0,0,0,0,0,0,0,0,44,2,0
13,0,13,28,7,31,46,46,46,46,46,28,7,31,13,0,13
49,0,0,2,50,2,13,13,13,13,13,2,50,2,0,0,49
0,42,13,0,0,0,13,0,0,0,13,0,0,0,13,41,0
endlayer

layer
0,0,0,0,0,0,0,0,0,0,0,0,0,0,0,0,0
0,0,0,51,51,51,0,0,0,0,0,0,0,0,0,0,0
0,0,1,51,51,51,1,43,43,43,1,43,43,43,1,0,0
0,0,51,51,51,51,52,52,52,52,52,52,52,52,47,16,0
0,0,51,51,51,51,52,52,52,52,52,52,52,52,47,0,0
0,0,1,51,51,51,1,1,1,1,1,1,1,1,1,0,0
0,0,0,1,1,1,51,51,51,51,51,51,51,51,51,0,0
51,51,51,51,51,51,51,51,51,51,51,51,51,51,51,51,51
51,51,51,51,51,51,51,51,51,51,51,51,51,51,51,51,51
51,51,51,51,55,51,51,51,54,51,51,51,53,51,51,51,51
51,51,51,51,51,51,51,51,51,51,51,51,51,51,51,51,51
51,51,51,51,51,51,51,51,51,51,51,51,51,51,51,51,51
51,51,51,51,51,51,51,51,51,51,51,51,51,51,51,51,51
51,51,51,51,55,51,51,51,53,51,51,51,53,51,51,51,51
51,51,51,51,51,51,51,51,51,51,51,51,51,51,51,51,51
51,51,51,51,51,51,51,51,51,51,51,51,51,51,51,51,51
0,0,51,51,51,51,51,51,51,51,51,51,51,51,51,0,0
0,0,51,51,51,51,51,51,51,51,51,51,51,51,51,0,0
endlayer

layer
0,0,0,0,0,0,0,0,0,0,0,0,0,0,0,0,0
0,0,0,0,0,0,0,0,0,0,0,0,0,0,0,0,0
0,0,7,0,0,0,7,0,7,0,7,0,7,0,7,0,0
0,0,0,0,0,0,0,0,0,0,0,0,0,16,16,0,0
0,0,0,0,0,0,0,0,0,0,0,16,16,16,0,0,0
0,0,7,0,0,0,7,0,7,0,7,0,7,0,7,0,0
0,0,0,0,7,0,0,0,0,0,0,0,0,0,0,0,0
0,0,0,0,0,0,0,0,0,0,0,0,0,0,0,0,0
0,0,0,0,0,0,0,0,0,0,0,0,0,0,0,0,0
0,0,0,0,0,0,0,0,0,0,0,0,0,0,0,0,0
0,0,0,0,0,0,0,0,0,0,0,0,0,0,0,0,0
0,0,0,0,0,0,0,0,0,0,0,0,0,0,0,0,0
0,0,0,0,0,0,0,0,0,0,0,0,0,0,0,0,0
0,0,0,0,0,0,0,0,0,0,0,0,0,0,0,0,0
0,0,0,0,0,0,0,0,0,0,0,0,0,0,0,0,0
0,0,0,0,0,0,0,0,0,0,0,0,0,0,0,0,0
0,0,0,0,0,0,0,0,0,0,0,0,0,0,0,0,0
0,0,0,0,0,0,0,0,0,0,0,0,0,0,0,0,0
endlayer

