
# Created by Ruins mod version 17.1 Ingame Parser
# authoring Player: Nemsun

# criterion expression specifying mod ids required to load template
# may include plus (AND), minus (AND NOT), comma (OR), and parentheses
# all required mods listed must be present; no prohibited mods can be
requiredMods=
# likelihood this template will be chosen relative to all others
# e.g., a weight=6 template is chosen 3X as often as one with weight=2
weight=1
# list of other biomes in which this template may spawn
# biome corresponding to directory is always assumed, listed or not
# generic templates should leave this list empty
biomesToSpawnIn=
# criterion expression specifying types of biome where template spawns
# this is in addition to those explicitly listed as biomesToSpawnIn
# generic templates should leave this list empty
biomeTypesToSpawnIn=
# list of biomes in which this template may not spawn
# takes precedence over biomeTypesToSpawnIn, but NOT biomesToSpawnIn
# should be empty if biomeTypesToSpawnIn is empty
biomesToNotSpawnIn=
# depth template is pushed down into the surface when built
# offset is min/max range of random additional bury depth
embed_into_distance=4
random_height_offset=0,0
# whitelist/blacklist of block types on which template may be built
# specify one, not both; leave the other empty (both empty = allow all)
acceptable_target_blocks=
unacceptable_target_blocks=flowing_water,water,flowing_lava,lava
# size of template (#layers, #rows per layer, #blocks per row)
dimensions=17,15,30
# max number of missing blocks allowed in surface beneath template
allowable_overhang=0
# depth/height limit affected by terrain leveling
# also maximum bumpiness tolerated in surface beneath template
max_leveling=2
# padding applied to all sides of template horizontal footprint
# expands area affected by terrain leveling (-1 = no leveling)
leveling_buffer=0
# do not rotate template randomly when built (1 = no rotation)
preventRotation=0
# treat water/lava blocks as air and protect them from rule0 (1 = yes)
preserve_water=0
preserve_lava=0
# minimum distance this template must have from instances of itself
uniqueMinDistance=500
# min/max distances this template can be from world spawn (0 = no limit)
# only applies to overworld--i.e., dimension 0
spawnMinDistance=0
spawnMaxDistance=0
# other template built nearby whenever this one is
# syntax: <name>;<relativeX>;<maxYdifference>;<relativeZ>[;<chance>]
# may be used more than once to specify multiple neighbors
adjoining_template=

rule1=0,100,minecraft:dirt-0
rule2=0,100,minecraft:grass-0
rule3=0,100,minecraft:stone-0
rule4=0,100,minecraft:glowstone-0
rule5=0,100,minecraft:cobblestone-0
rule6=0,100,minecraft:water-0
rule7=0,100,minecraft:oak_stairs-3
rule8=0,100,ChestGenHook:chests/simple_dungeon:5-5
rule9=0,100,minecraft:oak_stairs-2
rule10=0,100,minecraft:planks-0
rule11=0,100,minecraft:bookshelf-0
rule12=0,100,ChestGenHook:chests/simple_dungeon:5-2
rule13=0,100,minecraft:enchanting_table-0
rule14=0,100,minecraft:trapped_chest-2
rule15=0,100,minecraft:log-0
rule16=0,100,minecraft:reeds-2
rule17=0,100,minecraft:waterlily-0
rule18=0,100,minecraft:reeds-0
rule19=0,100,minecraft:reeds-1
rule20=0,100,minecraft:reeds-3
rule21=0,100,minecraft:oak_stairs-0
rule22=0,100,minecraft:stonebrick-0
rule23=0,100,minecraft:leaves-4
rule24=0,100,minecraft:fence-0
rule25=0,100,minecraft:stone_stairs-4
rule26=0,100,minecraft:oak_stairs-6
rule27=0,100,minecraft:oak_stairs-7
rule28=0,100,minecraft:stone_stairs-6
rule29=0,100,minecraft:stone_stairs-7
rule30=0,100,minecraft:stone_stairs-5
rule31=0,100,minecraft:leaves-12
rule32=0,100,minecraft:oak_stairs-1
rule33=0,100,minecraft:spruce_stairs-4
rule34=0,100,minecraft:wooden_slab-9
rule35=0,100,minecraft:spruce_stairs-6
rule36=0,100,minecraft:spruce_stairs-7
rule37=2,100,WallSign:null:Need most:Clay &:Glowstone-5
rule38=2,100,WallSign:null:Donations:In Here:null-5
rule39=0,100,minecraft:ladder-4
rule40=0,100,minecraft:wooden_door-2
rule41=0,100,minecraft:oak_stairs-5
rule42=0,100,minecraft:spruce_stairs-5
rule43=0,100,minecraft:planks-2
rule44=2,100,WallSign:null:TO SORT:null:null-4
rule45=0,100,ChestGenHook:chests/simple_dungeon:5-4
rule46=0,100,minecraft:wooden_door-9
rule47=0,100,minecraft:wooden_door-8
rule48=0,100,minecraft:glass_pane-0
rule49=0,100,realistictorches:torch_unlit-1
rule50=0,100,realistictorches:torch_unlit-3
rule51=0,100,realistictorches:torch_unlit-5
rule52=0,100,realistictorches:torch_unlit-4
rule53=0,100,realistictorches:torch_unlit-2
rule54=2,100,WallSign:BOOK DEPOSITS:null:FOR THE LAZY:null-4
rule55=2,100,minecraft:torch-3
rule56=2,100,minecraft:torch-4
rule57=0,100,minecraft:spruce_stairs-2
rule58=0,100,minecraft:spruce_stairs-3
rule59=0,100,minecraft:spruce_stairs-1
rule60=2,100,minecraft:torch-2
rule61=2,100,WallSign:null:NemGo:Library:null-5
rule62=2,100,WallSign:null:Ye Old:Book Shop:null-5
rule63=0,100,minecraft:stone_brick_stairs-6
rule64=0,100,minecraft:stone_brick_stairs-4
rule65=0,100,minecraft:planks-1
rule66=0,100,minecraft:wooden_slab-1
rule67=0,100,minecraft:stone_brick_stairs-5
rule68=0,100,minecraft:stone_brick_stairs-0
rule69=0,100,minecraft:stone_brick_stairs-7
rule70=0,100,minecraft:stone_slab-13
rule71=0,100,minecraft:trapdoor-11
rule72=0,100,minecraft:stone_brick_stairs-3
rule73=0,100,minecraft:stone_brick_stairs-2
rule74=0,100,minecraft:stone_brick_stairs-1
rule75=0,100,minecraft:stone_slab-5
rule76=0,100,minecraft:spruce_stairs-0
rule77=0,100,minecraft:birch_stairs-2
rule78=2,100,WallSign:Deliver to:NemGo Library:null:Old Books-4
rule79=0,100,minecraft:birch_stairs-3
rule80=0,100,contenttweaker:nb4-0
rule81=0,100,minecraft:birch_stairs-6
rule82=0,100,minecraft:birch_stairs-7
rule83=0,100,minecraft:log-9

layer
1,1,1,1,1,1,1,1,1,1,1,1,1,1,1,1,1,1,1,1,1,1,1,1,1,1,1,1,1,1
1,1,1,1,1,1,1,1,1,1,1,1,1,1,1,1,1,1,1,1,1,1,1,1,1,1,1,1,1,1
1,1,1,1,1,1,1,1,1,1,1,1,1,3,3,3,3,1,1,1,1,1,1,2,1,2,1,1,1,1
1,1,1,1,1,1,1,1,1,1,1,1,1,3,3,3,3,1,1,1,1,1,2,1,2,1,2,1,1,1
1,1,1,1,1,1,1,1,1,1,1,1,1,3,3,3,3,1,1,1,1,1,1,2,1,2,1,1,1,1
1,1,1,1,1,1,1,1,1,1,1,1,1,3,3,3,3,1,2,1,2,1,1,1,2,1,2,1,1,1
1,1,1,1,1,1,1,1,1,1,1,1,1,3,3,3,3,2,1,2,1,2,1,2,1,1,1,1,1,1
1,1,1,1,1,1,1,1,1,1,1,1,1,3,3,3,3,1,2,1,2,1,2,1,2,1,2,1,1,1
1,1,1,1,1,1,1,1,1,1,1,1,1,3,3,3,3,1,1,2,1,2,1,2,1,2,1,1,1,1
1,1,1,1,1,1,1,1,1,1,1,1,1,1,1,3,1,1,1,1,1,1,1,1,1,1,1,1,1,1
1,1,1,1,1,1,1,1,1,1,1,1,1,1,1,3,1,1,1,1,1,1,1,1,1,1,1,1,1,1
1,1,1,1,1,1,1,1,1,1,1,1,1,1,3,3,4,3,4,1,1,1,1,1,1,1,1,1,1,1
1,1,1,1,1,1,1,1,1,1,1,1,1,1,3,3,3,3,3,1,1,1,1,1,1,1,1,1,1,1
1,1,1,1,1,1,1,1,1,1,1,1,1,1,3,3,4,3,4,1,1,1,1,1,1,1,1,1,1,1
1,1,1,1,1,1,1,1,1,1,1,1,1,1,1,1,1,1,1,1,1,1,1,1,1,1,1,1,1,1
endlayer

layer
1,1,1,1,1,1,1,1,1,1,1,1,1,1,1,1,1,1,1,1,1,1,1,1,1,1,1,1,1,1
1,1,1,1,1,1,1,1,1,1,1,1,5,5,5,5,5,5,1,1,1,1,1,1,1,1,1,1,1,1
1,1,1,1,6,1,6,1,6,1,6,1,9,0,8,8,0,7,2,6,2,6,2,6,2,6,2,1,1,1
1,1,1,6,1,6,1,6,1,6,1,6,9,0,0,0,0,7,6,2,6,2,6,2,6,2,6,1,1,1
1,1,1,1,6,1,6,1,6,1,6,1,9,0,0,0,0,7,2,6,2,6,2,6,2,6,2,1,1,1
1,1,1,6,1,6,1,6,1,6,1,6,9,0,0,0,0,7,6,2,6,2,6,2,6,2,6,1,1,1
1,1,1,1,6,1,6,1,6,1,6,1,9,0,0,0,0,7,2,6,2,6,2,6,2,6,2,1,1,1
1,1,1,6,1,6,1,6,1,6,1,6,9,0,0,0,0,7,6,2,6,2,6,2,6,2,6,1,1,1
1,1,1,1,6,1,6,1,6,1,6,1,9,0,0,0,0,7,2,6,2,6,2,6,2,6,2,1,1,1
1,1,1,6,1,6,1,6,1,6,1,1,5,5,5,5,5,5,1,1,1,1,1,1,10,10,10,1,1,1
1,1,1,1,6,1,6,1,6,1,1,1,1,1,3,0,11,11,11,1,1,1,1,1,1,10,10,1,1,1
1,1,1,6,1,6,1,6,1,6,1,1,1,3,12,0,0,0,0,11,1,1,1,1,1,10,10,1,1,1
1,1,1,1,6,1,6,1,6,1,1,1,1,3,14,0,0,13,0,11,1,1,1,1,1,10,10,1,1,1
1,1,1,1,1,1,1,1,1,1,1,1,1,3,12,0,0,0,0,11,1,1,1,1,1,1,1,1,1,1
1,1,1,1,1,1,1,1,1,1,1,1,1,1,3,3,11,11,11,1,1,1,1,1,1,1,1,1,1,1
endlayer

layer
1,1,1,1,1,1,1,1,1,1,1,1,1,1,1,1,1,1,1,1,1,1,1,1,1,1,1,1,1,1
1,1,1,5,5,5,15,5,5,5,15,5,5,5,5,5,5,5,5,15,5,5,5,15,5,5,5,1,1,1
1,1,5,18,17,18,17,18,17,18,17,18,0,0,0,0,0,0,18,17,19,17,19,17,18,17,16,5,1,1
1,1,5,17,18,17,18,17,18,17,16,17,0,0,0,0,0,0,17,19,17,18,17,18,17,18,17,5,1,1
1,1,5,19,17,16,17,18,17,18,17,19,0,0,0,0,0,0,0,17,18,17,18,17,18,17,20,5,1,1
1,1,15,17,18,17,18,17,18,17,18,17,0,0,0,0,0,0,17,18,17,19,17,16,17,18,17,15,1,1
1,1,5,18,17,18,17,18,17,18,17,18,0,0,0,0,0,0,18,17,18,17,18,17,18,17,0,5,1,1
1,1,5,17,18,0,19,17,19,17,19,17,0,0,0,0,0,0,17,18,17,19,17,18,17,18,17,5,1,1
1,1,5,18,17,18,17,18,17,19,17,19,0,0,0,0,0,0,18,17,18,0,18,17,18,17,0,5,1,1
1,1,15,17,18,17,19,17,18,17,15,5,5,5,5,5,5,5,5,15,5,5,5,15,0,0,0,15,1,1
1,1,5,18,17,18,17,19,17,18,5,1,1,1,3,0,11,11,11,1,1,1,1,15,21,0,0,5,1,1
1,1,5,17,18,17,20,17,19,17,5,1,1,3,0,0,0,0,0,11,1,1,1,1,9,0,0,5,1,1
1,1,5,16,17,20,17,18,17,18,5,1,1,3,0,0,0,0,0,11,1,1,1,1,9,0,0,5,1,1
1,1,1,5,5,5,15,5,5,5,1,1,1,3,0,0,0,0,0,11,1,1,1,15,5,5,5,1,1,1
1,1,1,1,1,1,1,1,1,1,1,1,1,1,3,3,11,11,11,1,1,1,1,1,1,1,1,1,1,1
endlayer

layer
2,22,1,22,22,22,1,22,22,22,1,22,22,1,22,22,1,22,22,1,22,22,22,1,22,22,22,1,22,2
2,1,1,5,4,5,15,5,4,5,15,4,4,5,5,5,5,4,4,15,5,4,5,15,5,4,5,1,1,2
2,22,5,19,0,18,0,19,0,18,0,18,0,0,0,0,0,0,18,0,18,0,18,0,16,0,18,5,22,2
2,22,4,0,18,0,18,0,18,0,19,0,0,0,0,0,0,0,0,18,0,18,0,18,0,18,0,4,22,2
2,22,5,18,0,18,0,18,0,19,0,18,0,0,0,0,0,0,0,0,19,0,19,0,18,0,18,5,22,2
2,1,15,0,19,0,19,0,19,0,18,0,0,0,0,0,0,0,0,18,0,19,0,19,0,18,0,15,1,2
2,22,5,18,0,16,0,18,0,19,0,18,0,0,0,0,0,0,18,0,18,0,19,0,19,0,0,5,22,2
2,22,4,0,18,0,16,0,18,0,18,0,0,0,0,0,0,0,0,18,0,18,0,18,0,18,0,4,22,2
2,22,5,19,0,18,0,18,0,16,0,18,0,0,0,0,0,0,18,0,18,0,18,0,16,0,0,5,22,2
2,1,15,0,18,0,19,0,18,0,15,4,4,5,5,5,5,4,4,15,5,4,5,15,0,0,0,15,1,2
2,22,5,18,0,18,0,19,0,18,5,22,22,1,1,1,1,22,22,1,2,2,2,15,0,0,0,5,22,2
2,22,4,0,18,0,19,0,18,0,4,22,22,22,22,22,22,22,22,4,10,10,10,9,0,0,0,4,22,2
2,22,5,18,0,18,0,19,0,19,5,22,22,22,22,22,22,22,22,1,10,10,10,9,0,0,0,5,22,2
2,1,1,5,4,5,15,5,4,5,1,1,22,22,22,22,22,22,3,1,1,4,1,15,5,4,5,1,1,2
2,2,1,22,22,22,1,22,22,22,1,22,2,22,22,22,22,2,22,1,22,22,22,1,22,22,22,1,22,2
endlayer

layer
23,24,15,0,0,0,15,0,0,0,15,0,0,15,0,0,15,0,0,15,0,0,0,15,0,0,0,15,24,23
23,15,15,5,25,5,15,5,25,5,15,5,5,15,5,5,15,5,5,15,5,25,5,15,5,25,5,15,15,23
23,0,5,18,0,18,0,18,0,18,0,18,27,10,10,10,10,26,18,0,18,0,18,0,18,0,18,5,0,23
23,0,29,0,18,0,18,0,18,0,18,0,27,10,10,10,10,26,0,18,0,18,0,18,0,18,0,28,0,23
23,0,5,18,0,18,0,18,0,18,0,18,27,10,10,10,10,26,0,0,18,0,18,0,18,0,18,5,0,23
23,15,15,0,18,0,18,0,18,0,18,0,27,10,10,10,10,26,0,18,0,18,0,18,0,18,0,15,15,23
23,0,5,18,0,18,0,18,0,18,0,18,27,10,10,10,10,26,18,0,18,0,18,0,18,0,0,5,0,23
23,0,29,0,18,0,18,0,18,0,18,0,27,10,10,10,10,26,0,18,0,18,0,18,0,18,0,28,0,23
23,0,5,18,0,18,0,18,0,18,0,18,27,10,10,10,10,26,18,0,18,0,18,0,18,0,0,5,0,23
23,15,15,0,18,0,18,0,18,0,15,30,15,15,10,10,15,15,30,15,5,5,5,15,0,0,0,15,15,23
23,0,5,18,0,18,0,18,0,18,5,0,24,15,32,32,15,24,0,5,32,32,32,15,0,0,0,5,0,31
23,0,29,0,18,0,18,0,18,0,28,0,0,24,0,0,24,0,0,29,0,0,0,0,0,0,0,28,0,31
23,0,5,18,0,18,0,18,0,18,5,0,0,24,0,0,24,0,0,5,0,0,0,0,0,0,0,5,0,31
23,15,15,5,30,5,15,5,30,5,15,15,24,24,0,0,24,24,15,15,5,30,5,15,5,30,5,15,15,31
0,24,15,0,0,0,15,0,0,0,15,24,23,0,0,0,0,23,24,15,0,0,0,15,0,0,0,15,24,0
endlayer

layer
0,24,15,33,34,33,15,33,34,33,15,33,33,15,33,33,15,33,33,15,33,34,33,15,33,34,33,15,24,0
0,15,15,5,5,5,15,5,5,5,15,5,5,15,5,5,15,5,5,15,5,5,5,15,5,5,5,15,15,0
0,36,5,10,10,10,10,10,10,10,10,10,15,35,34,34,36,15,10,10,10,10,10,10,10,10,10,5,35,0
0,34,5,10,10,10,10,10,10,10,10,10,9,0,38,37,0,7,10,10,10,10,10,10,10,10,10,5,34,0
0,36,5,10,10,10,10,10,10,10,10,10,9,0,0,0,0,7,10,10,10,10,10,10,10,10,10,5,35,0
0,15,15,10,10,10,10,10,10,10,10,10,9,0,0,0,0,7,10,10,10,10,10,10,10,10,10,15,15,0
0,36,5,10,10,10,10,10,10,10,10,10,9,0,0,0,0,7,10,10,10,10,10,10,10,10,10,5,35,0
0,34,5,10,10,10,10,10,10,10,10,10,9,0,0,0,0,7,10,10,10,10,10,10,10,10,10,5,34,0
0,36,5,10,10,10,10,10,10,10,10,10,15,39,0,0,39,15,10,10,10,10,10,10,10,10,10,5,35,0
0,15,15,10,10,10,10,10,10,10,15,5,15,15,40,40,15,15,5,15,32,32,32,10,10,10,10,15,15,0
0,36,5,10,10,10,10,10,10,10,5,0,24,15,0,0,15,24,0,5,0,0,0,15,41,41,41,5,35,0
0,34,5,10,10,10,10,10,10,10,5,0,0,24,0,0,24,0,0,5,0,0,0,0,0,0,0,5,34,0
0,36,5,10,10,10,10,10,10,10,5,0,0,0,0,0,0,0,0,5,0,0,0,0,0,0,0,5,35,0
0,15,15,5,5,5,15,5,5,5,15,15,0,0,0,0,0,0,15,15,5,5,5,15,5,5,5,15,15,0
0,24,15,42,34,42,15,42,34,42,15,24,0,0,0,0,0,0,24,15,42,34,42,15,42,34,42,15,24,0
endlayer

layer
0,24,15,0,0,0,15,0,0,0,15,24,24,15,24,24,15,24,24,15,0,0,0,15,0,0,0,15,24,0
0,15,15,43,43,43,15,43,43,43,15,43,43,15,43,43,15,43,43,15,43,43,43,15,43,43,43,15,15,0
0,0,43,11,11,11,11,11,11,11,11,11,15,0,8,8,0,15,11,11,11,11,11,11,11,11,11,43,0,0
0,0,43,11,0,0,0,0,0,0,0,0,0,0,0,0,0,0,0,0,0,0,0,0,0,0,11,43,0,0
0,0,43,11,0,0,0,0,0,0,0,0,0,0,0,0,0,0,0,0,0,0,0,0,0,0,11,43,0,0
0,15,15,11,0,0,11,11,11,11,11,0,0,0,0,0,0,0,0,11,11,11,11,11,0,0,11,15,15,0
0,0,43,11,0,0,11,0,0,0,0,0,0,0,0,0,0,0,0,0,0,0,0,0,0,0,11,43,0,0
0,0,43,11,0,0,11,0,0,0,0,44,0,0,0,0,0,0,0,0,0,0,0,0,0,0,11,43,0,0
0,0,43,11,0,0,11,0,0,11,45,45,15,39,0,0,39,15,0,0,0,0,0,11,11,11,11,43,0,0
0,15,15,11,0,0,11,0,0,11,15,43,15,15,47,46,15,15,43,15,0,0,0,15,0,0,0,15,15,0
0,0,43,11,0,0,0,0,0,11,43,0,24,15,0,0,15,24,0,43,0,0,0,15,0,0,0,43,0,0
0,0,43,11,0,0,0,0,0,11,43,0,0,24,0,0,24,0,0,43,0,0,0,0,0,0,0,43,0,0
0,0,43,11,11,11,11,11,11,11,43,0,0,0,0,0,0,0,0,43,0,0,0,0,0,0,0,43,0,0
0,15,15,43,43,43,15,43,43,43,15,15,0,0,0,0,0,0,15,15,43,43,43,15,43,43,43,15,15,0
0,24,15,0,0,0,15,0,0,0,15,24,0,0,0,0,0,0,24,15,0,0,0,15,0,0,0,15,24,0
endlayer

layer
0,24,15,0,0,0,15,0,0,0,15,24,24,15,0,0,15,24,24,15,0,0,0,15,0,0,0,15,24,0
0,15,15,43,48,43,15,43,48,43,15,43,43,15,48,48,15,43,43,15,43,48,43,15,43,48,43,15,15,0
0,0,43,11,0,11,11,11,0,11,49,11,15,49,0,0,49,15,11,49,11,0,49,11,49,0,11,43,0,0
0,0,48,0,0,0,0,0,0,0,0,0,0,0,0,0,0,0,0,0,0,0,0,0,0,0,0,48,0,0
0,0,43,11,0,0,0,0,0,0,0,0,0,0,0,0,0,0,0,0,0,0,0,0,0,0,50,43,0,0
0,15,15,11,0,0,11,0,0,0,0,0,0,0,0,0,0,0,0,51,11,0,11,0,0,0,11,15,15,0
0,0,43,52,0,0,51,0,0,0,0,0,0,0,0,0,0,0,0,0,0,0,0,0,0,0,50,43,0,0
0,0,48,0,0,0,0,0,0,0,0,0,53,0,0,0,0,53,0,0,0,0,0,0,0,0,0,48,0,0
0,0,43,11,0,0,11,0,0,11,0,54,15,39,0,0,39,15,0,53,0,0,0,11,11,11,11,43,0,0
0,15,15,11,0,0,0,0,0,11,15,43,15,15,33,33,15,15,43,15,56,0,0,15,0,0,55,15,15,0
0,0,43,11,0,0,0,0,0,11,43,0,58,15,0,0,15,57,0,43,0,0,0,15,0,0,0,43,0,0
0,0,48,0,0,0,0,0,0,0,48,0,58,59,59,59,59,57,0,48,0,0,0,0,0,0,0,48,0,0
0,0,43,11,0,11,11,11,0,11,43,0,0,0,62,61,0,0,0,43,0,0,0,60,0,0,0,43,0,0
0,15,15,43,48,43,15,43,48,43,15,15,0,0,0,0,0,0,15,15,43,48,43,15,43,48,43,15,15,0
0,24,15,0,0,0,15,0,0,0,15,24,0,0,0,0,0,0,24,15,0,0,0,15,0,0,0,15,24,0
endlayer

layer
0,24,15,0,0,0,15,0,0,0,15,24,24,15,0,0,15,24,24,15,0,0,0,15,0,0,0,15,64,63
0,15,15,43,43,43,15,43,43,43,15,43,43,15,48,48,15,43,43,15,43,43,43,15,43,43,43,15,15,0
0,0,43,11,11,11,11,11,11,11,11,11,15,0,0,0,0,15,11,11,11,11,11,11,11,11,11,43,0,0
0,0,43,11,0,0,0,0,0,0,0,0,0,0,0,0,0,0,0,0,0,0,0,0,0,0,11,43,0,0
0,0,43,11,0,0,0,0,0,0,0,0,0,0,0,0,0,0,0,0,0,0,0,0,0,0,11,43,0,0
0,15,15,11,0,0,0,0,0,0,0,0,0,0,0,0,0,0,0,0,0,0,0,0,0,0,11,15,15,0
0,0,43,11,0,0,0,0,0,0,0,0,0,0,0,0,0,0,0,0,0,0,0,0,0,0,11,43,0,0
0,0,43,11,0,0,0,0,0,0,0,0,0,0,0,0,0,0,0,0,0,0,0,0,0,0,11,43,0,0
0,0,43,11,0,0,0,0,0,11,0,0,15,39,33,33,39,15,0,0,0,0,0,11,11,11,11,43,0,0
0,15,15,11,0,0,0,0,0,11,15,43,15,15,65,65,15,15,43,15,0,0,0,15,0,0,0,15,15,0
0,0,43,11,0,0,0,0,0,11,43,0,0,66,59,59,66,0,0,43,0,0,0,15,0,0,0,43,0,0
0,0,43,11,0,0,0,0,0,11,43,0,0,0,0,0,0,0,0,43,0,0,0,0,0,0,0,43,0,0
0,0,43,11,11,11,11,11,11,11,43,0,0,0,0,0,0,0,0,43,0,0,0,0,0,0,0,43,0,0
0,15,15,43,43,43,15,43,43,43,15,15,0,0,0,0,0,0,15,15,43,43,43,15,43,43,43,15,15,0
0,24,15,0,0,0,15,0,0,0,15,24,0,0,0,0,0,0,24,15,0,0,0,15,0,0,0,15,67,63
endlayer

layer
68,68,68,63,70,69,68,63,70,69,68,63,69,68,63,69,68,63,69,68,63,70,69,68,63,70,69,68,68,68
67,15,15,43,43,43,15,43,43,43,15,43,43,15,43,43,15,43,43,15,43,43,43,15,43,43,43,15,15,67
0,36,10,10,10,10,10,10,10,10,10,10,10,10,10,10,10,10,10,10,10,10,10,10,10,10,10,10,35,0
0,36,10,10,10,10,10,10,10,10,10,10,10,10,10,10,10,10,10,10,10,10,10,10,10,10,10,10,35,0
0,36,10,10,10,10,10,10,10,10,10,10,10,10,10,10,10,10,10,10,10,10,10,10,10,10,10,10,35,0
36,15,10,10,10,10,10,10,10,10,10,10,10,10,10,10,10,10,10,10,10,10,10,10,10,10,10,10,15,35
0,36,10,10,10,10,10,10,10,10,10,10,10,10,10,10,10,10,10,10,10,10,10,10,10,10,10,10,35,0
0,36,10,10,10,10,10,10,10,10,10,10,10,10,10,10,10,10,10,10,10,10,10,10,10,10,10,10,35,0
0,36,10,10,10,10,10,10,10,10,10,10,10,71,10,10,71,10,10,10,10,10,10,10,10,10,10,10,35,0
36,15,10,10,10,10,10,10,10,10,15,43,15,15,10,10,15,15,43,15,10,10,10,10,10,10,10,10,15,35
0,36,10,10,10,10,10,10,10,10,43,63,67,67,67,67,67,67,67,43,10,10,10,10,10,10,10,10,35,0
0,36,10,10,10,10,10,10,10,10,43,70,0,0,0,0,0,0,70,43,10,10,10,10,10,10,10,10,35,0
0,36,10,10,10,10,10,10,10,10,43,64,0,0,0,0,0,0,64,43,10,10,10,10,10,10,10,10,35,0
64,15,15,43,43,43,15,43,43,43,15,73,0,0,0,0,0,0,72,15,43,43,43,15,43,43,43,15,15,64
74,74,74,63,70,69,74,63,70,69,74,75,0,0,0,0,0,0,75,74,63,70,69,74,63,70,69,74,74,74
endlayer

layer
0,0,0,0,75,0,0,0,75,0,0,0,0,0,75,75,0,0,0,0,0,75,0,0,0,75,0,0,0,0
68,76,76,76,76,76,76,76,76,76,76,76,76,76,76,76,76,76,76,76,76,76,76,76,76,76,76,76,76,68
67,43,65,65,65,65,65,65,65,65,65,65,65,65,65,65,65,65,65,65,65,65,65,65,65,65,65,65,43,67
0,43,0,0,0,0,0,0,0,0,0,0,0,0,0,0,0,0,0,0,0,0,0,0,0,0,0,0,43,0
0,43,0,0,0,0,0,0,0,0,0,0,0,0,0,0,0,0,0,0,0,0,0,0,0,0,0,0,43,0
51,15,0,0,0,0,0,0,0,0,0,0,0,0,0,0,0,0,0,0,0,0,0,0,0,0,0,0,15,51
0,43,0,0,0,0,0,0,0,0,0,0,0,0,0,0,0,0,0,0,0,0,0,0,0,0,0,0,43,0
0,79,0,0,0,0,0,0,0,0,0,0,0,0,0,0,0,0,0,78,0,0,0,0,0,0,0,0,77,0
0,43,0,0,0,0,0,0,0,0,0,0,0,0,0,0,0,0,0,80,0,0,0,0,0,0,0,0,43,0
51,15,0,0,0,0,0,0,0,65,59,59,65,65,65,65,65,65,59,59,65,0,0,0,0,0,0,0,15,51
0,43,0,0,0,0,0,0,0,65,57,0,0,75,0,0,75,0,0,58,65,0,0,0,0,0,0,0,43,0
0,43,0,0,0,0,0,0,65,65,57,75,0,0,0,0,0,0,75,58,65,65,0,0,0,0,0,0,43,0
64,43,65,65,65,65,65,65,65,65,57,0,0,0,0,0,0,0,0,58,65,65,65,65,65,65,65,65,43,64
74,59,59,59,59,59,59,59,59,59,57,0,0,0,0,0,0,0,0,59,59,59,59,59,59,59,59,59,59,74
0,0,0,0,75,0,0,0,75,0,0,0,0,0,0,0,0,0,0,0,0,75,0,0,0,75,0,0,0,0
endlayer

layer
0,0,0,0,0,0,0,0,0,0,0,0,0,0,0,0,0,0,0,0,0,0,0,0,0,0,0,0,0,0
0,0,0,0,0,0,0,0,0,0,0,0,0,0,0,0,0,0,0,0,0,0,0,0,0,0,0,0,0,0
68,76,76,76,76,76,76,76,76,76,76,76,76,76,76,76,76,76,76,76,76,76,76,76,76,76,76,76,76,68
67,43,42,42,42,42,42,42,42,42,42,42,42,42,42,42,42,42,42,42,42,42,42,42,42,42,42,42,43,67
0,43,0,0,0,0,0,0,0,0,0,0,0,0,0,0,0,0,0,0,0,0,0,0,0,0,0,0,43,0
0,15,0,0,0,0,0,0,0,0,0,0,0,0,0,0,0,0,0,0,0,0,0,0,0,0,0,0,15,0
0,43,0,0,0,0,0,0,0,0,0,0,0,0,0,0,0,0,0,0,0,0,0,0,0,0,0,0,43,0
0,48,0,0,0,0,0,0,0,0,0,0,0,0,0,0,0,0,0,0,0,0,0,0,0,0,0,0,48,0
0,43,0,0,0,0,0,0,0,0,0,0,0,0,0,0,0,0,0,0,0,0,0,0,0,0,0,0,43,0
0,15,0,0,0,0,0,0,36,65,42,42,65,48,48,48,48,65,42,42,65,35,0,0,0,0,0,0,15,0
0,43,0,0,0,0,0,0,36,57,0,0,0,0,0,0,0,0,0,0,58,35,0,0,0,0,0,0,43,0
64,43,33,33,33,33,33,33,65,57,0,0,0,0,0,0,0,0,0,0,58,65,33,33,33,33,33,33,43,64
74,59,59,59,59,59,59,59,59,59,0,0,0,0,0,0,0,0,0,0,59,59,59,59,59,59,59,59,59,74
0,0,0,0,0,0,0,0,0,0,0,0,0,0,0,0,0,0,0,0,0,0,0,0,0,0,0,0,0,0
0,0,0,0,0,0,0,0,0,0,0,0,0,0,0,0,0,0,0,0,0,0,0,0,0,0,0,0,0,0
endlayer

layer
0,0,0,0,0,0,0,0,0,0,0,0,0,0,0,0,0,0,0,0,0,0,0,0,0,0,0,0,0,0
0,0,0,0,0,0,0,0,0,0,0,0,0,0,0,0,0,0,0,0,0,0,0,0,0,0,0,0,0,0
0,0,0,0,0,0,0,0,0,0,0,0,0,0,0,0,0,0,0,0,0,0,0,0,0,0,0,0,0,0
68,76,76,76,76,76,76,76,76,76,76,76,76,76,76,76,76,76,76,76,76,76,76,76,76,76,76,76,76,68
67,43,42,42,42,42,42,42,42,42,42,42,42,42,42,42,42,42,42,42,42,42,42,42,42,42,42,42,43,67
0,15,0,0,0,0,0,0,0,0,0,0,0,0,0,0,0,0,0,0,0,0,0,0,0,0,0,0,15,0
0,43,0,0,0,0,0,0,0,0,0,0,0,0,0,0,0,0,0,0,0,0,0,0,0,0,0,0,43,0
0,48,0,0,0,0,0,0,0,0,0,0,0,0,0,0,0,0,0,0,0,0,0,0,0,0,0,0,48,0
0,43,0,0,0,0,0,0,0,0,0,0,0,0,0,0,0,0,0,0,0,0,0,0,0,0,0,0,43,0
0,15,0,0,0,0,0,0,59,59,59,59,65,48,48,48,48,65,59,59,59,59,0,0,0,0,0,0,15,0
64,43,33,33,33,33,33,33,57,0,0,0,0,0,0,0,0,0,0,0,0,58,33,33,33,33,33,33,43,64
74,59,59,59,59,59,59,59,59,0,0,0,0,0,0,0,0,0,0,0,0,58,59,59,59,59,59,59,59,74
0,0,0,0,0,0,0,0,0,0,0,0,0,0,0,0,0,0,0,0,0,0,0,0,0,0,0,0,0,0
0,0,0,0,0,0,0,0,0,0,0,0,0,0,0,0,0,0,0,0,0,0,0,0,0,0,0,0,0,0
0,0,0,0,0,0,0,0,0,0,0,0,0,0,0,0,0,0,0,0,0,0,0,0,0,0,0,0,0,0
endlayer

layer
0,0,0,0,0,0,0,0,0,0,0,0,0,0,0,0,0,0,0,0,0,0,0,0,0,0,0,0,0,0
0,0,0,0,0,0,0,0,0,0,0,0,0,0,0,0,0,0,0,0,0,0,0,0,0,0,0,0,0,0
0,0,0,0,0,0,0,0,0,0,0,0,0,0,0,0,0,0,0,0,0,0,0,0,0,0,0,0,0,0
0,0,0,0,0,0,0,0,0,0,0,0,0,0,0,0,0,0,0,0,0,0,0,0,0,0,0,0,0,0
68,76,76,76,76,76,76,76,76,76,76,76,76,76,76,76,76,76,76,76,76,76,76,76,76,76,76,76,76,68
67,15,42,42,42,42,42,42,42,42,42,42,42,42,42,42,42,42,42,42,42,42,42,42,42,42,42,42,15,67
0,43,0,0,0,0,0,0,0,0,0,0,0,0,0,0,0,0,0,0,0,0,0,0,0,0,0,0,43,0
0,82,0,0,0,0,0,0,0,0,0,0,0,0,0,0,0,0,0,0,0,0,0,0,0,0,0,0,81,0
0,43,0,0,0,0,0,0,0,0,0,0,0,0,0,0,0,0,0,0,0,0,0,0,0,0,0,0,43,0
64,15,33,33,33,33,33,33,42,42,42,42,65,48,48,48,48,65,42,42,42,42,33,33,33,33,33,33,15,64
74,59,59,59,59,59,59,57,0,0,0,0,0,0,0,0,0,0,0,0,0,0,58,59,59,59,59,59,59,74
0,0,0,0,0,0,0,0,0,0,0,0,0,0,0,0,0,0,0,0,0,0,0,0,0,0,0,0,0,0
0,0,0,0,0,0,0,0,0,0,0,0,0,0,0,0,0,0,0,0,0,0,0,0,0,0,0,0,0,0
0,0,0,0,0,0,0,0,0,0,0,0,0,0,0,0,0,0,0,0,0,0,0,0,0,0,0,0,0,0
0,0,0,0,0,0,0,0,0,0,0,0,0,0,0,0,0,0,0,0,0,0,0,0,0,0,0,0,0,0
endlayer

layer
0,0,0,0,0,0,0,0,0,0,0,0,0,0,0,0,0,0,0,0,0,0,0,0,0,0,0,0,0,0
0,0,0,0,0,0,0,0,0,0,0,0,0,0,0,0,0,0,0,0,0,0,0,0,0,0,0,0,0,0
0,0,0,0,0,0,0,0,0,0,0,0,0,0,0,0,0,0,0,0,0,0,0,0,0,0,0,0,0,0
0,0,0,0,0,0,0,0,0,0,0,0,0,0,0,0,0,0,0,0,0,0,0,0,0,0,0,0,0,0
0,0,0,0,0,0,0,0,0,0,0,0,0,0,0,0,0,0,0,0,0,0,0,0,0,0,0,0,0,0
68,76,76,76,76,76,76,76,76,76,76,76,76,76,76,76,76,76,76,76,76,76,76,76,76,76,76,76,76,68
67,43,42,42,42,42,42,42,42,42,42,42,42,42,42,42,42,42,42,42,42,42,42,42,42,42,42,42,43,67
0,43,0,0,0,0,0,0,0,0,0,0,0,0,0,0,0,0,0,0,0,0,0,0,0,0,0,0,43,0
64,43,33,33,33,33,33,33,33,33,33,33,33,33,33,33,33,33,33,33,33,33,33,33,33,33,33,33,43,64
74,59,59,59,59,59,59,59,59,59,59,59,59,59,59,59,59,59,59,59,59,59,59,59,59,59,59,59,59,74
0,0,0,0,0,0,0,0,0,0,0,0,0,0,0,0,0,0,0,0,0,0,0,0,0,0,0,0,0,0
0,0,0,0,0,0,0,0,0,0,0,0,0,0,0,0,0,0,0,0,0,0,0,0,0,0,0,0,0,0
0,0,0,0,0,0,0,0,0,0,0,0,0,0,0,0,0,0,0,0,0,0,0,0,0,0,0,0,0,0
0,0,0,0,0,0,0,0,0,0,0,0,0,0,0,0,0,0,0,0,0,0,0,0,0,0,0,0,0,0
0,0,0,0,0,0,0,0,0,0,0,0,0,0,0,0,0,0,0,0,0,0,0,0,0,0,0,0,0,0
endlayer

layer
0,0,0,0,0,0,0,0,0,0,0,0,0,0,0,0,0,0,0,0,0,0,0,0,0,0,0,0,0,0
0,0,0,0,0,0,0,0,0,0,0,0,0,0,0,0,0,0,0,0,0,0,0,0,0,0,0,0,0,0
0,0,0,0,0,0,0,0,0,0,0,0,0,0,0,0,0,0,0,0,0,0,0,0,0,0,0,0,0,0
0,0,0,0,0,0,0,0,0,0,0,0,0,0,0,0,0,0,0,0,0,0,0,0,0,0,0,0,0,0
0,0,0,0,0,0,0,0,0,0,0,0,0,0,0,0,0,0,0,0,0,0,0,0,0,0,0,0,0,0
0,0,0,0,0,0,0,0,0,0,0,0,0,0,0,0,0,0,0,0,0,0,0,0,0,0,0,0,0,0
68,76,76,76,76,76,76,76,76,76,76,76,76,76,76,76,76,76,76,76,76,76,76,76,76,76,76,76,76,68
69,83,83,83,4,83,83,83,4,83,83,83,4,83,83,83,83,4,83,83,83,4,83,83,83,4,83,83,83,63
74,59,59,59,59,59,59,59,59,59,59,59,59,59,59,59,59,59,59,59,59,59,59,59,59,59,59,59,59,74
0,0,0,0,0,0,0,0,0,0,0,0,0,0,0,0,0,0,0,0,0,0,0,0,0,0,0,0,0,0
0,0,0,0,0,0,0,0,0,0,0,0,0,0,0,0,0,0,0,0,0,0,0,0,0,0,0,0,0,0
0,0,0,0,0,0,0,0,0,0,0,0,0,0,0,0,0,0,0,0,0,0,0,0,0,0,0,0,0,0
0,0,0,0,0,0,0,0,0,0,0,0,0,0,0,0,0,0,0,0,0,0,0,0,0,0,0,0,0,0
0,0,0,0,0,0,0,0,0,0,0,0,0,0,0,0,0,0,0,0,0,0,0,0,0,0,0,0,0,0
0,0,0,0,0,0,0,0,0,0,0,0,0,0,0,0,0,0,0,0,0,0,0,0,0,0,0,0,0,0
endlayer

layer
0,0,0,0,0,0,0,0,0,0,0,0,0,0,0,0,0,0,0,0,0,0,0,0,0,0,0,0,0,0
0,0,0,0,0,0,0,0,0,0,0,0,0,0,0,0,0,0,0,0,0,0,0,0,0,0,0,0,0,0
0,0,0,0,0,0,0,0,0,0,0,0,0,0,0,0,0,0,0,0,0,0,0,0,0,0,0,0,0,0
0,0,0,0,0,0,0,0,0,0,0,0,0,0,0,0,0,0,0,0,0,0,0,0,0,0,0,0,0,0
0,0,0,0,0,0,0,0,0,0,0,0,0,0,0,0,0,0,0,0,0,0,0,0,0,0,0,0,0,0
0,0,0,0,0,0,0,0,0,0,0,0,0,0,0,0,0,0,0,0,0,0,0,0,0,0,0,0,0,0
0,0,0,0,0,0,0,0,0,0,0,0,0,0,0,0,0,0,0,0,0,0,0,0,0,0,0,0,0,0
75,75,75,75,75,75,75,75,75,75,75,75,75,75,75,75,75,75,75,75,75,75,75,75,75,75,75,75,75,75
0,0,0,0,0,0,0,0,0,0,0,0,0,0,0,0,0,0,0,0,0,0,0,0,0,0,0,0,0,0
0,0,0,0,0,0,0,0,0,0,0,0,0,0,0,0,0,0,0,0,0,0,0,0,0,0,0,0,0,0
0,0,0,0,0,0,0,0,0,0,0,0,0,0,0,0,0,0,0,0,0,0,0,0,0,0,0,0,0,0
0,0,0,0,0,0,0,0,0,0,0,0,0,0,0,0,0,0,0,0,0,0,0,0,0,0,0,0,0,0
0,0,0,0,0,0,0,0,0,0,0,0,0,0,0,0,0,0,0,0,0,0,0,0,0,0,0,0,0,0
0,0,0,0,0,0,0,0,0,0,0,0,0,0,0,0,0,0,0,0,0,0,0,0,0,0,0,0,0,0
0,0,0,0,0,0,0,0,0,0,0,0,0,0,0,0,0,0,0,0,0,0,0,0,0,0,0,0,0,0
endlayer

