
# Created by Ruins mod version 17.1 Ingame Parser
# authoring Player: Nemsun

# criterion expression specifying mod ids required to load template
# may include plus (AND), minus (AND NOT), comma (OR), and parentheses
# all required mods listed must be present; no prohibited mods can be
requiredMods=
# likelihood this template will be chosen relative to all others
# e.g., a weight=6 template is chosen 3X as often as one with weight=2
weight=1
# list of other biomes in which this template may spawn
# biome corresponding to directory is always assumed, listed or not
# generic templates should leave this list empty
biomesToSpawnIn=
# criterion expression specifying types of biome where template spawns
# this is in addition to those explicitly listed as biomesToSpawnIn
# generic templates should leave this list empty
biomeTypesToSpawnIn=
# list of biomes in which this template may not spawn
# takes precedence over biomeTypesToSpawnIn, but NOT biomesToSpawnIn
# should be empty if biomeTypesToSpawnIn is empty
biomesToNotSpawnIn=
# depth template is pushed down into the surface when built
# offset is min/max range of random additional bury depth
embed_into_distance=0
random_height_offset=0,0
# whitelist/blacklist of block types on which template may be built
# specify one, not both; leave the other empty (both empty = allow all)
acceptable_target_blocks=
unacceptable_target_blocks=flowing_water,water,flowing_lava,lava
# size of template (#layers, #rows per layer, #blocks per row)
dimensions=14,30,30
# max number of missing blocks allowed in surface beneath template
allowable_overhang=0
# depth/height limit affected by terrain leveling
# also maximum bumpiness tolerated in surface beneath template
max_leveling=2
# padding applied to all sides of template horizontal footprint
# expands area affected by terrain leveling (-1 = no leveling)
leveling_buffer=0
# do not rotate template randomly when built (1 = no rotation)
preventRotation=0
# treat water/lava blocks as air and protect them from rule0 (1 = yes)
preserve_water=0
preserve_lava=0
# minimum distance this template must have from instances of itself
uniqueMinDistance=0
# min/max distances this template can be from world spawn (0 = no limit)
# only applies to overworld--i.e., dimension 0
spawnMinDistance=0
spawnMaxDistance=0
# other template built nearby whenever this one is
# syntax: <name>;<relativeX>;<maxYdifference>;<relativeZ>[;<chance>]
# may be used more than once to specify multiple neighbors
adjoining_template=

rule1=0,100,minecraft:stone-0
rule2=0,100,minecraft:dirt-0
rule3=0,100,minecraft:cobblestone-0
rule4=0,100,minecraft:double_wooden_slab-2
rule5=0,100,minecraft:glowstone-0
rule6=0,100,minecraft:wooden_slab-10
rule7=0,100,minecraft:stonebrick-0
rule8=0,100,minecraft:stonebrick-1
rule9=0,100,minecraft:stonebrick-2
rule10=0,100,minecraft:grass-0
rule11=0,100,minecraft:stone_slab-0
rule12=0,100,minecraft:stone_slab-8
rule13=0,100,minecraft:stone_slab-11
rule14=0,100,minecraft:stone_slab-3
rule15=0,100,minecraft:double_stone_slab-3
rule16=0,100,minecraft:planks-0
rule17=0,100,minecraft:oak_stairs-0
rule18=0,100,minecraft:log-0
rule19=0,100,minecraft:double_wooden_slab-0
rule20=0,100,minecraft:wooden_slab-8
rule21=0,100,minecraft:water-0
rule22=0,100,minecraft:oak_stairs-2
rule23=0,100,minecraft:oak_stairs-3
rule24=0,100,minecraft:water-1
rule25=0,100,minecraft:oak_stairs-1
rule26=0,100,minecraft:farmland-7
rule27=0,100,minecraft:wooden_slab-0
rule28=0,100,minecraft:farmland-0
rule29=0,100,minecraft:log-2
rule30=1,100,minecraft:torch-5
rule31=0,100,minecraft:stone_brick_stairs-0
rule32=0,100,minecraft:leaves-12
rule33=0,100,minecraft:stone_brick_stairs-3
rule34=0,100,minecraft:stone_brick_stairs-2
rule35=0,100,minecraft:leaves-4
rule36=0,100,minecraft:stone_brick_stairs-1
rule37=0,100,minecraft:wooden_door-5
rule38=0,100,minecraft:pumpkin_stem-7
rule39=0,100,minecraft:pumpkin-0
rule40=0,100,minecraft:fence-0
rule41=2,100,minecraft:torch-1
rule42=2,100,minecraft:torch-3
rule43=0,100,minecraft:iron_bars-0
rule44=2,100,minecraft:torch-4
rule45=0,100,minecraft:wooden_door-8
rule46=2,100,minecraft:torch-2
rule47=0,100,minecraft:leaves-6
rule48=0,100,minecraft:leaves-14
rule49=0,100,minecraft:oak_stairs-7
rule50=0,100,minecraft:oak_stairs-6
rule51=0,100,minecraft:stone_brick_stairs-7
rule52=0,100,minecraft:stone_brick_stairs-6
rule53=0,100,minecraft:oak_stairs-5
rule54=0,100,minecraft:stone_brick_stairs-5
rule55=0,100,minecraft:oak_stairs-4
rule56=0,100,minecraft:stone_brick_stairs-4

layer
1,1,1,1,1,1,1,1,1,1,1,1,1,1,1,1,1,1,1,1,1,1,1,1,1,1,1,1,1,1
1,1,1,1,1,1,1,1,1,1,1,1,1,1,1,1,1,1,1,1,1,1,1,1,1,1,1,1,1,1
1,1,1,1,1,1,1,1,1,1,1,1,1,1,1,1,1,1,1,1,1,1,1,1,1,1,1,1,1,1
1,1,1,1,1,1,1,1,1,1,1,1,1,1,1,1,1,1,1,1,1,1,1,1,1,1,1,1,1,1
1,1,1,1,1,1,1,1,1,1,1,1,1,1,1,1,1,1,1,1,1,1,1,1,1,1,1,1,1,1
1,1,1,1,1,1,1,1,1,1,1,1,1,1,1,1,1,1,1,1,1,1,1,1,1,1,1,1,1,1
1,1,1,1,1,1,1,1,1,1,1,1,1,1,1,1,1,1,1,1,1,1,1,1,1,1,1,1,1,1
1,1,1,1,1,1,1,1,1,1,1,1,1,1,1,1,1,1,1,1,1,1,1,1,1,1,1,1,1,1
1,1,1,1,1,1,1,1,1,1,1,1,1,1,1,1,1,1,1,1,1,1,1,1,1,1,1,1,1,1
1,1,1,1,1,1,1,1,1,1,1,1,1,1,1,1,1,1,1,1,1,1,1,1,1,1,1,1,1,1
1,1,1,1,1,1,1,1,1,1,1,1,1,1,1,1,1,1,1,1,1,1,1,1,1,1,1,1,1,1
1,1,1,1,1,1,1,1,1,1,1,1,1,1,1,1,1,1,1,1,1,1,1,1,1,1,1,1,1,1
1,1,1,1,1,1,1,1,1,1,1,1,1,1,1,1,1,1,1,1,1,1,1,1,1,1,1,1,1,1
1,1,1,1,1,1,1,1,1,1,1,1,1,1,1,1,1,1,1,1,1,1,1,1,1,1,1,1,1,1
1,1,1,1,1,1,1,1,1,1,1,1,1,1,1,1,1,1,1,1,1,1,1,1,1,1,1,1,1,1
1,1,1,1,1,1,1,1,1,1,1,1,1,1,1,1,1,1,1,1,1,1,1,1,1,1,1,1,1,1
1,1,1,1,1,1,1,1,1,1,1,1,1,1,1,1,1,1,1,1,1,1,1,1,1,1,1,1,1,1
1,1,1,1,1,1,1,1,1,1,1,1,1,1,1,1,1,1,1,1,1,1,1,1,1,1,1,1,1,1
1,1,1,1,1,1,1,1,1,1,1,1,1,1,1,1,1,1,1,1,1,1,1,1,1,1,1,1,1,1
1,1,1,1,1,1,1,1,1,1,1,1,1,1,1,1,1,1,1,1,1,1,1,1,1,1,1,1,1,1
1,1,1,1,1,1,1,1,1,1,1,1,1,1,1,1,1,1,1,1,1,1,1,1,1,1,1,1,1,1
1,1,1,1,1,1,1,1,1,1,1,1,1,1,1,1,1,1,1,1,1,1,1,1,1,1,1,1,1,1
1,1,1,1,1,1,1,1,1,1,1,1,1,1,1,1,1,1,1,1,1,1,1,1,1,1,1,1,1,1
1,1,1,1,1,1,1,1,1,1,1,1,1,1,1,1,1,1,1,1,1,1,1,1,1,1,1,1,1,1
1,1,1,1,1,1,1,1,1,1,1,1,1,1,1,1,1,1,1,1,1,1,1,1,1,1,1,1,1,1
1,1,1,1,1,1,1,1,1,1,1,1,1,1,1,1,1,1,1,1,1,1,1,1,1,1,1,1,1,1
1,1,1,1,1,1,1,1,1,1,1,1,1,1,1,1,1,1,1,1,1,1,1,1,1,1,1,1,1,1
1,1,1,1,1,1,1,1,1,1,1,1,1,1,1,1,1,1,1,1,1,1,1,1,1,1,1,1,1,1
1,1,1,1,1,1,1,1,1,1,1,1,1,1,1,1,1,1,1,1,1,1,1,1,1,1,1,1,1,1
1,1,1,1,1,1,1,1,1,1,1,1,1,1,1,1,1,1,1,1,1,1,1,1,1,1,1,1,1,1
endlayer

layer
1,1,1,1,1,1,1,1,1,1,1,1,1,1,1,1,1,1,1,1,1,1,1,1,1,1,1,1,1,1
1,1,1,1,1,1,1,1,1,1,1,1,1,1,1,1,1,1,1,1,1,1,1,1,1,1,1,1,1,1
1,1,1,1,1,1,1,1,1,1,1,1,1,1,1,1,1,1,1,1,1,1,1,1,1,1,1,1,1,1
1,1,1,1,1,1,1,1,1,1,1,1,1,1,1,1,1,1,1,1,1,1,1,1,1,1,1,1,1,1
1,1,1,1,1,1,1,1,1,1,1,1,1,1,1,1,1,1,1,1,1,1,1,1,1,1,1,1,1,1
1,1,1,1,1,1,1,1,1,1,1,1,1,1,1,1,1,1,1,1,1,1,1,1,1,1,1,1,1,1
1,1,1,1,1,1,1,1,1,1,1,1,1,1,1,1,1,1,1,1,1,1,1,1,1,1,1,1,1,1
1,1,1,1,1,1,1,1,1,1,1,1,1,1,1,1,1,1,1,1,1,1,1,1,1,1,1,1,1,1
1,1,1,1,1,1,1,1,1,1,1,1,1,1,1,1,1,1,1,1,1,1,1,1,1,1,1,1,1,1
1,1,1,1,1,1,1,1,1,1,1,1,1,1,1,1,1,1,1,1,1,1,1,1,1,1,1,1,1,1
1,1,1,1,1,1,1,1,1,1,1,1,1,1,1,1,1,1,1,1,1,1,1,1,1,1,1,1,1,1
1,1,1,1,1,1,1,1,1,1,1,1,1,1,1,1,1,1,1,1,1,1,1,1,1,1,1,1,1,1
1,1,1,1,1,1,1,1,1,1,1,1,1,1,1,1,1,1,1,1,1,1,1,1,1,1,1,1,1,1
1,1,1,1,1,1,1,1,1,1,1,1,1,1,1,1,1,1,1,1,1,1,1,1,1,1,1,1,1,1
1,1,1,1,1,1,1,1,1,1,1,1,1,1,1,1,1,1,1,1,1,1,1,1,1,1,1,1,1,1
1,1,1,1,1,1,1,1,1,1,1,1,1,1,1,1,1,1,1,1,1,1,1,1,1,1,1,1,1,1
1,1,1,1,1,1,1,1,1,1,1,1,1,1,1,1,1,1,1,1,1,1,1,1,1,1,1,1,1,1
1,1,1,1,1,1,1,1,1,1,1,1,1,1,1,1,1,1,1,1,1,1,1,1,1,1,1,1,1,1
1,1,1,1,1,1,1,1,1,1,1,1,1,1,1,1,1,1,1,1,1,1,1,1,1,1,1,1,1,1
1,1,1,1,1,1,1,1,1,1,1,1,1,1,1,1,1,1,1,1,1,1,1,1,1,1,1,1,1,1
1,1,1,1,1,1,1,1,1,1,1,1,1,1,1,1,1,1,1,1,1,1,1,1,1,1,1,1,1,1
1,1,1,1,1,1,1,1,1,1,1,1,1,1,1,1,1,1,1,1,1,1,1,1,1,1,1,1,1,1
1,1,1,1,1,1,1,1,1,1,1,1,1,1,1,1,1,1,1,1,1,1,1,1,1,1,1,1,1,1
1,1,1,1,1,1,1,1,1,1,1,1,1,1,1,1,1,1,1,1,1,1,1,1,1,1,1,1,1,1
1,1,1,1,1,1,1,1,1,1,1,1,1,1,1,1,1,1,1,1,1,1,1,1,1,1,1,1,1,1
1,1,1,1,1,1,1,1,1,1,1,1,1,1,1,1,1,1,1,1,1,1,1,1,1,1,1,1,1,1
1,1,1,1,1,1,1,1,1,1,1,1,1,1,1,1,1,1,1,1,1,1,1,1,1,1,1,1,1,1
1,1,1,1,1,1,1,1,1,1,1,1,1,1,1,1,1,1,1,1,1,1,1,1,1,1,1,1,1,1
1,1,1,1,1,1,1,1,1,1,1,1,1,1,1,1,1,1,1,1,1,1,1,1,1,1,1,1,1,1
1,1,1,1,1,1,1,1,1,1,1,1,1,1,1,1,1,1,1,1,1,1,1,1,1,1,1,1,1,1
endlayer

layer
1,1,1,1,1,1,1,1,1,1,1,1,1,1,1,1,1,1,1,1,1,1,1,1,1,1,1,1,1,1
1,1,1,1,1,1,1,1,1,1,1,1,1,1,1,1,1,1,1,1,1,1,1,1,1,1,1,1,1,1
1,1,1,1,1,1,1,1,1,1,1,1,1,1,1,1,1,1,1,1,1,1,1,1,1,1,1,1,1,1
1,1,1,1,1,1,1,1,1,1,1,1,1,1,1,1,1,1,1,1,1,1,1,1,1,1,1,1,1,1
1,1,1,1,1,1,1,1,1,1,1,1,1,1,1,1,1,1,1,1,1,1,1,1,1,1,1,1,1,1
1,1,1,1,1,1,1,1,1,1,1,1,1,1,1,1,1,1,1,1,1,1,1,1,1,1,1,1,1,1
1,1,1,1,1,1,1,1,1,1,1,1,1,1,1,1,1,1,1,1,1,1,1,1,1,1,1,1,1,1
1,1,1,1,1,1,1,1,1,1,1,1,1,1,1,1,1,1,1,1,1,1,1,1,1,1,1,1,1,1
1,1,1,1,1,1,1,1,1,1,1,1,1,1,1,1,1,1,1,1,1,1,1,1,1,1,1,1,1,1
1,1,1,1,1,1,1,1,1,1,1,1,1,1,1,1,1,1,1,1,1,1,1,1,1,1,1,1,1,1
1,1,1,1,1,1,1,1,1,1,1,1,1,1,1,1,1,1,1,1,1,1,1,1,1,1,1,1,1,1
1,1,1,1,1,1,1,1,1,1,1,1,1,1,1,1,1,1,1,1,1,1,1,1,1,1,1,1,1,1
1,1,1,1,1,1,1,1,1,1,1,1,1,1,1,1,1,1,1,1,1,1,1,1,1,1,1,1,1,1
1,1,1,1,1,1,1,1,1,1,1,1,1,1,1,1,1,1,1,1,1,1,1,1,1,1,1,1,1,1
1,1,1,1,1,1,1,1,1,1,1,1,1,1,1,1,1,1,1,1,1,1,1,1,1,1,1,1,1,1
1,1,1,1,1,1,1,1,1,1,1,1,1,1,1,1,1,1,1,1,1,1,1,1,1,1,1,1,1,1
1,1,1,1,1,1,1,1,1,1,1,1,1,1,1,1,1,1,1,1,1,1,1,1,1,1,1,1,1,1
1,1,1,1,1,1,1,1,1,1,1,1,1,1,1,1,1,1,1,1,1,1,1,1,1,1,1,1,1,1
1,1,1,1,1,1,1,1,1,1,1,1,1,1,1,1,1,1,1,1,1,1,1,1,1,1,1,1,1,1
1,1,1,1,1,1,1,1,1,1,1,1,1,1,1,1,1,1,1,1,1,1,1,1,1,1,1,1,1,1
1,1,1,1,1,1,1,1,1,1,1,1,1,1,1,1,1,1,1,1,1,1,1,1,1,1,1,1,1,1
1,1,1,1,1,1,1,1,1,1,1,1,1,1,1,1,1,1,1,1,1,1,1,1,1,1,1,1,1,1
1,1,1,1,1,1,1,1,1,1,1,1,1,1,1,1,1,1,1,1,1,1,1,1,1,1,1,1,1,1
1,1,1,1,1,1,1,1,1,1,1,1,1,1,1,1,1,1,1,1,1,1,1,1,1,1,1,1,1,1
1,1,1,1,1,1,1,1,1,1,1,1,1,1,1,1,1,1,1,1,1,1,1,1,1,1,1,1,1,1
1,1,1,1,1,1,1,1,1,1,1,1,1,1,1,1,1,1,1,1,1,1,1,1,1,1,1,1,1,1
1,1,1,1,1,1,1,1,1,1,1,1,1,1,1,1,1,1,1,1,1,1,1,1,1,1,1,1,1,1
1,1,1,1,1,1,1,1,1,1,1,1,1,1,1,1,1,1,1,1,1,1,1,1,1,1,1,1,1,1
1,1,1,1,1,1,1,1,1,1,1,1,1,1,1,1,1,1,1,1,1,1,1,1,1,1,1,1,1,1
1,1,1,1,1,1,1,1,1,1,1,1,1,1,1,1,1,1,1,1,1,1,1,1,1,1,1,1,1,1
endlayer

layer
1,1,1,1,1,1,1,1,1,1,1,1,1,1,1,1,1,1,1,1,1,1,1,1,1,1,1,1,1,1
1,1,1,1,1,1,1,1,1,1,1,1,1,1,1,1,1,1,1,1,1,1,1,1,1,1,1,1,1,1
1,1,1,1,1,1,1,1,1,1,1,1,1,1,1,1,1,1,1,1,1,1,1,1,1,1,1,1,1,1
1,1,1,1,1,1,1,1,1,1,1,1,1,1,1,1,1,1,1,1,1,1,1,1,1,1,1,1,1,1
1,1,1,1,1,1,1,1,1,1,1,1,1,1,1,1,1,1,1,1,1,1,1,1,1,1,1,1,1,1
1,1,1,1,1,1,1,1,1,1,1,1,1,1,1,1,1,1,1,1,1,1,1,1,1,1,1,1,1,1
1,1,1,1,1,1,1,1,1,1,1,1,1,1,1,1,1,1,1,1,1,1,1,1,1,1,1,1,1,1
1,1,1,1,1,1,1,1,1,1,1,1,1,1,1,1,1,1,1,1,1,1,1,1,1,1,1,1,1,1
1,1,1,1,1,1,1,1,1,1,1,1,1,1,1,1,1,1,1,1,1,1,1,1,1,1,1,1,1,1
1,1,1,1,1,1,1,1,1,1,1,1,1,1,1,1,1,1,1,1,1,1,1,1,1,1,1,1,1,1
1,1,1,1,1,1,1,1,1,1,1,1,1,1,1,1,1,1,1,1,1,1,1,1,1,1,1,1,1,1
1,1,1,1,1,1,1,1,1,1,1,1,1,1,1,1,1,1,1,1,1,1,1,1,1,1,1,1,1,1
1,1,1,1,1,1,1,1,1,1,1,1,1,1,1,1,1,1,1,1,1,1,1,1,1,1,1,1,1,1
1,1,1,1,1,1,1,1,1,1,1,1,1,1,1,1,1,1,1,1,1,1,1,1,1,1,1,1,1,1
1,1,1,1,1,1,1,1,1,1,1,1,1,1,1,1,1,1,1,1,1,1,1,1,1,1,1,1,1,1
1,1,1,1,1,1,1,1,1,1,1,1,1,1,1,1,1,1,1,1,1,1,1,1,1,1,1,1,1,1
1,1,1,1,1,1,1,1,1,1,1,1,1,1,1,1,1,1,1,1,1,1,1,1,1,1,1,1,1,1
1,1,1,1,1,1,1,1,1,1,1,1,1,1,1,1,1,1,1,1,1,1,1,1,1,1,1,1,1,1
1,1,1,1,1,1,1,1,1,1,1,1,1,1,1,1,1,1,1,1,1,1,1,1,1,1,1,1,1,1
1,1,1,1,1,1,1,1,1,1,1,1,1,1,1,1,1,1,1,1,1,1,1,1,1,1,1,1,1,1
1,1,1,1,1,1,1,1,1,1,1,1,1,1,1,1,1,1,1,1,1,1,1,1,1,1,1,1,1,1
1,1,1,1,1,1,1,1,1,1,1,1,1,1,1,1,1,1,1,1,1,1,1,1,1,1,1,1,1,1
1,1,1,1,1,1,1,1,1,1,1,1,1,1,1,1,1,1,1,1,1,1,1,1,1,1,1,1,1,1
1,1,1,1,1,1,1,1,1,1,1,1,1,1,1,1,1,1,1,1,1,1,1,1,1,1,1,1,1,1
1,1,1,1,1,1,1,1,1,1,1,1,1,1,1,1,1,1,1,1,1,1,1,1,1,1,1,1,1,1
1,1,1,1,1,1,1,1,1,1,1,1,1,1,1,1,1,1,1,1,1,1,1,1,1,1,1,1,1,1
1,1,1,1,1,1,1,1,1,1,1,1,1,1,1,1,1,1,1,1,1,1,1,1,1,1,1,1,1,1
1,1,1,1,1,1,1,1,1,1,1,1,1,1,1,1,1,1,1,1,1,1,1,1,1,1,1,1,1,1
1,1,1,1,1,1,1,1,1,1,1,1,1,1,1,1,1,1,1,1,1,1,1,1,1,1,1,1,1,1
1,1,1,1,1,1,1,1,1,1,1,1,1,1,1,1,1,1,1,1,1,1,1,1,1,1,1,1,1,1
endlayer

layer
2,2,2,2,2,2,2,2,2,2,2,2,2,2,2,2,2,2,2,2,2,2,2,2,2,2,2,2,2,2
2,2,2,2,2,2,2,2,2,2,2,2,2,2,2,2,2,2,2,2,2,2,2,2,2,2,2,2,2,2
2,2,2,2,2,2,2,2,2,2,2,2,2,2,2,2,2,2,2,2,2,2,2,2,2,2,2,2,2,2
2,2,2,2,2,2,2,2,2,2,3,3,3,3,3,3,3,3,3,2,2,2,2,2,2,2,2,2,2,2
2,2,2,2,2,2,2,2,3,3,3,3,3,3,3,3,3,3,3,3,3,3,2,2,2,2,2,2,2,2
2,2,2,2,2,2,2,3,3,3,3,3,3,4,4,4,3,3,3,3,3,3,3,2,2,2,2,2,2,2
2,2,2,2,2,2,3,3,3,3,3,3,3,4,5,4,3,3,3,3,3,3,3,3,2,2,2,2,2,2
2,2,2,2,2,3,3,3,3,3,3,3,3,4,4,4,3,3,3,3,3,3,3,3,3,2,2,2,2,2
2,2,2,2,2,3,3,3,3,3,3,3,3,6,6,6,3,3,3,3,3,3,3,3,3,2,2,2,2,2
2,2,2,2,3,3,3,3,3,3,3,8,7,0,0,0,8,7,3,3,3,3,3,3,3,2,2,2,2,2
2,2,2,2,3,3,3,3,3,3,7,0,0,0,0,0,0,0,8,3,3,3,3,3,3,2,2,2,2,2
2,2,2,2,3,3,3,3,3,3,7,0,0,0,0,0,0,0,9,7,3,3,3,3,3,2,2,2,2,2
2,2,10,2,3,3,3,3,14,13,0,0,0,11,12,0,0,0,0,12,11,3,3,3,3,2,10,2,2,2
2,2,10,2,3,3,3,3,14,13,0,0,0,0,7,0,0,0,0,12,11,3,3,3,3,2,10,2,2,2
2,2,10,2,3,3,3,3,14,13,0,0,0,0,0,0,0,0,0,12,11,3,3,3,3,2,10,2,2,2
2,2,2,2,3,3,3,3,3,3,8,0,0,0,0,0,0,0,8,7,3,3,3,3,3,2,2,2,2,2
2,2,2,2,3,3,3,3,3,3,8,0,0,0,0,0,0,0,8,3,3,3,3,3,3,2,2,2,2,2
2,2,2,2,3,3,3,3,3,3,3,8,8,0,0,0,8,8,3,3,3,3,3,3,3,2,2,2,2,2
2,2,2,2,2,3,3,3,3,3,3,3,3,13,13,13,3,3,3,3,3,3,3,3,2,2,2,2,2,2
2,2,2,2,2,3,3,3,3,3,3,3,3,15,15,15,3,3,3,3,3,3,3,3,2,2,2,2,2,2
2,2,2,2,2,2,3,3,3,3,3,3,3,3,3,3,3,3,3,3,3,3,3,2,2,2,2,2,2,2
2,2,2,2,2,2,2,3,3,3,3,3,3,3,5,3,3,3,3,3,3,3,2,2,2,2,2,2,2,2
2,2,2,2,2,2,2,2,3,3,3,3,3,3,3,3,3,3,3,3,3,2,2,2,2,2,2,2,2,2
2,2,2,2,2,2,2,2,2,2,3,3,3,3,3,3,3,3,3,2,2,2,2,2,2,2,2,2,2,2
2,2,2,2,2,2,2,2,2,2,2,2,2,2,2,2,2,2,2,2,2,2,2,2,2,2,2,2,2,2
2,2,2,2,2,2,2,2,2,2,2,2,2,2,2,2,2,2,2,2,2,2,2,2,2,2,2,2,2,2
2,2,2,2,2,2,2,2,2,2,2,2,10,2,2,10,10,2,2,2,2,2,2,2,2,2,2,2,2,2
2,2,2,2,2,2,2,2,2,2,2,2,10,2,2,2,10,2,2,2,2,2,2,2,2,2,2,2,2,2
2,2,2,2,2,2,2,2,2,2,2,2,2,10,2,2,10,2,2,2,2,2,2,2,2,2,2,2,2,2
2,2,2,2,2,2,2,2,2,2,2,2,10,2,2,2,10,2,2,2,2,2,2,2,2,2,2,2,2,2
endlayer

layer
10,10,10,10,10,10,10,10,10,10,10,10,10,10,10,10,10,10,10,10,10,10,10,10,10,10,10,10,10,10
10,10,10,10,10,10,10,10,10,10,10,10,16,17,17,17,16,10,10,10,10,10,10,10,10,10,10,10,10,10
10,10,10,2,10,10,10,10,10,10,18,18,2,20,20,19,18,18,18,10,10,10,10,10,10,2,10,10,10,10
10,10,10,10,10,10,10,10,18,18,21,21,16,19,20,19,16,21,21,18,18,10,10,10,10,10,10,10,10,10
10,10,10,10,10,10,10,18,21,21,21,21,21,19,20,19,21,21,21,21,21,18,10,10,10,10,10,10,10,10
10,10,10,10,10,10,18,21,21,21,21,21,21,19,19,19,21,21,21,21,21,21,18,10,10,10,10,10,10,10
10,10,10,10,10,18,21,21,21,21,21,21,21,16,16,19,21,21,21,21,21,21,21,18,10,10,10,10,10,10
10,10,10,10,18,21,21,21,21,21,21,21,19,16,16,19,19,21,21,21,21,21,21,21,18,10,10,10,10,10
10,10,10,10,18,21,21,21,21,21,21,19,19,16,19,19,19,19,21,21,21,21,21,21,18,10,10,10,10,10
10,10,10,18,21,21,21,21,21,21,19,19,8,7,7,7,7,19,19,21,21,21,21,21,21,18,10,10,10,10
10,10,10,18,21,21,21,21,21,19,19,5,7,7,7,7,8,5,19,19,21,21,21,21,21,18,10,10,10,10
10,10,16,18,16,21,21,21,19,19,7,7,7,7,7,7,7,7,7,19,19,21,21,21,16,18,16,10,10,10
10,10,23,20,19,19,19,19,20,20,7,7,7,0,0,11,7,7,7,19,19,19,19,19,19,19,22,10,10,10
10,10,23,20,20,20,20,20,20,20,7,7,7,0,7,7,7,7,7,20,20,20,20,20,20,20,22,10,10,10
10,10,23,19,19,19,19,19,19,19,7,7,7,0,0,7,7,7,7,20,19,19,19,19,19,20,22,10,10,10
10,10,16,18,16,21,21,21,19,19,9,8,7,7,7,7,7,7,8,19,19,21,21,21,16,18,16,10,10,10
10,10,10,18,21,21,21,21,21,19,19,5,8,7,7,7,7,5,20,19,21,21,21,21,24,18,10,10,10,10
10,10,10,18,21,21,21,21,21,21,19,19,8,7,7,7,7,20,19,21,21,21,21,21,24,18,10,10,10,10
10,10,10,10,18,21,21,21,21,21,21,19,19,20,20,19,19,19,21,21,21,21,21,21,18,10,10,10,10,10
10,10,10,10,18,21,21,21,21,21,21,21,19,19,20,19,19,21,21,21,21,21,21,21,18,10,10,10,10,10
10,10,10,10,10,18,21,21,21,21,21,21,21,19,20,19,21,21,21,21,21,21,21,18,10,10,10,10,10,10
10,10,10,10,10,10,18,21,21,21,21,21,21,19,20,19,21,21,21,21,21,21,18,10,10,10,10,10,10,10
10,10,10,10,10,10,10,18,21,21,21,21,21,19,20,19,21,21,21,21,21,18,10,10,10,10,10,10,10,10
10,10,10,10,10,10,10,10,18,18,24,24,16,19,20,19,16,21,21,18,18,10,10,10,10,10,10,10,10,10
10,10,10,10,10,10,10,10,10,10,18,18,18,20,20,20,18,18,18,10,10,10,10,10,10,10,10,10,10,10
10,10,2,26,2,26,10,10,10,10,10,10,16,25,25,25,16,10,10,10,10,10,10,10,10,10,10,10,10,10
10,10,28,28,26,26,10,10,10,10,10,10,22,27,27,27,23,10,10,10,10,10,10,10,10,10,10,10,10,10
10,10,10,2,10,2,10,10,10,10,10,10,22,27,27,27,23,10,10,10,10,10,10,10,10,10,10,10,10,10
10,10,10,10,10,10,10,10,10,2,10,10,22,27,27,27,23,10,10,2,10,10,10,10,10,10,10,10,10,10
10,10,10,10,10,10,10,10,10,10,10,10,22,27,27,27,23,10,10,10,10,10,10,10,10,10,10,10,10,10
endlayer

layer
0,0,0,0,0,0,0,0,0,0,0,0,0,0,0,0,0,0,0,0,0,0,0,0,0,0,0,0,0,0
0,0,0,0,0,0,0,0,0,0,0,0,16,0,0,0,16,0,0,0,0,0,0,0,0,0,0,0,0,0
0,0,0,29,0,0,0,30,0,0,18,18,18,0,0,0,18,18,18,0,0,0,0,0,0,29,0,0,0,0
0,0,30,0,0,0,0,0,18,18,0,0,16,0,0,0,16,0,0,18,18,0,0,30,0,0,0,0,0,0
0,0,0,0,0,0,0,18,0,0,0,0,0,0,0,0,0,0,0,0,0,18,0,0,0,0,0,0,0,0
0,0,0,0,30,0,18,0,0,0,0,0,0,0,0,0,0,0,0,0,0,0,18,0,0,0,0,0,0,0
0,0,0,0,0,18,0,0,0,0,0,0,0,0,0,0,0,0,0,0,0,0,0,18,0,0,0,0,0,0
0,0,0,0,18,0,0,0,0,0,0,0,0,0,0,0,0,0,0,0,0,0,0,0,18,0,0,0,0,0
0,0,0,0,18,0,0,0,0,0,0,0,0,0,0,0,0,0,0,0,0,0,0,0,18,0,0,0,0,0
0,0,0,18,0,0,0,0,0,0,0,0,31,0,0,0,31,0,0,0,0,0,0,0,0,18,0,0,0,0
0,0,0,18,0,0,0,0,0,0,0,35,8,34,0,33,7,32,0,0,0,0,0,0,0,18,0,0,0,0
0,0,16,18,16,0,0,0,0,0,33,7,7,7,7,8,7,8,34,0,0,0,0,0,16,18,16,0,0,0
0,0,0,0,0,0,0,0,0,0,0,36,7,0,0,0,7,36,0,0,0,0,0,0,0,0,0,0,0,0
0,0,0,0,0,0,0,0,0,0,0,0,7,0,7,0,37,0,0,0,0,0,0,0,0,0,0,0,0,0
0,0,0,0,0,0,0,0,0,0,0,31,7,0,12,11,7,31,0,0,0,0,0,0,0,0,0,0,0,0
0,0,16,18,16,0,0,0,0,0,33,8,7,8,7,8,7,8,34,0,0,0,0,0,16,18,16,0,0,0
0,0,0,18,0,0,0,0,0,0,0,35,7,34,0,33,7,35,0,0,0,0,0,0,0,18,0,0,0,0
0,0,0,18,0,0,0,0,0,0,0,0,36,0,0,0,36,0,0,0,0,0,0,0,0,18,0,0,0,0
0,0,0,0,18,0,0,0,0,0,0,0,0,0,0,0,0,0,0,0,0,0,0,0,18,0,0,0,0,0
0,0,0,0,18,0,0,0,0,0,0,0,0,0,0,0,0,0,0,0,0,0,0,0,18,0,0,0,0,0
0,0,0,0,0,18,0,0,0,0,0,0,0,0,0,0,0,0,0,0,0,0,0,18,0,0,0,0,0,0
0,0,0,0,0,0,18,0,0,0,0,0,0,0,0,0,0,0,0,0,0,0,18,0,0,0,0,0,0,0
0,0,0,0,0,0,0,18,0,0,0,0,0,0,0,0,0,0,0,0,0,18,0,0,0,0,30,0,0,0
0,0,30,0,0,30,0,0,18,18,0,0,16,0,0,0,16,0,0,18,18,0,0,0,0,30,0,0,0,0
0,0,0,0,0,0,0,0,0,30,18,18,18,0,0,0,18,18,18,0,0,0,0,0,0,0,0,0,0,0
0,0,39,0,39,38,0,0,0,0,0,0,16,0,0,0,16,0,0,0,0,0,0,0,0,0,0,0,0,0
0,0,38,38,38,38,0,0,0,0,0,0,0,0,0,0,0,0,0,0,30,0,0,0,0,0,0,0,0,0
0,0,0,39,0,39,0,30,0,0,0,0,0,0,0,0,0,0,0,0,0,0,0,0,0,0,0,0,0,0
0,0,0,0,0,0,0,0,0,29,30,0,0,0,0,0,0,0,30,29,0,0,0,0,0,0,0,0,0,0
0,0,0,0,30,0,0,0,0,0,0,0,0,0,0,0,0,0,0,0,0,0,0,0,0,0,0,0,0,0
endlayer

layer
0,0,0,0,0,0,0,0,0,0,0,0,0,0,0,0,0,0,0,0,0,0,0,0,0,0,0,0,0,0
0,0,0,0,0,0,0,0,0,0,0,0,16,0,0,0,16,0,0,0,0,0,0,0,0,0,0,0,0,0
0,0,0,29,0,0,0,0,0,0,18,18,18,40,40,40,18,18,18,0,0,0,0,0,0,29,0,0,0,0
0,0,0,0,0,0,0,0,18,18,0,0,16,0,0,0,16,0,0,18,18,0,0,0,0,0,0,0,0,0
0,0,0,0,0,0,0,18,0,0,0,0,41,0,0,0,41,0,0,0,0,18,0,0,0,0,0,0,0,0
0,0,0,0,0,0,18,0,0,0,0,0,0,0,0,0,0,0,0,0,0,42,18,0,0,0,0,0,0,0
0,0,0,0,0,18,0,0,0,0,0,0,0,0,0,0,0,0,0,0,0,0,41,18,0,0,0,0,0,0
0,0,0,0,18,0,0,0,0,0,0,0,0,0,0,0,0,0,0,0,0,0,0,0,18,0,0,0,0,0
0,0,0,0,18,0,0,0,0,0,0,0,0,0,0,0,0,0,0,0,0,0,0,0,18,0,0,0,0,0
0,0,0,18,0,0,0,0,0,0,0,0,0,0,0,0,0,0,0,0,0,0,0,0,0,18,0,0,0,0
0,0,0,18,0,0,0,0,0,0,0,35,7,0,0,0,8,35,0,0,0,0,0,0,0,18,0,0,0,0
0,0,16,18,16,44,0,0,0,0,0,8,7,7,43,7,7,7,0,0,0,0,0,42,16,18,16,0,0,0
0,0,0,40,0,0,0,0,0,0,0,0,8,0,0,0,8,0,0,0,0,0,0,0,0,40,0,0,0,0
0,0,0,40,0,0,0,0,0,0,0,0,43,12,7,0,45,0,0,0,0,0,0,0,0,40,0,0,0,0
0,0,0,40,0,0,0,0,0,0,0,0,7,11,0,0,7,0,0,0,0,0,0,0,0,40,0,0,0,0
0,0,16,18,16,44,0,0,0,0,0,7,7,7,43,7,7,8,0,0,0,0,0,42,16,18,16,0,0,0
0,0,0,18,0,0,0,0,0,0,0,35,8,0,0,0,7,35,0,0,0,0,0,0,0,18,0,0,0,0
0,0,0,18,0,0,0,0,0,0,0,0,0,0,0,0,0,0,0,0,0,0,0,0,0,18,0,0,0,0
0,0,0,0,18,0,0,0,0,0,0,0,0,0,0,0,0,0,0,0,0,0,0,0,18,0,0,0,0,0
0,0,0,0,18,0,0,0,0,0,0,0,0,0,0,0,0,0,0,0,0,0,0,0,18,0,0,0,0,0
0,0,0,0,0,18,0,0,0,0,0,0,0,0,0,0,0,0,0,0,0,0,0,18,0,0,0,0,0,0
0,0,0,0,0,0,18,0,0,0,0,0,0,0,0,0,0,0,0,0,0,0,18,0,0,0,0,0,0,0
0,0,0,0,0,0,0,18,0,0,0,0,46,0,0,0,46,0,0,0,0,18,0,0,0,0,0,0,0,0
0,0,0,0,0,0,0,0,18,18,0,0,16,0,0,0,16,0,0,18,18,0,0,0,0,0,0,0,0,0
0,0,0,0,0,0,0,0,0,0,18,18,18,40,40,40,18,18,18,0,0,0,0,0,0,0,0,0,0,0
0,0,0,0,0,0,0,0,0,0,0,0,16,0,0,0,16,0,0,0,0,0,0,0,0,0,0,0,0,0
0,0,0,0,0,0,0,0,0,0,0,0,41,0,0,0,41,0,0,0,0,0,0,0,0,0,0,0,0,0
0,0,0,0,0,0,0,0,0,0,0,0,0,0,0,0,0,0,0,0,0,0,0,0,0,0,0,0,0,0
0,0,0,0,0,0,0,0,0,29,0,0,0,0,0,0,0,0,0,29,0,0,0,0,0,0,0,0,0,0
0,0,0,0,0,0,0,0,0,0,0,0,0,0,0,0,0,0,0,0,0,0,0,0,0,0,0,0,0,0
endlayer

layer
0,0,0,0,0,0,0,0,0,0,0,0,0,0,0,0,0,0,0,0,0,0,0,0,47,47,47,0,0,0
0,0,0,0,0,0,0,0,0,0,0,0,23,50,0,49,22,0,0,0,0,0,0,48,47,47,48,47,0,0
0,0,0,29,0,0,0,0,0,0,18,18,18,40,40,40,18,18,18,0,0,0,0,48,47,29,48,47,0,0
0,0,0,0,0,0,0,0,18,18,0,0,23,50,0,49,22,0,0,18,18,0,0,47,47,47,48,47,0,0
0,0,0,0,0,0,0,18,0,0,0,0,0,0,0,0,0,0,0,0,0,18,0,47,47,47,48,0,0,0
0,0,0,0,0,0,18,44,0,0,0,0,0,0,0,0,0,0,0,0,0,0,18,0,0,0,0,0,0,0
0,0,0,0,0,18,41,0,0,0,0,0,0,0,0,0,0,0,0,0,0,0,0,18,0,0,0,0,0,0
0,0,0,0,18,0,0,0,0,0,0,0,0,0,0,0,0,0,0,0,0,0,0,0,18,0,0,0,0,0
0,0,0,0,18,0,0,0,0,0,0,0,0,0,0,0,0,0,0,0,0,0,0,0,18,0,0,0,0,0
0,0,0,18,0,0,0,0,0,0,0,0,0,0,0,0,0,0,0,0,0,0,0,0,0,18,0,0,0,0
0,0,0,18,0,0,0,0,0,0,0,0,7,52,0,51,7,0,0,0,0,0,0,0,0,18,0,0,0,0
0,0,17,18,17,0,0,0,0,0,0,7,7,7,9,7,7,7,0,0,0,0,0,0,17,18,17,0,0,0
0,0,53,40,53,0,0,0,0,0,0,54,7,11,12,0,7,54,0,0,0,0,0,0,53,40,53,0,0,0
0,0,0,40,0,0,0,0,0,0,0,0,9,0,7,0,9,0,0,0,0,0,0,0,0,40,0,0,0,0
0,0,55,40,55,0,0,0,0,0,0,56,8,0,0,0,7,56,0,0,0,0,0,0,55,40,55,0,0,0
0,0,25,18,25,0,0,0,0,0,0,7,7,7,9,7,7,7,0,0,0,0,0,0,25,18,25,0,0,0
0,0,0,18,0,0,0,0,0,0,0,0,7,52,0,51,7,0,0,0,0,0,0,0,0,18,0,0,0,0
0,0,0,18,0,0,0,0,0,0,0,0,0,0,0,0,0,0,0,0,0,0,0,0,0,18,0,0,0,0
0,0,0,0,18,0,0,0,0,0,0,0,0,0,0,0,0,0,0,0,0,0,0,0,18,0,0,0,0,0
0,0,0,0,18,0,0,0,0,0,0,0,0,0,0,0,0,0,0,0,0,0,0,0,18,0,0,0,0,0
0,0,0,0,0,18,46,0,0,0,0,0,0,0,0,0,0,0,0,0,0,0,46,18,0,0,0,0,0,0
0,0,0,0,0,0,18,44,0,0,0,0,0,0,0,0,0,0,0,0,0,42,18,0,0,0,0,0,0,0
0,0,0,0,0,0,0,18,0,0,0,0,0,0,0,0,0,0,0,0,0,18,0,0,0,0,0,0,0,0
0,0,0,0,0,0,0,0,18,18,0,0,23,50,0,49,22,0,0,18,18,0,0,0,0,0,0,0,0,0
0,0,0,0,0,0,0,0,0,0,18,18,18,40,40,40,18,18,18,0,0,0,0,0,0,0,0,0,0,0
0,0,0,0,0,0,0,0,0,0,0,0,23,50,0,49,22,0,0,0,0,0,0,0,0,0,0,0,0,0
0,0,0,0,0,0,0,0,0,0,0,0,0,0,0,0,0,0,0,0,0,0,0,0,0,0,0,0,0,0
0,0,0,0,0,0,0,0,0,0,0,0,0,0,0,0,0,0,0,0,0,0,0,0,0,0,0,0,0,0
0,0,0,0,0,0,0,0,0,29,0,0,0,0,0,0,0,0,0,29,0,0,0,0,0,0,0,0,0,0
0,0,0,0,0,0,0,0,0,0,0,0,0,0,0,0,0,0,0,0,0,0,0,0,0,0,0,0,0,0
endlayer

layer
0,0,0,0,0,0,0,0,0,0,0,0,0,0,0,0,0,0,0,0,0,0,0,0,47,47,47,0,0,0
0,0,0,0,0,0,0,0,0,0,0,0,0,23,16,22,0,0,0,0,0,0,0,48,47,47,48,47,0,0
0,0,0,29,0,0,0,0,0,0,27,27,23,40,40,40,22,27,27,0,0,0,0,48,47,29,48,47,0,0
0,0,0,0,0,0,0,0,18,18,0,0,0,23,16,22,0,0,0,18,18,0,0,47,47,47,48,47,0,0
0,0,0,0,0,0,0,18,0,0,0,0,0,0,0,0,0,0,0,0,0,18,0,0,47,47,48,0,0,0
0,0,0,0,0,0,18,0,0,0,0,0,0,0,0,0,0,0,0,0,0,0,18,0,0,0,0,0,0,0
0,0,0,0,0,18,0,0,0,0,0,0,0,0,0,0,0,0,0,0,0,0,0,18,0,0,0,0,0,0
0,0,0,0,18,0,0,0,0,0,0,0,0,0,0,0,0,0,0,0,0,0,0,0,18,0,0,0,0,0
0,0,0,0,18,0,0,0,0,0,0,0,0,0,0,0,0,0,0,0,0,0,0,0,18,0,0,0,0,0
0,0,0,27,0,0,0,0,0,0,0,0,0,0,0,0,0,0,0,0,0,0,0,0,0,27,0,0,0,0
0,0,0,27,0,0,0,0,0,0,0,0,7,30,0,30,7,0,0,0,0,0,0,0,0,27,0,0,0,0
0,0,0,17,0,0,0,0,0,0,0,7,7,7,7,7,7,7,0,0,0,0,0,0,0,17,0,0,0,0
0,0,17,40,17,0,0,0,0,0,0,30,7,0,0,11,7,30,0,0,0,0,0,0,17,40,17,0,0,0
0,0,16,40,16,0,0,0,0,0,0,0,7,0,7,12,7,0,0,0,0,0,0,0,16,40,16,0,0,0
0,0,25,40,25,0,0,0,0,0,0,30,7,0,0,0,7,30,0,0,0,0,0,0,25,40,25,0,0,0
0,0,0,25,0,0,0,0,0,0,0,7,7,7,7,7,7,7,0,0,0,0,0,0,0,25,0,0,0,0
0,0,0,27,0,0,0,0,0,0,0,0,7,30,0,30,7,0,0,0,0,0,0,0,0,27,0,0,0,0
0,0,0,27,0,0,0,0,0,0,0,0,0,0,0,0,0,0,0,0,0,0,0,0,0,27,0,0,0,0
0,0,0,0,18,0,0,0,0,0,0,0,0,0,0,0,0,0,0,0,0,0,0,0,18,0,0,0,0,0
0,0,0,0,18,0,0,0,0,0,0,0,0,0,0,0,0,0,0,0,0,0,0,0,18,0,0,0,0,0
0,0,0,0,0,18,0,0,0,0,0,0,0,0,0,0,0,0,0,0,0,0,0,18,0,0,0,0,0,0
0,0,0,0,0,0,18,0,0,0,0,0,0,0,0,0,0,0,0,0,0,0,18,0,0,0,0,0,0,0
0,0,0,0,0,0,0,18,0,0,0,0,0,0,0,0,0,0,0,0,0,18,0,0,0,0,0,0,0,0
0,0,0,0,0,0,0,0,18,18,0,0,0,23,16,22,0,0,0,18,18,0,0,0,0,0,0,0,0,0
0,0,0,0,0,0,0,0,0,0,27,27,23,40,40,40,22,27,27,0,0,0,0,0,0,0,0,0,0,0
0,0,0,0,0,0,0,0,0,0,0,0,0,23,16,22,0,0,0,0,0,0,0,0,0,0,0,0,0,0
0,0,0,0,0,0,0,0,0,0,0,0,0,0,0,0,0,0,47,47,48,48,0,0,0,0,0,0,0,0
0,0,0,0,0,0,0,0,0,0,0,0,0,0,0,0,0,47,47,47,48,48,0,0,0,0,0,0,0,0
0,0,0,0,0,0,0,0,0,29,0,0,0,0,0,0,0,47,47,29,48,48,0,0,0,0,0,0,0,0
0,0,0,0,0,0,0,0,0,0,0,0,0,0,0,0,0,47,47,47,48,48,0,0,0,0,0,0,0,0
endlayer

layer
0,0,47,47,47,0,0,0,0,0,0,0,0,0,0,0,0,0,0,0,0,0,0,0,0,0,0,0,0,0
0,48,47,47,47,47,0,0,0,0,0,0,0,0,0,0,0,0,0,0,0,0,0,0,47,47,0,0,0,0
0,48,47,29,47,47,0,0,0,0,0,0,0,40,40,40,0,0,0,0,0,0,0,0,47,29,47,0,0,0
0,48,47,47,47,47,0,0,0,0,0,0,0,0,0,0,0,0,0,0,0,0,0,0,0,47,47,0,0,0
0,0,47,47,47,0,0,0,0,0,0,0,0,0,0,0,0,0,0,0,0,0,0,0,0,0,0,0,0,0
0,0,0,0,0,0,0,0,0,0,0,0,0,0,0,0,0,0,0,0,0,0,0,0,0,0,0,0,0,0
0,0,0,0,0,0,0,0,0,0,0,0,0,0,0,0,0,0,0,0,0,0,0,0,0,0,0,0,0,0
0,0,0,0,0,0,0,0,0,0,0,0,0,0,0,0,0,0,0,0,0,0,0,0,0,0,0,0,0,0
0,0,0,0,0,0,0,0,0,0,0,0,0,0,0,0,0,0,0,0,0,0,0,0,0,0,0,0,0,0
0,0,0,0,0,0,0,0,0,0,0,0,0,0,0,0,0,0,0,0,0,0,0,0,0,0,0,0,0,0
0,0,0,0,0,0,0,0,0,0,0,0,31,0,0,0,31,0,0,0,0,0,0,0,0,0,0,0,0,0
0,0,0,0,0,0,0,0,0,0,0,33,18,7,31,7,18,34,0,0,0,0,0,0,0,0,0,0,0,0
0,0,0,40,0,0,0,0,0,0,0,0,7,0,0,0,7,0,0,0,0,0,0,0,0,40,0,0,0,0
0,0,0,40,0,0,0,0,0,0,0,0,33,0,7,0,34,0,0,0,0,0,0,0,0,40,0,0,0,0
0,0,0,40,0,0,0,0,0,0,0,0,7,0,12,11,7,0,0,0,0,0,0,0,0,40,0,0,0,0
0,0,0,0,0,0,0,0,0,0,0,33,18,7,36,7,18,34,0,0,0,0,0,0,0,0,0,0,0,0
0,0,0,0,0,0,0,0,0,0,0,0,36,0,0,0,36,0,0,0,0,0,0,0,0,0,0,0,0,0
0,0,0,0,0,0,0,0,0,0,0,0,0,0,0,0,0,0,0,0,0,0,0,0,0,0,0,0,0,0
0,0,0,0,0,0,0,0,0,0,0,0,0,0,0,0,0,0,0,0,0,0,0,0,0,0,0,0,0,0
0,0,0,0,0,0,0,0,0,0,0,0,0,0,0,0,0,0,0,0,0,0,0,0,0,0,0,0,0,0
0,0,0,0,0,0,0,0,0,0,0,0,0,0,0,0,0,0,0,0,0,0,0,0,0,0,0,0,0,0
0,0,0,0,0,0,0,0,0,0,0,0,0,0,0,0,0,0,0,0,0,0,0,0,0,0,0,0,0,0
0,0,0,0,0,0,0,0,0,0,0,0,0,0,0,0,0,0,0,0,0,0,0,0,0,0,0,0,0,0
0,0,0,0,0,0,0,0,0,0,0,0,0,0,0,0,0,0,0,0,0,0,0,0,0,0,0,0,0,0
0,0,0,0,0,0,0,0,0,0,0,0,0,40,40,40,0,0,0,0,0,0,0,0,0,0,0,0,0,0
0,0,0,0,0,0,0,0,0,0,0,0,0,0,0,0,0,0,0,0,0,0,0,0,0,0,0,0,0,0
0,0,0,0,0,0,0,47,47,47,47,47,0,0,0,0,0,47,47,47,48,48,0,0,0,0,0,0,0,0
0,0,0,0,0,0,0,47,47,47,47,47,0,0,0,0,0,47,47,47,48,48,0,0,0,0,0,0,0,0
0,0,0,0,0,0,0,47,47,29,47,47,0,0,0,0,0,47,47,29,48,48,0,0,0,0,0,0,0,0
0,0,0,0,0,0,0,47,47,47,47,47,0,0,0,0,0,47,47,47,0,0,0,0,0,0,0,0,0,0
endlayer

layer
0,0,47,47,47,0,0,0,0,0,0,0,0,0,0,0,0,0,0,0,0,0,0,0,0,0,0,0,0,0
0,48,47,47,47,47,0,0,0,0,0,0,0,0,0,0,0,0,0,0,0,0,0,0,0,47,0,0,0,0
0,48,47,29,47,47,0,0,0,0,0,0,0,0,0,0,0,0,0,0,0,0,0,0,47,47,47,0,0,0
0,47,47,47,47,47,0,0,0,0,0,0,0,0,0,0,0,0,0,0,0,0,0,0,0,47,0,0,0,0
0,0,47,47,47,47,0,0,0,0,0,0,0,0,0,0,0,0,0,0,0,0,0,0,0,0,0,0,0,0
0,0,0,0,0,0,0,0,0,0,0,0,0,0,0,0,0,0,0,0,0,0,0,0,0,0,0,0,0,0
0,0,0,0,0,0,0,0,0,0,0,0,0,0,0,0,0,0,0,0,0,0,0,0,0,0,0,0,0,0
0,0,0,0,0,0,0,0,0,0,0,0,0,0,0,0,0,0,0,0,0,0,0,0,0,0,0,0,0,0
0,0,0,0,0,0,0,0,0,0,0,0,0,0,0,0,0,0,0,0,0,0,0,0,0,0,0,0,0,0
0,0,0,0,0,0,0,0,0,0,0,0,0,0,0,0,0,0,0,0,0,0,0,0,0,0,0,0,0,0
0,0,0,0,0,0,0,0,0,0,0,0,0,0,0,0,0,0,0,0,0,0,0,0,0,0,0,0,0,0
0,0,0,0,0,0,0,0,0,0,0,0,18,7,0,7,18,0,0,0,0,0,0,0,0,0,0,0,0,0
0,0,0,0,0,0,0,0,0,0,0,0,7,0,0,0,7,0,0,0,0,0,0,0,0,0,0,0,0,0
0,0,0,0,0,0,0,0,0,0,0,0,0,12,0,0,0,0,0,0,0,0,0,0,0,0,0,0,0,0
0,0,0,0,0,0,0,0,0,0,0,0,7,11,0,0,7,0,0,0,0,0,0,0,0,0,0,0,0,0
0,0,0,0,0,0,0,0,0,0,0,0,18,7,0,7,18,0,0,0,0,0,0,0,0,0,0,0,0,0
0,0,0,0,0,0,0,0,0,0,0,0,0,0,0,0,0,0,0,0,0,0,0,0,0,0,0,0,0,0
0,0,0,0,0,0,0,0,0,0,0,0,0,0,0,0,0,0,0,0,0,0,0,0,0,0,0,0,0,0
0,0,0,0,0,0,0,0,0,0,0,0,0,0,0,0,0,0,0,0,0,0,0,0,0,0,0,0,0,0
0,0,0,0,0,0,0,0,0,0,0,0,0,0,0,0,0,0,0,0,0,0,0,0,0,0,0,0,0,0
0,0,0,0,0,0,0,0,0,0,0,0,0,0,0,0,0,0,0,0,0,0,0,0,0,0,0,0,0,0
0,0,0,0,0,0,0,0,0,0,0,0,0,0,0,0,0,0,0,0,0,0,0,0,0,0,0,0,0,0
0,0,0,0,0,0,0,0,0,0,0,0,0,0,0,0,0,0,0,0,0,0,0,0,0,0,0,0,0,0
0,0,0,0,0,0,0,0,0,0,0,0,0,0,0,0,0,0,0,0,0,0,0,0,0,0,0,0,0,0
0,0,0,0,0,0,0,0,0,0,0,0,0,0,0,0,0,0,0,0,0,0,0,0,0,0,0,0,0,0
0,0,0,0,0,0,0,0,0,0,0,0,0,0,0,0,0,0,0,0,0,0,0,0,0,0,0,0,0,0
0,0,0,0,0,0,0,47,47,47,47,47,0,0,0,0,0,0,0,0,0,0,0,0,0,0,0,0,0,0
0,0,0,0,0,0,0,47,47,47,47,47,0,0,0,0,0,0,0,47,0,0,0,0,0,0,0,0,0,0
0,0,0,0,0,0,0,47,47,29,47,47,0,0,0,0,0,0,47,29,48,0,0,0,0,0,0,0,0,0
0,0,0,0,0,0,0,47,47,47,47,47,0,0,0,0,0,0,47,47,0,0,0,0,0,0,0,0,0,0
endlayer

layer
0,0,0,0,0,0,0,0,0,0,0,0,0,0,0,0,0,0,0,0,0,0,0,0,0,0,0,0,0,0
0,0,0,47,47,0,0,0,0,0,0,0,0,0,0,0,0,0,0,0,0,0,0,0,0,0,0,0,0,0
0,0,47,29,47,0,0,0,0,0,0,0,0,0,0,0,0,0,0,0,0,0,0,0,0,0,0,0,0,0
0,0,47,47,47,0,0,0,0,0,0,0,0,0,0,0,0,0,0,0,0,0,0,0,0,0,0,0,0,0
0,0,0,0,0,0,0,0,0,0,0,0,0,0,0,0,0,0,0,0,0,0,0,0,0,0,0,0,0,0
0,0,0,0,0,0,0,0,0,0,0,0,0,0,0,0,0,0,0,0,0,0,0,0,0,0,0,0,0,0
0,0,0,0,0,0,0,0,0,0,0,0,0,0,0,0,0,0,0,0,0,0,0,0,0,0,0,0,0,0
0,0,0,0,0,0,0,0,0,0,0,0,0,0,0,0,0,0,0,0,0,0,0,0,0,0,0,0,0,0
0,0,0,0,0,0,0,0,0,0,0,0,0,0,0,0,0,0,0,0,0,0,0,0,0,0,0,0,0,0
0,0,0,0,0,0,0,0,0,0,0,0,0,0,0,0,0,0,0,0,0,0,0,0,0,0,0,0,0,0
0,0,0,0,0,0,0,0,0,0,0,0,0,0,0,0,0,0,0,0,0,0,0,0,0,0,0,0,0,0
0,0,0,0,0,0,0,0,0,0,0,0,18,7,0,7,18,0,0,0,0,0,0,0,0,0,0,0,0,0
0,0,0,0,0,0,0,0,0,0,0,0,7,11,12,0,7,0,0,0,0,0,0,0,0,0,0,0,0,0
0,0,0,0,0,0,0,0,0,0,0,0,0,0,0,0,0,0,0,0,0,0,0,0,0,0,0,0,0,0
0,0,0,0,0,0,0,0,0,0,0,0,7,0,0,0,7,0,0,0,0,0,0,0,0,0,0,0,0,0
0,0,0,0,0,0,0,0,0,0,0,0,18,7,0,7,18,0,0,0,0,0,0,0,0,0,0,0,0,0
0,0,0,0,0,0,0,0,0,0,0,0,0,0,0,0,0,0,0,0,0,0,0,0,0,0,0,0,0,0
0,0,0,0,0,0,0,0,0,0,0,0,0,0,0,0,0,0,0,0,0,0,0,0,0,0,0,0,0,0
0,0,0,0,0,0,0,0,0,0,0,0,0,0,0,0,0,0,0,0,0,0,0,0,0,0,0,0,0,0
0,0,0,0,0,0,0,0,0,0,0,0,0,0,0,0,0,0,0,0,0,0,0,0,0,0,0,0,0,0
0,0,0,0,0,0,0,0,0,0,0,0,0,0,0,0,0,0,0,0,0,0,0,0,0,0,0,0,0,0
0,0,0,0,0,0,0,0,0,0,0,0,0,0,0,0,0,0,0,0,0,0,0,0,0,0,0,0,0,0
0,0,0,0,0,0,0,0,0,0,0,0,0,0,0,0,0,0,0,0,0,0,0,0,0,0,0,0,0,0
0,0,0,0,0,0,0,0,0,0,0,0,0,0,0,0,0,0,0,0,0,0,0,0,0,0,0,0,0,0
0,0,0,0,0,0,0,0,0,0,0,0,0,0,0,0,0,0,0,0,0,0,0,0,0,0,0,0,0,0
0,0,0,0,0,0,0,0,0,0,0,0,0,0,0,0,0,0,0,0,0,0,0,0,0,0,0,0,0,0
0,0,0,0,0,0,0,0,0,0,0,0,0,0,0,0,0,0,0,0,0,0,0,0,0,0,0,0,0,0
0,0,0,0,0,0,0,0,0,47,47,0,0,0,0,0,0,0,0,47,0,0,0,0,0,0,0,0,0,0
0,0,0,0,0,0,0,0,47,29,47,0,0,0,0,0,0,0,47,47,48,0,0,0,0,0,0,0,0,0
0,0,0,0,0,0,0,0,0,47,0,0,0,0,0,0,0,0,0,0,0,0,0,0,0,0,0,0,0,0
endlayer

layer
0,0,0,0,0,0,0,0,0,0,0,0,0,0,0,0,0,0,0,0,0,0,0,0,0,0,0,0,0,0
0,0,0,0,0,0,0,0,0,0,0,0,0,0,0,0,0,0,0,0,0,0,0,0,0,0,0,0,0,0
0,0,0,47,47,0,0,0,0,0,0,0,0,0,0,0,0,0,0,0,0,0,0,0,0,0,0,0,0,0
0,0,0,47,0,0,0,0,0,0,0,0,0,0,0,0,0,0,0,0,0,0,0,0,0,0,0,0,0,0
0,0,0,0,0,0,0,0,0,0,0,0,0,0,0,0,0,0,0,0,0,0,0,0,0,0,0,0,0,0
0,0,0,0,0,0,0,0,0,0,0,0,0,0,0,0,0,0,0,0,0,0,0,0,0,0,0,0,0,0
0,0,0,0,0,0,0,0,0,0,0,0,0,0,0,0,0,0,0,0,0,0,0,0,0,0,0,0,0,0
0,0,0,0,0,0,0,0,0,0,0,0,0,0,0,0,0,0,0,0,0,0,0,0,0,0,0,0,0,0
0,0,0,0,0,0,0,0,0,0,0,0,0,0,0,0,0,0,0,0,0,0,0,0,0,0,0,0,0,0
0,0,0,0,0,0,0,0,0,0,0,0,0,0,0,0,0,0,0,0,0,0,0,0,0,0,0,0,0,0
0,0,0,0,0,0,0,0,0,0,0,0,0,0,0,0,0,0,0,0,0,0,0,0,0,0,0,0,0,0
0,0,0,0,0,0,0,0,0,0,0,0,18,0,0,0,18,0,0,0,0,0,0,0,0,0,0,0,0,0
0,0,0,0,0,0,0,0,0,0,0,0,0,0,0,11,0,0,0,0,0,0,0,0,0,0,0,0,0,0
0,0,0,0,0,0,0,0,0,0,0,0,0,0,0,11,0,0,0,0,0,0,0,0,0,0,0,0,0,0
0,0,0,0,0,0,0,0,0,0,0,0,0,0,0,11,0,0,0,0,0,0,0,0,0,0,0,0,0,0
0,0,0,0,0,0,0,0,0,0,0,0,18,0,0,0,18,0,0,0,0,0,0,0,0,0,0,0,0,0
0,0,0,0,0,0,0,0,0,0,0,0,0,0,0,0,0,0,0,0,0,0,0,0,0,0,0,0,0,0
0,0,0,0,0,0,0,0,0,0,0,0,0,0,0,0,0,0,0,0,0,0,0,0,0,0,0,0,0,0
0,0,0,0,0,0,0,0,0,0,0,0,0,0,0,0,0,0,0,0,0,0,0,0,0,0,0,0,0,0
0,0,0,0,0,0,0,0,0,0,0,0,0,0,0,0,0,0,0,0,0,0,0,0,0,0,0,0,0,0
0,0,0,0,0,0,0,0,0,0,0,0,0,0,0,0,0,0,0,0,0,0,0,0,0,0,0,0,0,0
0,0,0,0,0,0,0,0,0,0,0,0,0,0,0,0,0,0,0,0,0,0,0,0,0,0,0,0,0,0
0,0,0,0,0,0,0,0,0,0,0,0,0,0,0,0,0,0,0,0,0,0,0,0,0,0,0,0,0,0
0,0,0,0,0,0,0,0,0,0,0,0,0,0,0,0,0,0,0,0,0,0,0,0,0,0,0,0,0,0
0,0,0,0,0,0,0,0,0,0,0,0,0,0,0,0,0,0,0,0,0,0,0,0,0,0,0,0,0,0
0,0,0,0,0,0,0,0,0,0,0,0,0,0,0,0,0,0,0,0,0,0,0,0,0,0,0,0,0,0
0,0,0,0,0,0,0,0,0,0,0,0,0,0,0,0,0,0,0,0,0,0,0,0,0,0,0,0,0,0
0,0,0,0,0,0,0,0,0,47,0,0,0,0,0,0,0,0,0,0,0,0,0,0,0,0,0,0,0,0
0,0,0,0,0,0,0,0,47,47,47,0,0,0,0,0,0,0,0,0,0,0,0,0,0,0,0,0,0,0
0,0,0,0,0,0,0,0,0,47,0,0,0,0,0,0,0,0,0,0,0,0,0,0,0,0,0,0,0,0
endlayer

