
# Created by Ruins mod version 17.1 Ingame Parser
# authoring Player: Nemsun

# criterion expression specifying mod ids required to load template
# may include plus (AND), minus (AND NOT), comma (OR), and parentheses
# all required mods listed must be present; no prohibited mods can be
requiredMods=
# likelihood this template will be chosen relative to all others
# e.g., a weight=6 template is chosen 3X as often as one with weight=2
weight=1
# list of other biomes in which this template may spawn
# biome corresponding to directory is always assumed, listed or not
# generic templates should leave this list empty
biomesToSpawnIn=
# criterion expression specifying types of biome where template spawns
# this is in addition to those explicitly listed as biomesToSpawnIn
# generic templates should leave this list empty
biomeTypesToSpawnIn=
# list of biomes in which this template may not spawn
# takes precedence over biomeTypesToSpawnIn, but NOT biomesToSpawnIn
# should be empty if biomeTypesToSpawnIn is empty
biomesToNotSpawnIn=
# depth template is pushed down into the surface when built
# offset is min/max range of random additional bury depth
embed_into_distance=0
random_height_offset=0,0
# whitelist/blacklist of block types on which template may be built
# specify one, not both; leave the other empty (both empty = allow all)
acceptable_target_blocks=
unacceptable_target_blocks=flowing_water,water,flowing_lava,lava
# size of template (#layers, #rows per layer, #blocks per row)
dimensions=17,15,30
# max number of missing blocks allowed in surface beneath template
allowable_overhang=0
# depth/height limit affected by terrain leveling
# also maximum bumpiness tolerated in surface beneath template
max_leveling=2
# padding applied to all sides of template horizontal footprint
# expands area affected by terrain leveling (-1 = no leveling)
leveling_buffer=0
# do not rotate template randomly when built (1 = no rotation)
preventRotation=0
# treat water/lava blocks as air and protect them from rule0 (1 = yes)
preserve_water=0
preserve_lava=0
# minimum distance this template must have from instances of itself
uniqueMinDistance=0
# min/max distances this template can be from world spawn (0 = no limit)
# only applies to overworld--i.e., dimension 0
spawnMinDistance=0
spawnMaxDistance=0
# other template built nearby whenever this one is
# syntax: <name>;<relativeX>;<maxYdifference>;<relativeZ>[;<chance>]
# may be used more than once to specify multiple neighbors
adjoining_template=

rule1=0,100,minecraft:dirt-0
rule2=0,100,minecraft:grass-0
rule3=0,100,minecraft:stone-0
rule4=0,100,minecraft:glowstone-0
rule5=0,100,minecraft:tnt-0
rule6=0,100,minecraft:cobblestone-0
rule7=0,100,minecraft:water-0
rule8=0,100,minecraft:oak_stairs-3
rule9=0,100,ChestGenHook:chests/simple_dungeon:5-5
rule10=0,100,minecraft:oak_stairs-2
rule11=0,100,minecraft:planks-0
rule12=0,100,minecraft:bookshelf-0
rule13=0,100,ChestGenHook:chests/simple_dungeon:5-2
rule14=0,100,minecraft:enchanting_table-0
rule15=0,100,minecraft:trapped_chest-2
rule16=0,100,minecraft:log-0
rule17=0,100,minecraft:reeds-2
rule18=0,100,minecraft:waterlily-0
rule19=0,100,minecraft:reeds-0
rule20=0,100,minecraft:reeds-1
rule21=0,100,minecraft:reeds-3
rule22=0,100,minecraft:oak_stairs-0
rule23=0,100,minecraft:stonebrick-0
rule24=0,100,minecraft:leaves-4
rule25=0,100,minecraft:fence-0
rule26=0,100,minecraft:stone_stairs-4
rule27=0,100,minecraft:oak_stairs-6
rule28=0,100,minecraft:oak_stairs-7
rule29=0,100,minecraft:stone_stairs-6
rule30=0,100,minecraft:stone_stairs-7
rule31=0,100,minecraft:stone_stairs-5
rule32=0,100,minecraft:leaves-12
rule33=0,100,minecraft:oak_stairs-1
rule34=0,100,minecraft:spruce_stairs-4
rule35=0,100,minecraft:wooden_slab-9
rule36=0,100,minecraft:spruce_stairs-6
rule37=0,100,minecraft:spruce_stairs-7
rule38=2,100,WallSign:null:Need most:Clay &:Glowstone-5
rule39=2,100,WallSign:null:Donations:In Here:null-5
rule40=0,100,minecraft:ladder-4
rule41=0,100,minecraft:wooden_door-2
rule42=0,100,minecraft:oak_stairs-5
rule43=0,100,minecraft:spruce_stairs-5
rule44=0,100,minecraft:planks-2
rule45=2,100,WallSign:null:TO SORT:null:null-4
rule46=0,100,ChestGenHook:chests/simple_dungeon:5-4
rule47=0,100,minecraft:wooden_door-9
rule48=0,100,minecraft:wooden_door-8
rule49=0,100,minecraft:glass_pane-0
rule50=0,100,realistictorches:torch_unlit-1
rule51=0,100,realistictorches:torch_unlit-3
rule52=0,100,realistictorches:torch_unlit-5
rule53=0,100,realistictorches:torch_unlit-4
rule54=0,100,realistictorches:torch_unlit-2
rule55=2,100,WallSign:BOOK DEPOSITS:null:FOR THE LAZY:null-4
rule56=2,100,minecraft:torch-3
rule57=2,100,minecraft:torch-4
rule58=0,100,minecraft:spruce_stairs-2
rule59=0,100,minecraft:spruce_stairs-3
rule60=0,100,minecraft:spruce_stairs-1
rule61=2,100,minecraft:torch-2
rule62=2,100,WallSign:null:NemGo:Library:null-5
rule63=2,100,WallSign:null:Ye Old:Book Shop:null-5
rule64=0,100,minecraft:stone_brick_stairs-6
rule65=0,100,minecraft:stone_brick_stairs-4
rule66=0,100,minecraft:planks-1
rule67=0,100,minecraft:wooden_slab-1
rule68=0,100,minecraft:stone_brick_stairs-5
rule69=0,100,minecraft:stone_brick_stairs-0
rule70=0,100,minecraft:stone_brick_stairs-7
rule71=0,100,minecraft:stone_slab-13
rule72=0,100,minecraft:trapdoor-11
rule73=0,100,minecraft:stone_brick_stairs-3
rule74=0,100,minecraft:stone_brick_stairs-2
rule75=0,100,minecraft:stone_brick_stairs-1
rule76=0,100,minecraft:stone_slab-5
rule77=0,100,minecraft:spruce_stairs-0
rule78=0,100,minecraft:birch_stairs-2
rule79=2,100,WallSign:Deliver to:NemGo Library:null:Old Books-4
rule80=0,100,minecraft:birch_stairs-3
rule81=0,100,contenttweaker:nb4-0
rule82=0,100,minecraft:birch_stairs-6
rule83=0,100,minecraft:birch_stairs-7
rule84=0,100,minecraft:log-9

layer
1,1,1,1,1,1,1,1,1,1,1,1,1,1,1,1,1,1,1,1,1,1,1,1,1,1,1,1,1,1
1,1,1,1,1,1,1,1,1,1,1,1,1,1,1,1,1,1,1,1,1,1,1,1,1,1,1,1,1,1
1,1,1,1,1,1,1,1,1,1,1,1,1,3,3,3,3,1,1,1,1,1,1,2,1,2,1,1,1,1
1,1,1,1,1,1,1,1,1,1,1,1,1,3,3,3,3,1,1,1,1,1,2,1,2,1,2,1,1,1
1,1,1,1,1,1,1,1,1,1,1,1,1,3,3,3,3,1,1,1,1,1,1,2,1,2,1,1,1,1
1,1,1,1,1,1,1,1,1,1,1,1,1,3,3,3,3,1,2,1,2,1,1,1,2,1,2,1,1,1
1,1,1,1,1,1,1,1,1,1,1,1,1,3,3,3,3,2,1,2,1,2,1,2,1,1,1,1,1,1
1,1,1,1,1,1,1,1,1,1,1,1,1,3,3,3,3,1,2,1,2,1,2,1,2,1,2,1,1,1
1,1,1,1,1,1,1,1,1,1,1,1,1,3,3,3,3,1,1,2,1,2,1,2,1,2,1,1,1,1
1,1,1,1,1,1,1,1,1,1,1,1,1,1,1,3,1,1,1,1,1,1,1,1,1,1,1,1,1,1
1,1,1,1,1,1,1,1,1,1,1,1,1,1,1,3,1,1,1,1,1,1,1,1,1,1,1,1,1,1
1,1,1,1,1,1,1,1,1,1,1,1,1,5,3,3,4,3,4,1,1,1,1,1,1,1,1,1,1,1
1,1,1,1,1,1,1,1,1,1,1,1,1,5,3,3,3,3,3,1,1,1,1,1,1,1,1,1,1,1
1,1,1,1,1,1,1,1,1,1,1,1,1,5,3,3,4,3,4,1,1,1,1,1,1,1,1,1,1,1
1,1,1,1,1,1,1,1,1,1,1,1,1,1,1,1,1,1,1,1,1,1,1,1,1,1,1,1,1,1
endlayer

layer
1,1,1,1,1,1,1,1,1,1,1,1,1,1,1,1,1,1,1,1,1,1,1,1,1,1,1,1,1,1
1,1,1,1,1,1,1,1,1,1,1,1,6,6,6,6,6,6,1,1,1,1,1,1,1,1,1,1,1,1
1,1,1,1,7,1,7,1,7,1,7,1,10,0,9,9,0,8,2,7,2,7,2,7,2,7,2,1,1,1
1,1,1,7,1,7,1,7,1,7,1,7,10,0,0,0,0,8,7,2,7,2,7,2,7,2,7,1,1,1
1,1,1,1,7,1,7,1,7,1,7,1,10,0,0,0,0,8,2,7,2,7,2,7,2,7,2,1,1,1
1,1,1,7,1,7,1,7,1,7,1,7,10,0,0,0,0,8,7,2,7,2,7,2,7,2,7,1,1,1
1,1,1,1,7,1,7,1,7,1,7,1,10,0,0,0,0,8,2,7,2,7,2,7,2,7,2,1,1,1
1,1,1,7,1,7,1,7,1,7,1,7,10,0,0,0,0,8,7,2,7,2,7,2,7,2,7,1,1,1
1,1,1,1,7,1,7,1,7,1,7,1,10,0,0,0,0,8,2,7,2,7,2,7,2,7,2,1,1,1
1,1,1,7,1,7,1,7,1,7,1,1,6,6,6,6,6,6,1,1,1,1,1,1,11,11,11,1,1,1
1,1,1,1,7,1,7,1,7,1,1,1,1,1,3,0,12,12,12,1,1,1,1,1,1,11,11,1,1,1
1,1,1,7,1,7,1,7,1,7,1,1,1,3,13,0,0,0,0,12,1,1,1,1,1,11,11,1,1,1
1,1,1,1,7,1,7,1,7,1,1,1,1,3,15,0,0,14,0,12,1,1,1,1,1,11,11,1,1,1
1,1,1,1,1,1,1,1,1,1,1,1,1,3,13,0,0,0,0,12,1,1,1,1,1,1,1,1,1,1
1,1,1,1,1,1,1,1,1,1,1,1,1,1,3,3,12,12,12,1,1,1,1,1,1,1,1,1,1,1
endlayer

layer
1,1,1,1,1,1,1,1,1,1,1,1,1,1,1,1,1,1,1,1,1,1,1,1,1,1,1,1,1,1
1,1,1,6,6,6,16,6,6,6,16,6,6,6,6,6,6,6,6,16,6,6,6,16,6,6,6,1,1,1
1,1,6,19,18,19,18,19,18,19,18,19,0,0,0,0,0,0,19,18,20,18,20,18,19,18,17,6,1,1
1,1,6,18,19,18,19,18,19,18,17,18,0,0,0,0,0,0,18,20,18,19,18,19,18,19,18,6,1,1
1,1,6,20,18,17,18,19,18,19,18,20,0,0,0,0,0,0,0,18,19,18,19,18,19,18,21,6,1,1
1,1,16,18,19,18,19,18,19,18,19,18,0,0,0,0,0,0,18,19,18,20,18,17,18,19,18,16,1,1
1,1,6,19,18,19,18,19,18,19,18,19,0,0,0,0,0,0,19,18,19,18,19,18,19,18,0,6,1,1
1,1,6,18,19,0,20,18,20,18,20,18,0,0,0,0,0,0,18,19,18,20,18,19,18,19,18,6,1,1
1,1,6,19,18,19,18,19,18,20,18,20,0,0,0,0,0,0,19,18,19,0,19,18,19,18,0,6,1,1
1,1,16,18,19,18,20,18,19,18,16,6,6,6,6,6,6,6,6,16,6,6,6,16,0,0,0,16,1,1
1,1,6,19,18,19,18,20,18,19,6,1,1,1,3,0,12,12,12,1,1,1,1,16,22,0,0,6,1,1
1,1,6,18,19,18,21,18,20,18,6,1,1,3,0,0,0,0,0,12,1,1,1,1,10,0,0,6,1,1
1,1,6,17,18,21,18,19,18,19,6,1,1,3,0,0,0,0,0,12,1,1,1,1,10,0,0,6,1,1
1,1,1,6,6,6,16,6,6,6,1,1,1,3,0,0,0,0,0,12,1,1,1,16,6,6,6,1,1,1
1,1,1,1,1,1,1,1,1,1,1,1,1,1,3,3,12,12,12,1,1,1,1,1,1,1,1,1,1,1
endlayer

layer
2,23,1,23,23,23,1,23,23,23,1,23,23,1,23,23,1,23,23,1,23,23,23,1,23,23,23,1,23,2
2,1,1,6,4,6,16,6,4,6,16,4,4,6,6,6,6,4,4,16,6,4,6,16,6,4,6,1,1,2
2,23,6,20,0,19,0,20,0,19,0,19,0,0,0,0,0,0,19,0,19,0,19,0,17,0,19,6,23,2
2,23,4,0,19,0,19,0,19,0,20,0,0,0,0,0,0,0,0,19,0,19,0,19,0,19,0,4,23,2
2,23,6,19,0,19,0,19,0,20,0,19,0,0,0,0,0,0,0,0,20,0,20,0,19,0,19,6,23,2
2,1,16,0,20,0,20,0,20,0,19,0,0,0,0,0,0,0,0,19,0,20,0,20,0,19,0,16,1,2
2,23,6,19,0,17,0,19,0,20,0,19,0,0,0,0,0,0,19,0,19,0,20,0,20,0,0,6,23,2
2,23,4,0,19,0,17,0,19,0,19,0,0,0,0,0,0,0,0,19,0,19,0,19,0,19,0,4,23,2
2,23,6,20,0,19,0,19,0,17,0,19,0,0,0,0,0,0,19,0,19,0,19,0,17,0,0,6,23,2
2,1,16,0,19,0,20,0,19,0,16,4,4,6,6,6,6,4,4,16,6,4,6,16,0,0,0,16,1,2
2,23,6,19,0,19,0,20,0,19,6,23,23,1,1,1,1,23,23,1,2,2,2,16,0,0,0,6,23,2
2,23,4,0,19,0,20,0,19,0,4,23,23,23,23,23,23,23,23,4,11,11,11,10,0,0,0,4,23,2
2,23,6,19,0,19,0,20,0,20,6,23,23,23,23,23,23,23,23,1,11,11,11,10,0,0,0,6,23,2
2,1,1,6,4,6,16,6,4,6,1,1,23,23,23,23,23,23,3,1,1,4,1,16,6,4,6,1,1,2
2,2,1,23,23,23,1,23,23,23,1,23,2,23,23,23,23,2,23,1,23,23,23,1,23,23,23,1,23,2
endlayer

layer
24,25,16,0,0,0,16,0,0,0,16,0,0,16,0,0,16,0,0,16,0,0,0,16,0,0,0,16,25,24
24,16,16,6,26,6,16,6,26,6,16,6,6,16,6,6,16,6,6,16,6,26,6,16,6,26,6,16,16,24
24,0,6,19,0,19,0,19,0,19,0,19,28,11,11,11,11,27,19,0,19,0,19,0,19,0,19,6,0,24
24,0,30,0,19,0,19,0,19,0,19,0,28,11,11,11,11,27,0,19,0,19,0,19,0,19,0,29,0,24
24,0,6,19,0,19,0,19,0,19,0,19,28,11,11,11,11,27,0,0,19,0,19,0,19,0,19,6,0,24
24,16,16,0,19,0,19,0,19,0,19,0,28,11,11,11,11,27,0,19,0,19,0,19,0,19,0,16,16,24
24,0,6,19,0,19,0,19,0,19,0,19,28,11,11,11,11,27,19,0,19,0,19,0,19,0,0,6,0,24
24,0,30,0,19,0,19,0,19,0,19,0,28,11,11,11,11,27,0,19,0,19,0,19,0,19,0,29,0,24
24,0,6,19,0,19,0,19,0,19,0,19,28,11,11,11,11,27,19,0,19,0,19,0,19,0,0,6,0,24
24,16,16,0,19,0,19,0,19,0,16,31,16,16,11,11,16,16,31,16,6,6,6,16,0,0,0,16,16,24
24,0,6,19,0,19,0,19,0,19,6,0,25,16,33,33,16,25,0,6,33,33,33,16,0,0,0,6,0,32
24,0,30,0,19,0,19,0,19,0,29,0,0,25,0,0,25,0,0,30,0,0,0,0,0,0,0,29,0,32
24,0,6,19,0,19,0,19,0,19,6,0,0,25,0,0,25,0,0,6,0,0,0,0,0,0,0,6,0,32
24,16,16,6,31,6,16,6,31,6,16,16,25,25,0,0,25,25,16,16,6,31,6,16,6,31,6,16,16,32
0,25,16,0,0,0,16,0,0,0,16,25,24,0,0,0,0,24,25,16,0,0,0,16,0,0,0,16,25,0
endlayer

layer
0,25,16,34,35,34,16,34,35,34,16,34,34,16,34,34,16,34,34,16,34,35,34,16,34,35,34,16,25,0
0,16,16,6,6,6,16,6,6,6,16,6,6,16,6,6,16,6,6,16,6,6,6,16,6,6,6,16,16,0
0,37,6,11,11,11,11,11,11,11,11,11,16,36,35,35,37,16,11,11,11,11,11,11,11,11,11,6,36,0
0,35,6,11,11,11,11,11,11,11,11,11,10,0,39,38,0,8,11,11,11,11,11,11,11,11,11,6,35,0
0,37,6,11,11,11,11,11,11,11,11,11,10,0,0,0,0,8,11,11,11,11,11,11,11,11,11,6,36,0
0,16,16,11,11,11,11,11,11,11,11,11,10,0,0,0,0,8,11,11,11,11,11,11,11,11,11,16,16,0
0,37,6,11,11,11,11,11,11,11,11,11,10,0,0,0,0,8,11,11,11,11,11,11,11,11,11,6,36,0
0,35,6,11,11,11,11,11,11,11,11,11,10,0,0,0,0,8,11,11,11,11,11,11,11,11,11,6,35,0
0,37,6,11,11,11,11,11,11,11,11,11,16,40,0,0,40,16,11,11,11,11,11,11,11,11,11,6,36,0
0,16,16,11,11,11,11,11,11,11,16,6,16,16,41,41,16,16,6,16,33,33,33,11,11,11,11,16,16,0
0,37,6,11,11,11,11,11,11,11,6,0,25,16,0,0,16,25,0,6,0,0,0,16,42,42,42,6,36,0
0,35,6,11,11,11,11,11,11,11,6,0,0,25,0,0,25,0,0,6,0,0,0,0,0,0,0,6,35,0
0,37,6,11,11,11,11,11,11,11,6,0,0,0,0,0,0,0,0,6,0,0,0,0,0,0,0,6,36,0
0,16,16,6,6,6,16,6,6,6,16,16,0,0,0,0,0,0,16,16,6,6,6,16,6,6,6,16,16,0
0,25,16,43,35,43,16,43,35,43,16,25,0,0,0,0,0,0,25,16,43,35,43,16,43,35,43,16,25,0
endlayer

layer
0,25,16,0,0,0,16,0,0,0,16,25,25,16,25,25,16,25,25,16,0,0,0,16,0,0,0,16,25,0
0,16,16,44,44,44,16,44,44,44,16,44,44,16,44,44,16,44,44,16,44,44,44,16,44,44,44,16,16,0
0,0,44,12,12,12,12,12,12,12,12,12,16,0,9,9,0,16,12,12,12,12,12,12,12,12,12,44,0,0
0,0,44,12,0,0,0,0,0,0,0,0,0,0,0,0,0,0,0,0,0,0,0,0,0,0,12,44,0,0
0,0,44,12,0,0,0,0,0,0,0,0,0,0,0,0,0,0,0,0,0,0,0,0,0,0,12,44,0,0
0,16,16,12,0,0,12,12,12,12,12,0,0,0,0,0,0,0,0,12,12,12,12,12,0,0,12,16,16,0
0,0,44,12,0,0,12,0,0,0,0,0,0,0,0,0,0,0,0,0,0,0,0,0,0,0,12,44,0,0
0,0,44,12,0,0,12,0,0,0,0,45,0,0,0,0,0,0,0,0,0,0,0,0,0,0,12,44,0,0
0,0,44,12,0,0,12,0,0,12,46,46,16,40,0,0,40,16,0,0,0,0,0,12,12,12,12,44,0,0
0,16,16,12,0,0,12,0,0,12,16,44,16,16,48,47,16,16,44,16,0,0,0,16,0,0,0,16,16,0
0,0,44,12,0,0,0,0,0,12,44,0,25,16,0,0,16,25,0,44,0,0,0,16,0,0,0,44,0,0
0,0,44,12,0,0,0,0,0,12,44,0,0,25,0,0,25,0,0,44,0,0,0,0,0,0,0,44,0,0
0,0,44,12,12,12,12,12,12,12,44,0,0,0,0,0,0,0,0,44,0,0,0,0,0,0,0,44,0,0
0,16,16,44,44,44,16,44,44,44,16,16,0,0,0,0,0,0,16,16,44,44,44,16,44,44,44,16,16,0
0,25,16,0,0,0,16,0,0,0,16,25,0,0,0,0,0,0,25,16,0,0,0,16,0,0,0,16,25,0
endlayer

layer
0,25,16,0,0,0,16,0,0,0,16,25,25,16,0,0,16,25,25,16,0,0,0,16,0,0,0,16,25,0
0,16,16,44,49,44,16,44,49,44,16,44,44,16,49,49,16,44,44,16,44,49,44,16,44,49,44,16,16,0
0,0,44,12,0,12,12,12,0,12,50,12,16,50,0,0,50,16,12,50,12,0,50,12,50,0,12,44,0,0
0,0,49,0,0,0,0,0,0,0,0,0,0,0,0,0,0,0,0,0,0,0,0,0,0,0,0,49,0,0
0,0,44,12,0,0,0,0,0,0,0,0,0,0,0,0,0,0,0,0,0,0,0,0,0,0,51,44,0,0
0,16,16,12,0,0,12,0,0,0,0,0,0,0,0,0,0,0,0,52,12,0,12,0,0,0,12,16,16,0
0,0,44,53,0,0,52,0,0,0,0,0,0,0,0,0,0,0,0,0,0,0,0,0,0,0,51,44,0,0
0,0,49,0,0,0,0,0,0,0,0,0,54,0,0,0,0,54,0,0,0,0,0,0,0,0,0,49,0,0
0,0,44,12,0,0,12,0,0,12,0,55,16,40,0,0,40,16,0,54,0,0,0,12,12,12,12,44,0,0
0,16,16,12,0,0,0,0,0,12,16,44,16,16,34,34,16,16,44,16,57,0,0,16,0,0,56,16,16,0
0,0,44,12,0,0,0,0,0,12,44,0,59,16,0,0,16,58,0,44,0,0,0,16,0,0,0,44,0,0
0,0,49,0,0,0,0,0,0,0,49,0,59,60,60,60,60,58,0,49,0,0,0,0,0,0,0,49,0,0
0,0,44,12,0,12,12,12,0,12,44,0,0,0,63,62,0,0,0,44,0,0,0,61,0,0,0,44,0,0
0,16,16,44,49,44,16,44,49,44,16,16,0,0,0,0,0,0,16,16,44,49,44,16,44,49,44,16,16,0
0,25,16,0,0,0,16,0,0,0,16,25,0,0,0,0,0,0,25,16,0,0,0,16,0,0,0,16,25,0
endlayer

layer
0,25,16,0,0,0,16,0,0,0,16,25,25,16,0,0,16,25,25,16,0,0,0,16,0,0,0,16,65,64
0,16,16,44,44,44,16,44,44,44,16,44,44,16,49,49,16,44,44,16,44,44,44,16,44,44,44,16,16,0
0,0,44,12,12,12,12,12,12,12,12,12,16,0,0,0,0,16,12,12,12,12,12,12,12,12,12,44,0,0
0,0,44,12,0,0,0,0,0,0,0,0,0,0,0,0,0,0,0,0,0,0,0,0,0,0,12,44,0,0
0,0,44,12,0,0,0,0,0,0,0,0,0,0,0,0,0,0,0,0,0,0,0,0,0,0,12,44,0,0
0,16,16,12,0,0,0,0,0,0,0,0,0,0,0,0,0,0,0,0,0,0,0,0,0,0,12,16,16,0
0,0,44,12,0,0,0,0,0,0,0,0,0,0,0,0,0,0,0,0,0,0,0,0,0,0,12,44,0,0
0,0,44,12,0,0,0,0,0,0,0,0,0,0,0,0,0,0,0,0,0,0,0,0,0,0,12,44,0,0
0,0,44,12,0,0,0,0,0,12,0,0,16,40,34,34,40,16,0,0,0,0,0,12,12,12,12,44,0,0
0,16,16,12,0,0,0,0,0,12,16,44,16,16,66,66,16,16,44,16,0,0,0,16,0,0,0,16,16,0
0,0,44,12,0,0,0,0,0,12,44,0,0,67,60,60,67,0,0,44,0,0,0,16,0,0,0,44,0,0
0,0,44,12,0,0,0,0,0,12,44,0,0,0,0,0,0,0,0,44,0,0,0,0,0,0,0,44,0,0
0,0,44,12,12,12,12,12,12,12,44,0,0,0,0,0,0,0,0,44,0,0,0,0,0,0,0,44,0,0
0,16,16,44,44,44,16,44,44,44,16,16,0,0,0,0,0,0,16,16,44,44,44,16,44,44,44,16,16,0
0,25,16,0,0,0,16,0,0,0,16,25,0,0,0,0,0,0,25,16,0,0,0,16,0,0,0,16,68,64
endlayer

layer
69,69,69,64,71,70,69,64,71,70,69,64,70,69,64,70,69,64,70,69,64,71,70,69,64,71,70,69,69,69
68,16,16,44,44,44,16,44,44,44,16,44,44,16,44,44,16,44,44,16,44,44,44,16,44,44,44,16,16,68
0,37,11,11,11,11,11,11,11,11,11,11,11,11,11,11,11,11,11,11,11,11,11,11,11,11,11,11,36,0
0,37,11,11,11,11,11,11,11,11,11,11,11,11,11,11,11,11,11,11,11,11,11,11,11,11,11,11,36,0
0,37,11,11,11,11,11,11,11,11,11,11,11,11,11,11,11,11,11,11,11,11,11,11,11,11,11,11,36,0
37,16,11,11,11,11,11,11,11,11,11,11,11,11,11,11,11,11,11,11,11,11,11,11,11,11,11,11,16,36
0,37,11,11,11,11,11,11,11,11,11,11,11,11,11,11,11,11,11,11,11,11,11,11,11,11,11,11,36,0
0,37,11,11,11,11,11,11,11,11,11,11,11,11,11,11,11,11,11,11,11,11,11,11,11,11,11,11,36,0
0,37,11,11,11,11,11,11,11,11,11,11,11,72,11,11,72,11,11,11,11,11,11,11,11,11,11,11,36,0
37,16,11,11,11,11,11,11,11,11,16,44,16,16,11,11,16,16,44,16,11,11,11,11,11,11,11,11,16,36
0,37,11,11,11,11,11,11,11,11,44,64,68,68,68,68,68,68,68,44,11,11,11,11,11,11,11,11,36,0
0,37,11,11,11,11,11,11,11,11,44,71,0,0,0,0,0,0,71,44,11,11,11,11,11,11,11,11,36,0
0,37,11,11,11,11,11,11,11,11,44,65,0,0,0,0,0,0,65,44,11,11,11,11,11,11,11,11,36,0
65,16,16,44,44,44,16,44,44,44,16,74,0,0,0,0,0,0,73,16,44,44,44,16,44,44,44,16,16,65
75,75,75,64,71,70,75,64,71,70,75,76,0,0,0,0,0,0,76,75,64,71,70,75,64,71,70,75,75,75
endlayer

layer
0,0,0,0,76,0,0,0,76,0,0,0,0,0,76,76,0,0,0,0,0,76,0,0,0,76,0,0,0,0
69,77,77,77,77,77,77,77,77,77,77,77,77,77,77,77,77,77,77,77,77,77,77,77,77,77,77,77,77,69
68,44,66,66,66,66,66,66,66,66,66,66,66,66,66,66,66,66,66,66,66,66,66,66,66,66,66,66,44,68
0,44,0,0,0,0,0,0,0,0,0,0,0,0,0,0,0,0,0,0,0,0,0,0,0,0,0,0,44,0
0,44,0,0,0,0,0,0,0,0,0,0,0,0,0,0,0,0,0,0,0,0,0,0,0,0,0,0,44,0
52,16,0,0,0,0,0,0,0,0,0,0,0,0,0,0,0,0,0,0,0,0,0,0,0,0,0,0,16,52
0,44,0,0,0,0,0,0,0,0,0,0,0,0,0,0,0,0,0,0,0,0,0,0,0,0,0,0,44,0
0,80,0,0,0,0,0,0,0,0,0,0,0,0,0,0,0,0,0,79,0,0,0,0,0,0,0,0,78,0
0,44,0,0,0,0,0,0,0,0,0,0,0,0,0,0,0,0,0,81,0,0,0,0,0,0,0,0,44,0
52,16,0,0,0,0,0,0,0,66,60,60,66,66,66,66,66,66,60,60,66,0,0,0,0,0,0,0,16,52
0,44,0,0,0,0,0,0,0,66,58,0,0,76,0,0,76,0,0,59,66,0,0,0,0,0,0,0,44,0
0,44,0,0,0,0,0,0,66,66,58,76,0,0,0,0,0,0,76,59,66,66,0,0,0,0,0,0,44,0
65,44,66,66,66,66,66,66,66,66,58,0,0,0,0,0,0,0,0,59,66,66,66,66,66,66,66,66,44,65
75,60,60,60,60,60,60,60,60,60,58,0,0,0,0,0,0,0,0,60,60,60,60,60,60,60,60,60,60,75
0,0,0,0,76,0,0,0,76,0,0,0,0,0,0,0,0,0,0,0,0,76,0,0,0,76,0,0,0,0
endlayer

layer
0,0,0,0,0,0,0,0,0,0,0,0,0,0,0,0,0,0,0,0,0,0,0,0,0,0,0,0,0,0
0,0,0,0,0,0,0,0,0,0,0,0,0,0,0,0,0,0,0,0,0,0,0,0,0,0,0,0,0,0
69,77,77,77,77,77,77,77,77,77,77,77,77,77,77,77,77,77,77,77,77,77,77,77,77,77,77,77,77,69
68,44,43,43,43,43,43,43,43,43,43,43,43,43,43,43,43,43,43,43,43,43,43,43,43,43,43,43,44,68
0,44,0,0,0,0,0,0,0,0,0,0,0,0,0,0,0,0,0,0,0,0,0,0,0,0,0,0,44,0
0,16,0,0,0,0,0,0,0,0,0,0,0,0,0,0,0,0,0,0,0,0,0,0,0,0,0,0,16,0
0,44,0,0,0,0,0,0,0,0,0,0,0,0,0,0,0,0,0,0,0,0,0,0,0,0,0,0,44,0
0,49,0,0,0,0,0,0,0,0,0,0,0,0,0,0,0,0,0,0,0,0,0,0,0,0,0,0,49,0
0,44,0,0,0,0,0,0,0,0,0,0,0,0,0,0,0,0,0,0,0,0,0,0,0,0,0,0,44,0
0,16,0,0,0,0,0,0,37,66,43,43,66,49,49,49,49,66,43,43,66,36,0,0,0,0,0,0,16,0
0,44,0,0,0,0,0,0,37,58,0,0,0,0,0,0,0,0,0,0,59,36,0,0,0,0,0,0,44,0
65,44,34,34,34,34,34,34,66,58,0,0,0,0,0,0,0,0,0,0,59,66,34,34,34,34,34,34,44,65
75,60,60,60,60,60,60,60,60,60,0,0,0,0,0,0,0,0,0,0,60,60,60,60,60,60,60,60,60,75
0,0,0,0,0,0,0,0,0,0,0,0,0,0,0,0,0,0,0,0,0,0,0,0,0,0,0,0,0,0
0,0,0,0,0,0,0,0,0,0,0,0,0,0,0,0,0,0,0,0,0,0,0,0,0,0,0,0,0,0
endlayer

layer
0,0,0,0,0,0,0,0,0,0,0,0,0,0,0,0,0,0,0,0,0,0,0,0,0,0,0,0,0,0
0,0,0,0,0,0,0,0,0,0,0,0,0,0,0,0,0,0,0,0,0,0,0,0,0,0,0,0,0,0
0,0,0,0,0,0,0,0,0,0,0,0,0,0,0,0,0,0,0,0,0,0,0,0,0,0,0,0,0,0
69,77,77,77,77,77,77,77,77,77,77,77,77,77,77,77,77,77,77,77,77,77,77,77,77,77,77,77,77,69
68,44,43,43,43,43,43,43,43,43,43,43,43,43,43,43,43,43,43,43,43,43,43,43,43,43,43,43,44,68
0,16,0,0,0,0,0,0,0,0,0,0,0,0,0,0,0,0,0,0,0,0,0,0,0,0,0,0,16,0
0,44,0,0,0,0,0,0,0,0,0,0,0,0,0,0,0,0,0,0,0,0,0,0,0,0,0,0,44,0
0,49,0,0,0,0,0,0,0,0,0,0,0,0,0,0,0,0,0,0,0,0,0,0,0,0,0,0,49,0
0,44,0,0,0,0,0,0,0,0,0,0,0,0,0,0,0,0,0,0,0,0,0,0,0,0,0,0,44,0
0,16,0,0,0,0,0,0,60,60,60,60,66,49,49,49,49,66,60,60,60,60,0,0,0,0,0,0,16,0
65,44,34,34,34,34,34,34,58,0,0,0,0,0,0,0,0,0,0,0,0,59,34,34,34,34,34,34,44,65
75,60,60,60,60,60,60,60,60,0,0,0,0,0,0,0,0,0,0,0,0,59,60,60,60,60,60,60,60,75
0,0,0,0,0,0,0,0,0,0,0,0,0,0,0,0,0,0,0,0,0,0,0,0,0,0,0,0,0,0
0,0,0,0,0,0,0,0,0,0,0,0,0,0,0,0,0,0,0,0,0,0,0,0,0,0,0,0,0,0
0,0,0,0,0,0,0,0,0,0,0,0,0,0,0,0,0,0,0,0,0,0,0,0,0,0,0,0,0,0
endlayer

layer
0,0,0,0,0,0,0,0,0,0,0,0,0,0,0,0,0,0,0,0,0,0,0,0,0,0,0,0,0,0
0,0,0,0,0,0,0,0,0,0,0,0,0,0,0,0,0,0,0,0,0,0,0,0,0,0,0,0,0,0
0,0,0,0,0,0,0,0,0,0,0,0,0,0,0,0,0,0,0,0,0,0,0,0,0,0,0,0,0,0
0,0,0,0,0,0,0,0,0,0,0,0,0,0,0,0,0,0,0,0,0,0,0,0,0,0,0,0,0,0
69,77,77,77,77,77,77,77,77,77,77,77,77,77,77,77,77,77,77,77,77,77,77,77,77,77,77,77,77,69
68,16,43,43,43,43,43,43,43,43,43,43,43,43,43,43,43,43,43,43,43,43,43,43,43,43,43,43,16,68
0,44,0,0,0,0,0,0,0,0,0,0,0,0,0,0,0,0,0,0,0,0,0,0,0,0,0,0,44,0
0,83,0,0,0,0,0,0,0,0,0,0,0,0,0,0,0,0,0,0,0,0,0,0,0,0,0,0,82,0
0,44,0,0,0,0,0,0,0,0,0,0,0,0,0,0,0,0,0,0,0,0,0,0,0,0,0,0,44,0
65,16,34,34,34,34,34,34,43,43,43,43,66,49,49,49,49,66,43,43,43,43,34,34,34,34,34,34,16,65
75,60,60,60,60,60,60,58,0,0,0,0,0,0,0,0,0,0,0,0,0,0,59,60,60,60,60,60,60,75
0,0,0,0,0,0,0,0,0,0,0,0,0,0,0,0,0,0,0,0,0,0,0,0,0,0,0,0,0,0
0,0,0,0,0,0,0,0,0,0,0,0,0,0,0,0,0,0,0,0,0,0,0,0,0,0,0,0,0,0
0,0,0,0,0,0,0,0,0,0,0,0,0,0,0,0,0,0,0,0,0,0,0,0,0,0,0,0,0,0
0,0,0,0,0,0,0,0,0,0,0,0,0,0,0,0,0,0,0,0,0,0,0,0,0,0,0,0,0,0
endlayer

layer
0,0,0,0,0,0,0,0,0,0,0,0,0,0,0,0,0,0,0,0,0,0,0,0,0,0,0,0,0,0
0,0,0,0,0,0,0,0,0,0,0,0,0,0,0,0,0,0,0,0,0,0,0,0,0,0,0,0,0,0
0,0,0,0,0,0,0,0,0,0,0,0,0,0,0,0,0,0,0,0,0,0,0,0,0,0,0,0,0,0
0,0,0,0,0,0,0,0,0,0,0,0,0,0,0,0,0,0,0,0,0,0,0,0,0,0,0,0,0,0
0,0,0,0,0,0,0,0,0,0,0,0,0,0,0,0,0,0,0,0,0,0,0,0,0,0,0,0,0,0
69,77,77,77,77,77,77,77,77,77,77,77,77,77,77,77,77,77,77,77,77,77,77,77,77,77,77,77,77,69
68,44,43,43,43,43,43,43,43,43,43,43,43,43,43,43,43,43,43,43,43,43,43,43,43,43,43,43,44,68
0,44,0,0,0,0,0,0,0,0,0,0,0,0,0,0,0,0,0,0,0,0,0,0,0,0,0,0,44,0
65,44,34,34,34,34,34,34,34,34,34,34,34,34,34,34,34,34,34,34,34,34,34,34,34,34,34,34,44,65
75,60,60,60,60,60,60,60,60,60,60,60,60,60,60,60,60,60,60,60,60,60,60,60,60,60,60,60,60,75
0,0,0,0,0,0,0,0,0,0,0,0,0,0,0,0,0,0,0,0,0,0,0,0,0,0,0,0,0,0
0,0,0,0,0,0,0,0,0,0,0,0,0,0,0,0,0,0,0,0,0,0,0,0,0,0,0,0,0,0
0,0,0,0,0,0,0,0,0,0,0,0,0,0,0,0,0,0,0,0,0,0,0,0,0,0,0,0,0,0
0,0,0,0,0,0,0,0,0,0,0,0,0,0,0,0,0,0,0,0,0,0,0,0,0,0,0,0,0,0
0,0,0,0,0,0,0,0,0,0,0,0,0,0,0,0,0,0,0,0,0,0,0,0,0,0,0,0,0,0
endlayer

layer
0,0,0,0,0,0,0,0,0,0,0,0,0,0,0,0,0,0,0,0,0,0,0,0,0,0,0,0,0,0
0,0,0,0,0,0,0,0,0,0,0,0,0,0,0,0,0,0,0,0,0,0,0,0,0,0,0,0,0,0
0,0,0,0,0,0,0,0,0,0,0,0,0,0,0,0,0,0,0,0,0,0,0,0,0,0,0,0,0,0
0,0,0,0,0,0,0,0,0,0,0,0,0,0,0,0,0,0,0,0,0,0,0,0,0,0,0,0,0,0
0,0,0,0,0,0,0,0,0,0,0,0,0,0,0,0,0,0,0,0,0,0,0,0,0,0,0,0,0,0
0,0,0,0,0,0,0,0,0,0,0,0,0,0,0,0,0,0,0,0,0,0,0,0,0,0,0,0,0,0
69,77,77,77,77,77,77,77,77,77,77,77,77,77,77,77,77,77,77,77,77,77,77,77,77,77,77,77,77,69
70,84,84,84,4,84,84,84,4,84,84,84,4,84,84,84,84,4,84,84,84,4,84,84,84,4,84,84,84,64
75,60,60,60,60,60,60,60,60,60,60,60,60,60,60,60,60,60,60,60,60,60,60,60,60,60,60,60,60,75
0,0,0,0,0,0,0,0,0,0,0,0,0,0,0,0,0,0,0,0,0,0,0,0,0,0,0,0,0,0
0,0,0,0,0,0,0,0,0,0,0,0,0,0,0,0,0,0,0,0,0,0,0,0,0,0,0,0,0,0
0,0,0,0,0,0,0,0,0,0,0,0,0,0,0,0,0,0,0,0,0,0,0,0,0,0,0,0,0,0
0,0,0,0,0,0,0,0,0,0,0,0,0,0,0,0,0,0,0,0,0,0,0,0,0,0,0,0,0,0
0,0,0,0,0,0,0,0,0,0,0,0,0,0,0,0,0,0,0,0,0,0,0,0,0,0,0,0,0,0
0,0,0,0,0,0,0,0,0,0,0,0,0,0,0,0,0,0,0,0,0,0,0,0,0,0,0,0,0,0
endlayer

layer
0,0,0,0,0,0,0,0,0,0,0,0,0,0,0,0,0,0,0,0,0,0,0,0,0,0,0,0,0,0
0,0,0,0,0,0,0,0,0,0,0,0,0,0,0,0,0,0,0,0,0,0,0,0,0,0,0,0,0,0
0,0,0,0,0,0,0,0,0,0,0,0,0,0,0,0,0,0,0,0,0,0,0,0,0,0,0,0,0,0
0,0,0,0,0,0,0,0,0,0,0,0,0,0,0,0,0,0,0,0,0,0,0,0,0,0,0,0,0,0
0,0,0,0,0,0,0,0,0,0,0,0,0,0,0,0,0,0,0,0,0,0,0,0,0,0,0,0,0,0
0,0,0,0,0,0,0,0,0,0,0,0,0,0,0,0,0,0,0,0,0,0,0,0,0,0,0,0,0,0
0,0,0,0,0,0,0,0,0,0,0,0,0,0,0,0,0,0,0,0,0,0,0,0,0,0,0,0,0,0
76,76,76,76,76,76,76,76,76,76,76,76,76,76,76,76,76,76,76,76,76,76,76,76,76,76,76,76,76,76
0,0,0,0,0,0,0,0,0,0,0,0,0,0,0,0,0,0,0,0,0,0,0,0,0,0,0,0,0,0
0,0,0,0,0,0,0,0,0,0,0,0,0,0,0,0,0,0,0,0,0,0,0,0,0,0,0,0,0,0
0,0,0,0,0,0,0,0,0,0,0,0,0,0,0,0,0,0,0,0,0,0,0,0,0,0,0,0,0,0
0,0,0,0,0,0,0,0,0,0,0,0,0,0,0,0,0,0,0,0,0,0,0,0,0,0,0,0,0,0
0,0,0,0,0,0,0,0,0,0,0,0,0,0,0,0,0,0,0,0,0,0,0,0,0,0,0,0,0,0
0,0,0,0,0,0,0,0,0,0,0,0,0,0,0,0,0,0,0,0,0,0,0,0,0,0,0,0,0,0
0,0,0,0,0,0,0,0,0,0,0,0,0,0,0,0,0,0,0,0,0,0,0,0,0,0,0,0,0,0
endlayer

