
# Created by Ruins mod version 17.1 Ingame Parser
# authoring Player: Nemsun

# criterion expression specifying mod ids required to load template
# may include plus (AND), minus (AND NOT), comma (OR), and parentheses
# all required mods listed must be present; no prohibited mods can be
requiredMods=
# likelihood this template will be chosen relative to all others
# e.g., a weight=6 template is chosen 3X as often as one with weight=2
weight=1
# list of other biomes in which this template may spawn
# biome corresponding to directory is always assumed, listed or not
# generic templates should leave this list empty
biomesToSpawnIn=
# criterion expression specifying types of biome where template spawns
# this is in addition to those explicitly listed as biomesToSpawnIn
# generic templates should leave this list empty
biomeTypesToSpawnIn=
# list of biomes in which this template may not spawn
# takes precedence over biomeTypesToSpawnIn, but NOT biomesToSpawnIn
# should be empty if biomeTypesToSpawnIn is empty
biomesToNotSpawnIn=
# depth template is pushed down into the surface when built
# offset is min/max range of random additional bury depth
embed_into_distance=0
random_height_offset=0,0
# whitelist/blacklist of block types on which template may be built
# specify one, not both; leave the other empty (both empty = allow all)
acceptable_target_blocks=
unacceptable_target_blocks=flowing_water,water,flowing_lava,lava
# size of template (#layers, #rows per layer, #blocks per row)
dimensions=13,18,39
# max number of missing blocks allowed in surface beneath template
allowable_overhang=0
# depth/height limit affected by terrain leveling
# also maximum bumpiness tolerated in surface beneath template
max_leveling=2
# padding applied to all sides of template horizontal footprint
# expands area affected by terrain leveling (-1 = no leveling)
leveling_buffer=0
# do not rotate template randomly when built (1 = no rotation)
preventRotation=0
# treat water/lava blocks as air and protect them from rule0 (1 = yes)
preserve_water=0
preserve_lava=0
# minimum distance this template must have from instances of itself
uniqueMinDistance=0
# min/max distances this template can be from world spawn (0 = no limit)
# only applies to overworld--i.e., dimension 0
spawnMinDistance=0
spawnMaxDistance=0
# other template built nearby whenever this one is
# syntax: <name>;<relativeX>;<maxYdifference>;<relativeZ>[;<chance>]
# may be used more than once to specify multiple neighbors
adjoining_template=

rule1=0,100,minecraft:sandstone-0
rule2=0,100,minecraft:sand-0
rule3=0,100,minecraft:fence-0
rule4=0,100,minecraft:wooden_slab-9
rule5=0,100,minecraft:fence_gate-1
rule6=0,100,minecraft:sandstone_stairs-2
rule7=0,100,minecraft:planks-1
rule8=0,100,minecraft:lever-14
rule9=0,100,minecraft:rail-0
rule10=0,100,minecraft:rail-5
rule11=0,100,minecraft:golden_rail-8
rule12=0,100,minecraft:golden_rail-0
rule13=0,100,minecraft:crafting_table-0
rule14=0,100,minecraft:rail-1
rule15=0,100,minecraft:sandstone_stairs-0
rule16=0,100,minecraft:sandstone_stairs-3
rule17=0,100,minecraft:trapdoor-9
rule18=0,100,minecraft:rail-8
rule19=0,100,minecraft:lava-0
rule20=0,100,minecraft:anvil-0
rule21=0,100,minecraft:cauldron-0
rule22=0,100,minecraft:dispenser-3
rule23=1,100,minecraft:torch-5
rule24=0,100,minecraft:sandstone_stairs-1
rule25=0,100,minecraft:wooden_pressure_plate-0
rule26=0,100,minecraft:sandstone-2
rule27=0,100,contenttweaker:nb7-0
rule28=0,100,minecraft:rail-9
rule29=0,100,minecraft:lever-6
rule30=0,100,ChestGenHook:chests/simple_dungeon:5-5
rule31=0,100,minecraft:spruce_stairs-4
rule32=0,100,minecraft:glass-0
rule33=0,100,minecraft:spruce_stairs-6
rule34=0,100,minecraft:golden_rail-12
rule35=2,100,minecraft:stone_button-3
rule36=0,100,minecraft:fence_gate-2
rule37=0,100,minecraft:spruce_stairs-5
rule38=2,100,minecraft:wooden_button-1
rule39=0,100,minecraft:rail-7
rule40=0,100,minecraft:wooden_slab-1
rule41=0,100,minecraft:fence_gate-3
rule42=0,100,minecraft:spruce_stairs-7
rule43=0,100,minecraft:emerald_block-0
rule44=0,100,minecraft:iron_bars-0
rule45=2,100,minecraft:torch-4
rule46=0,100,minecraft:double_wooden_slab-1
rule47=2,100,WallSign:Deliver to:NemGo:Desert Traders:null-4
rule48=0,100,minecraft:sandstone_stairs-4
rule49=2,100,minecraft:wooden_button-2
rule50=2,100,minecraft:torch-3
rule51=2,100,minecraft:wooden_button-4
rule52=2,100,minecraft:wooden_button-3
rule53=2,100,minecraft:torch-1
rule54=0,100,minecraft:sandstone_stairs-7
rule55=0,100,minecraft:lever-1
rule56=0,100,minecraft:sticky_piston-0
rule57=2,100,minecraft:torch-2
rule58=0,100,minecraft:sandstone_stairs-6
rule59=0,100,minecraft:lever-9
rule60=0,100,minecraft:sandstone_stairs-5
rule61=0,100,minecraft:trapdoor-2
rule62=1,100,minecraft:redstone_torch-5
rule63=0,100,minecraft:trapdoor-4
rule64=0,100,minecraft:rail-4
rule65=0,100,minecraft:wooden_door-2
rule66=0,100,minecraft:log-0
rule67=0,100,minecraft:wooden_door-0
rule68=0,100,minecraft:wooden_door-9
rule69=0,100,minecraft:wooden_door-8
rule70=0,100,minecraft:spruce_stairs-2
rule71=0,100,minecraft:spruce_stairs-0
rule72=0,100,minecraft:spruce_stairs-3
rule73=0,100,minecraft:spruce_stairs-1

layer
1,1,1,1,1,1,1,1,1,1,1,1,1,1,1,1,1,1,1,1,1,1,1,1,1,1,1,1,1,1,1,1,1,1,1,1,1,1,1
1,1,1,1,1,1,1,1,1,1,1,1,1,1,1,1,1,1,1,1,1,1,1,1,1,1,1,1,1,1,1,1,1,1,1,1,1,1,1
1,1,1,1,1,1,1,1,1,1,1,1,1,1,1,1,1,1,1,1,1,1,1,1,1,1,1,1,1,1,1,1,1,1,1,1,1,1,1
1,1,1,1,1,1,1,1,1,1,1,1,1,1,1,1,1,1,1,1,1,1,1,1,1,1,1,1,1,1,1,1,1,1,1,1,1,1,1
1,1,1,1,1,1,1,1,1,1,1,1,1,1,1,1,1,1,1,1,1,1,1,1,1,1,1,1,1,1,1,1,1,1,1,1,1,1,1
1,1,1,1,1,1,1,1,1,1,1,1,1,1,1,1,1,1,1,1,1,1,1,1,1,1,1,1,1,1,1,1,1,1,1,1,1,1,1
1,1,1,1,1,1,1,1,1,1,1,1,1,1,1,1,1,1,1,1,1,1,1,1,1,1,1,1,1,1,1,1,1,1,1,1,1,1,1
1,1,1,1,1,1,1,1,1,1,1,1,1,1,1,1,1,1,1,1,1,1,1,1,1,1,1,1,1,1,1,1,1,1,1,1,1,1,1
1,1,1,1,1,1,1,1,1,1,1,1,1,1,1,1,1,1,1,1,1,1,1,1,1,1,1,1,1,1,1,1,1,1,1,1,1,1,1
1,1,1,1,1,1,1,1,1,1,1,1,1,1,1,1,1,1,1,1,1,1,1,1,1,1,1,1,1,1,1,1,1,1,1,1,1,1,1
1,1,1,1,1,1,1,1,1,1,1,1,1,1,1,1,1,1,1,1,1,1,1,1,1,1,1,1,1,1,1,1,1,1,1,1,1,1,1
1,1,1,1,1,1,1,1,1,1,1,1,1,1,1,1,1,1,1,1,1,1,1,1,1,1,1,1,1,1,1,1,1,1,1,1,1,1,1
1,1,1,1,1,1,1,1,1,1,1,1,1,1,1,1,1,1,1,1,1,1,1,1,1,1,1,1,1,1,1,1,1,1,1,1,1,1,1
1,1,1,1,1,1,1,1,1,1,1,1,1,1,1,1,1,1,1,1,1,1,1,1,1,1,1,1,1,1,1,1,1,1,1,1,1,1,1
1,1,1,1,1,1,1,1,1,1,1,1,1,1,1,1,1,1,1,1,1,1,1,1,1,1,1,1,1,1,1,1,1,1,1,1,1,1,1
1,1,1,1,1,1,1,1,1,1,1,1,1,1,1,1,1,1,1,1,1,1,1,1,1,1,1,1,1,1,1,1,1,1,1,1,1,1,1
1,1,1,1,1,1,1,1,1,1,1,1,1,1,1,1,1,1,1,1,1,1,1,1,1,1,1,1,1,1,1,1,1,1,1,1,1,1,1
1,1,1,1,1,1,1,1,1,1,1,1,1,1,1,1,1,1,1,1,1,1,1,1,1,1,1,1,1,1,1,1,1,1,1,1,1,1,1
endlayer

layer
2,2,2,2,2,2,2,2,2,2,2,2,2,2,2,2,2,2,2,2,2,2,2,2,2,2,2,2,2,2,2,2,2,2,2,2,2,2,2
2,2,2,2,2,2,2,2,2,2,2,2,2,2,2,2,2,2,2,2,2,2,2,2,2,2,2,2,2,2,2,2,2,2,2,2,2,2,2
2,2,2,2,2,2,2,2,2,2,2,2,2,2,2,2,2,2,2,2,2,2,2,2,2,2,2,2,2,2,2,2,2,2,2,2,2,2,2
2,2,2,2,2,2,2,2,2,2,2,2,2,2,2,2,2,2,2,2,2,2,2,2,2,2,2,2,2,2,2,2,2,2,2,2,2,2,2
2,2,2,2,2,2,2,2,2,2,2,2,2,2,2,2,2,2,2,2,2,2,2,2,2,2,2,2,2,2,2,2,2,2,2,2,2,2,2
2,2,2,2,2,2,2,2,2,2,2,2,2,2,2,2,2,2,2,2,2,2,2,2,2,2,2,2,2,2,2,2,2,2,2,2,2,2,2
2,2,2,2,2,2,2,2,2,2,2,2,2,2,2,2,2,2,2,2,2,2,2,2,2,2,2,2,2,2,2,2,2,2,2,2,2,2,2
2,2,2,2,2,2,2,2,2,2,2,2,2,2,2,2,2,2,2,2,2,2,2,2,2,2,2,2,2,2,2,2,2,2,2,2,2,2,2
2,2,2,2,2,2,2,2,2,2,2,2,2,2,2,2,2,2,2,2,2,2,2,2,2,2,2,2,2,2,2,2,2,2,2,2,2,2,2
2,2,2,2,2,2,2,2,2,2,2,2,2,2,2,2,2,2,2,2,2,2,2,2,2,2,2,2,2,2,2,2,2,2,2,2,2,2,2
2,2,2,2,2,2,2,2,2,2,2,2,2,2,2,2,2,2,2,2,2,2,2,2,2,2,2,2,2,2,2,2,2,2,2,2,2,2,2
2,2,2,2,2,2,2,2,2,2,2,2,2,2,2,2,2,2,2,2,2,2,2,2,2,2,2,2,2,2,2,2,2,2,2,2,2,2,2
2,2,2,2,2,2,2,2,2,2,2,2,2,2,2,2,2,2,2,2,2,2,2,2,2,2,2,2,2,2,2,2,2,2,2,2,2,2,2
2,2,2,2,2,2,2,2,2,2,2,2,2,2,2,2,2,2,2,2,2,2,2,2,2,2,2,2,2,2,2,2,2,2,2,2,2,2,2
2,2,2,2,2,2,2,2,2,2,2,2,2,2,2,2,2,2,2,2,2,2,2,2,2,2,2,2,2,2,2,2,2,2,2,2,2,2,2
2,2,2,2,2,2,2,2,2,2,2,2,2,2,2,2,2,2,2,2,2,2,2,2,2,2,2,2,2,2,2,2,2,2,2,2,2,2,2
2,2,2,2,2,2,2,2,2,2,2,2,2,2,2,2,2,2,2,2,2,2,2,2,2,2,2,2,2,2,2,2,2,2,2,2,2,2,2
2,2,2,2,2,2,2,2,2,2,2,2,2,2,2,2,2,2,2,2,2,2,2,2,2,2,2,2,2,2,2,2,2,2,2,2,2,2,2
endlayer

layer
0,0,0,0,0,0,0,0,0,0,0,0,0,0,0,0,3,3,3,3,3,3,3,3,3,3,3,3,3,3,3,3,3,3,3,0,0,0,0
0,0,1,4,4,4,1,3,3,3,3,3,3,3,3,3,3,0,0,0,0,0,0,0,0,0,0,0,0,0,0,0,0,0,3,3,0,0,0
0,0,4,1,1,1,0,0,0,0,0,0,3,3,3,3,3,0,0,0,0,0,0,0,0,0,0,0,0,0,0,0,0,0,0,3,3,0,0
1,4,1,1,1,1,1,0,0,0,1,0,3,0,3,0,3,0,0,0,0,0,0,0,0,0,0,0,0,0,0,0,0,0,0,0,3,3,0
4,1,1,7,7,7,6,0,0,0,0,0,3,5,3,5,3,0,1,4,4,4,1,4,4,4,1,4,4,4,1,4,4,4,1,0,0,3,3
4,1,1,7,7,7,10,9,9,9,9,9,0,0,0,0,0,0,4,1,1,1,7,1,1,1,8,1,1,1,8,1,1,1,4,0,0,0,3
4,1,1,7,7,7,6,0,0,16,15,6,0,0,0,14,1,4,1,13,7,12,9,9,11,11,11,9,9,9,11,11,1,1,1,4,1,0,3
1,1,1,7,7,7,1,21,20,16,19,6,0,0,0,18,9,9,9,9,9,0,17,7,7,7,7,7,7,7,7,1,0,0,1,1,4,0,3
4,1,1,7,7,7,6,0,0,16,24,6,23,0,0,0,16,1,7,7,7,7,17,7,7,7,7,7,7,7,7,1,0,0,22,1,4,0,3
4,1,1,7,7,7,6,0,0,0,0,0,0,0,0,0,16,1,1,7,7,7,17,7,7,7,7,7,7,7,7,7,1,1,1,1,4,0,3
4,1,1,7,7,7,6,0,0,0,0,0,0,0,0,0,1,4,1,7,7,7,7,7,7,7,7,7,7,7,7,7,7,7,7,7,1,0,3
1,1,1,7,7,7,1,15,15,15,1,0,0,0,0,0,0,0,4,1,1,1,7,1,1,1,7,7,7,7,7,7,7,7,7,1,4,0,3
4,1,1,7,7,7,7,7,7,7,6,0,0,0,0,0,0,0,1,4,4,4,1,4,4,4,1,7,7,7,7,7,7,7,7,1,4,0,3
4,1,1,7,7,7,7,7,7,7,6,0,0,0,0,0,0,0,0,0,0,0,0,0,0,0,4,1,1,1,7,7,7,7,7,1,4,0,3
4,1,1,7,7,7,7,7,7,7,6,0,0,0,0,0,0,0,0,0,0,0,0,0,0,0,2,4,4,4,1,1,1,1,1,4,1,0,3
1,4,1,1,1,1,1,1,1,1,1,0,0,0,0,0,0,0,0,0,0,0,0,0,0,0,0,0,0,0,4,1,1,1,4,0,0,0,3
0,0,4,1,1,1,1,1,1,1,4,0,0,25,25,0,3,3,3,3,3,3,3,3,3,3,3,3,3,3,1,24,24,24,1,3,3,3,3
0,0,1,4,4,4,1,4,4,4,1,3,3,5,5,3,3,0,0,0,0,0,0,0,0,0,0,0,0,0,0,0,0,0,0,0,0,0,0
endlayer

layer
0,0,0,0,0,0,0,0,0,0,0,0,0,0,0,0,23,0,23,0,0,0,23,0,0,0,23,0,0,0,23,0,0,0,23,0,0,0,0
0,0,26,0,0,0,26,0,0,3,0,0,3,0,3,0,3,0,0,0,0,0,0,0,0,0,0,0,0,0,0,0,0,0,0,0,0,0,0
0,0,0,2,15,2,0,0,0,0,0,0,0,0,0,0,0,0,0,0,0,0,0,0,0,0,0,0,0,0,0,0,0,0,0,0,23,0,0
26,0,26,27,20,0,26,0,0,0,26,0,0,0,0,0,0,0,0,0,0,0,0,0,0,0,0,0,0,0,0,0,0,0,0,0,0,0,0
0,2,27,0,0,0,0,0,0,0,0,0,0,0,0,0,0,0,26,0,0,0,26,0,0,0,26,0,0,0,26,0,0,0,26,0,0,0,23
0,16,0,0,28,9,0,0,0,0,0,0,0,0,0,0,0,0,3,2,15,2,7,2,15,2,7,2,15,2,7,2,15,2,0,0,0,0,0
3,2,31,0,14,0,0,0,0,0,0,0,0,0,0,0,26,3,26,30,29,0,0,0,0,0,0,0,0,0,0,0,26,26,26,0,26,0,23
26,0,33,0,14,0,26,0,0,0,0,0,0,0,0,0,0,0,0,0,0,0,0,0,26,7,26,7,26,0,0,32,0,0,26,2,0,0,0
3,2,37,0,14,0,0,0,0,0,0,0,0,0,0,0,0,0,36,25,0,0,0,35,7,12,9,34,7,26,0,32,0,0,26,6,0,0,0
0,16,20,0,14,0,0,0,0,0,0,0,0,0,0,0,0,0,2,0,0,0,0,0,26,7,26,7,26,0,0,32,32,32,38,2,0,0,0
3,2,31,0,14,0,0,0,0,0,0,0,0,0,0,0,26,3,26,0,0,0,0,0,0,0,0,0,0,0,0,0,0,0,0,7,26,0,23
26,0,33,9,39,0,26,0,0,0,26,0,0,0,0,0,0,0,3,2,24,2,7,2,24,2,7,0,0,0,0,0,0,0,0,2,0,0,0
3,2,37,0,0,0,0,0,0,0,0,0,0,0,0,0,0,0,26,0,0,0,26,0,0,0,26,7,7,7,40,0,25,0,0,6,0,0,0
0,16,0,0,0,0,0,0,0,0,0,0,0,0,0,0,0,0,0,0,0,0,0,0,0,0,3,2,24,2,7,26,41,26,7,2,0,0,0
0,2,27,0,0,0,0,0,0,0,0,0,0,0,0,0,0,0,0,0,0,0,0,0,0,0,26,0,0,0,26,0,0,0,26,3,26,0,23
26,0,26,27,0,42,4,33,27,27,26,0,0,0,0,0,0,0,0,0,0,0,0,0,0,0,0,0,0,0,3,0,0,0,3,0,0,0,0
0,0,0,2,24,2,0,2,24,2,0,0,0,0,0,0,0,0,23,0,0,0,23,0,0,0,23,0,0,0,26,0,0,0,26,0,23,0,23
0,0,26,0,0,3,26,3,0,0,26,23,3,0,0,3,23,0,0,0,0,0,0,0,0,0,0,0,0,0,0,0,0,0,0,0,0,0,0
endlayer

layer
0,0,0,0,0,0,0,0,0,0,0,0,0,0,0,0,0,0,0,0,0,0,0,0,0,0,0,0,0,0,0,0,0,0,0,0,0,0,0
0,0,2,0,0,0,2,0,0,3,0,0,3,0,3,0,3,0,0,0,0,0,0,0,0,0,0,0,0,0,0,0,0,0,0,0,0,0,0
0,0,0,2,3,2,0,0,0,0,0,0,0,0,0,0,0,0,0,0,0,0,0,0,0,0,0,0,0,0,0,0,0,0,0,0,0,0,0
2,0,2,27,0,0,2,0,0,0,2,0,0,0,0,0,0,0,0,0,0,0,0,0,0,0,0,0,0,0,0,0,0,0,0,0,0,0,0
0,2,0,0,0,0,0,0,0,0,0,0,0,0,0,0,0,0,2,0,0,0,2,0,0,0,2,0,0,0,2,0,0,0,2,0,0,0,0
0,3,0,0,0,0,0,0,0,0,0,0,0,0,0,0,0,0,3,2,3,2,7,2,3,2,7,2,3,2,7,2,3,2,0,0,0,0,0
3,2,0,0,0,0,0,0,0,0,0,0,0,0,0,0,2,0,2,0,0,43,0,0,0,0,0,0,0,0,0,0,32,26,2,0,2,0,0
2,0,0,0,0,0,2,0,0,0,44,0,0,0,0,0,0,0,0,0,0,0,0,0,32,32,32,32,32,0,0,32,32,32,26,2,0,0,0
3,2,0,0,0,0,0,0,0,0,0,0,0,0,0,0,0,0,0,0,0,0,0,0,32,0,0,0,34,26,0,32,32,32,0,3,0,0,0
0,3,0,0,0,0,0,0,0,0,0,0,0,0,0,0,0,0,2,45,0,0,0,0,32,32,32,32,32,0,0,32,32,32,0,2,0,0,0
3,2,0,0,0,0,0,0,0,0,0,0,0,0,0,0,2,0,2,0,0,0,0,0,0,0,0,0,0,0,0,0,0,0,0,7,2,0,0
2,0,0,0,0,0,2,0,0,0,2,0,0,0,0,0,0,0,3,2,3,2,7,2,3,2,7,45,0,0,0,0,0,0,0,2,0,0,0
3,2,0,0,0,0,0,0,0,0,0,0,0,0,0,0,0,0,2,0,0,0,2,0,0,0,2,46,40,0,0,0,0,0,0,3,0,0,0
0,0,0,0,0,0,0,0,0,0,0,0,0,0,0,0,0,0,0,0,0,0,0,0,0,0,3,2,3,2,7,26,0,26,7,2,0,0,0
0,2,27,0,0,0,0,0,0,47,0,0,0,0,0,0,0,0,0,0,0,0,0,0,0,0,2,0,0,0,2,0,0,0,2,3,2,0,0
2,0,2,0,0,0,0,0,0,27,2,0,0,0,0,0,0,0,0,0,0,0,0,0,0,0,0,0,0,0,3,0,0,0,3,0,0,0,0
0,0,0,2,3,2,0,2,3,2,0,0,0,0,0,0,0,0,0,0,0,0,0,0,0,0,0,0,0,0,3,0,0,0,3,0,0,0,0
0,0,2,0,0,3,2,3,0,0,2,0,3,0,0,3,0,0,0,0,0,0,0,0,0,0,0,0,0,0,0,0,0,0,0,0,0,0,0
endlayer

layer
0,0,0,0,0,0,4,4,4,4,4,4,4,4,4,4,4,4,0,0,0,0,0,0,0,0,0,0,0,0,0,0,0,0,0,0,0,0,0
0,0,26,0,0,0,26,4,4,7,4,4,7,4,7,4,7,4,0,0,0,0,0,0,0,0,0,0,0,0,0,0,0,0,0,0,0,0,0
0,0,0,2,48,2,0,4,4,4,4,4,4,4,4,4,4,4,0,0,0,0,0,0,0,0,0,0,0,0,0,0,0,0,0,0,0,0,0
26,0,26,45,0,50,26,0,0,0,26,0,0,0,0,0,0,0,49,0,0,0,49,0,0,0,49,0,0,0,49,0,0,0,49,0,0,0,0
0,2,53,0,0,0,53,0,0,0,0,0,0,0,0,0,0,52,26,0,0,0,26,0,0,0,26,0,0,0,26,0,0,0,26,51,0,0,0
0,54,0,0,0,0,0,0,0,0,0,0,0,0,0,0,49,0,3,2,48,2,7,2,48,2,7,2,48,2,7,2,48,2,0,0,49,0,0
3,2,44,0,0,0,57,0,0,0,57,0,0,0,0,52,26,0,26,0,0,56,55,0,4,4,4,4,4,4,4,4,26,26,26,0,26,51,0
26,4,44,0,0,50,26,0,0,50,26,45,0,0,0,0,0,0,26,0,0,0,0,0,46,46,46,46,46,46,46,26,0,0,26,2,0,0,0
3,2,44,0,0,0,53,0,0,0,53,0,0,0,0,0,0,0,26,0,0,0,0,0,46,46,46,0,0,34,26,26,0,0,26,58,0,0,0
0,54,0,0,0,0,0,0,0,0,0,0,0,0,0,0,0,0,26,0,0,0,0,0,46,46,46,46,46,46,59,46,26,26,53,2,0,0,0
3,2,44,0,0,0,57,0,0,0,0,0,0,0,0,52,26,0,26,0,0,0,0,0,4,4,4,4,4,4,4,4,4,4,4,7,26,51,0
26,4,44,0,0,50,26,0,0,0,26,0,0,0,0,0,38,0,3,2,60,2,7,2,60,2,7,40,4,4,4,4,4,4,4,2,0,0,0
3,2,44,0,0,0,53,0,0,0,0,0,0,0,0,0,0,52,26,0,0,0,26,0,0,0,26,0,0,0,0,4,4,4,4,58,0,0,0
0,54,0,0,0,0,0,0,0,0,0,0,0,0,0,0,0,0,38,0,0,0,38,0,0,0,3,2,60,2,7,26,48,26,7,2,0,0,0
0,2,57,0,0,0,0,0,0,0,0,0,0,0,0,0,0,0,0,0,0,0,0,0,0,0,26,0,0,0,26,26,26,26,26,3,26,51,0
26,0,26,45,0,0,0,0,0,50,26,0,0,0,0,0,0,0,0,0,0,0,0,0,0,0,38,0,0,0,7,0,0,0,7,0,38,0,0
0,0,0,2,60,2,57,2,60,2,4,4,4,4,4,4,4,0,0,0,0,0,0,0,0,0,0,0,0,0,23,0,0,0,23,0,0,0,0
0,0,26,0,0,3,26,3,0,0,26,0,7,0,0,7,4,0,0,0,0,0,0,0,0,0,0,0,0,0,0,0,0,0,0,0,0,0,0
endlayer

layer
0,0,0,0,0,0,0,0,0,0,0,0,0,0,0,0,0,0,0,0,0,0,0,0,0,0,0,0,0,0,0,0,0,0,0,0,0,0,0
0,0,40,40,40,40,40,40,40,40,40,40,40,40,40,0,0,0,0,0,0,0,0,0,0,0,0,0,0,0,0,0,0,0,0,0,0,0,0
0,0,40,40,40,40,40,0,0,0,23,0,0,0,23,0,0,0,0,0,0,0,0,0,0,0,0,0,0,0,0,0,0,0,0,0,0,0,0
40,40,40,40,40,40,1,48,48,48,1,0,0,0,0,0,0,0,0,0,0,0,0,0,0,0,0,0,0,0,0,0,0,0,0,0,0,0,0
40,40,40,40,40,40,54,0,0,0,58,0,0,0,0,0,0,0,1,48,48,48,1,48,48,48,1,48,48,48,1,48,48,48,1,0,0,0,0
40,40,40,40,40,40,54,0,0,0,58,0,0,0,0,0,0,0,54,40,40,40,40,40,40,40,40,40,40,40,40,40,40,40,58,0,0,0,0
40,40,40,40,40,40,54,0,0,0,58,0,0,0,0,0,1,48,1,40,40,40,40,40,0,0,0,0,0,0,1,46,46,46,1,48,1,0,0
40,40,40,40,40,40,1,0,0,0,1,0,0,0,0,0,54,40,40,40,40,40,40,40,0,0,0,0,0,26,0,57,0,0,0,1,58,0,0
40,40,40,40,40,40,54,0,0,0,58,0,0,0,0,0,54,40,40,40,40,40,40,40,23,0,0,0,0,0,34,26,0,0,26,1,58,0,0
40,40,40,40,40,40,54,0,0,0,58,0,0,0,0,0,54,40,40,40,40,40,40,40,0,0,0,0,0,0,40,53,0,0,55,46,58,0,0
40,40,40,40,40,40,54,0,0,0,58,0,0,0,0,0,1,60,1,40,40,40,40,40,0,0,0,0,0,0,0,0,0,0,0,46,1,0,0
40,40,40,40,40,40,1,60,60,60,1,0,0,0,0,0,0,0,54,40,40,40,40,40,40,40,0,0,0,0,0,0,0,0,0,46,58,0,0
40,40,40,40,40,40,40,40,40,40,58,0,0,0,0,0,0,0,1,60,60,60,1,60,60,60,1,0,0,0,0,0,0,0,0,46,58,0,0
40,40,40,40,40,40,40,40,40,40,58,0,0,0,0,0,0,0,0,0,0,0,0,0,0,0,54,46,46,26,46,40,40,40,46,46,58,0,0
40,40,40,40,40,40,40,40,40,40,58,0,0,0,0,0,0,0,0,0,0,0,0,0,0,0,1,60,60,60,1,37,46,37,1,60,1,0,0
40,40,40,40,40,40,40,40,40,40,1,0,0,0,0,0,0,0,0,0,0,0,0,0,0,0,0,0,0,0,0,40,40,40,0,0,0,0,0
0,0,40,40,40,40,40,40,40,40,40,0,0,23,0,0,0,0,0,0,0,0,0,0,0,0,0,0,0,0,0,0,0,0,0,0,0,0,0
0,0,40,40,40,40,40,40,40,40,40,40,40,40,40,0,0,0,0,0,0,0,0,0,0,0,0,0,0,0,0,0,0,0,0,0,0,0,0
endlayer

layer
0,0,0,0,0,0,0,0,0,0,0,0,0,0,0,0,0,0,0,0,0,0,0,0,0,0,0,0,0,0,0,0,0,0,0,0,0,0,0
0,0,0,0,0,0,0,0,0,0,0,0,0,0,0,0,0,0,0,0,0,0,0,0,0,0,0,0,0,0,0,0,0,0,0,0,0,0,0
0,0,0,0,0,0,0,0,0,0,0,0,0,0,0,0,0,0,0,0,0,0,0,0,0,0,0,0,0,0,0,0,0,0,0,0,0,0,0
0,0,0,0,0,0,23,0,0,23,0,0,0,0,0,0,0,0,0,0,0,0,0,0,0,0,0,0,0,0,0,0,0,0,0,0,0,0,0
0,0,0,0,0,0,0,0,0,0,0,0,0,0,0,0,0,0,40,40,40,40,40,40,40,40,40,40,40,40,40,40,40,40,40,0,0,0,0
0,0,0,0,0,0,0,0,0,0,0,0,0,0,0,0,0,0,40,0,0,0,0,0,0,0,0,0,0,0,0,0,0,0,40,0,0,0,0
0,0,0,0,0,0,0,0,0,0,0,0,0,0,0,0,40,40,40,0,0,0,0,0,0,0,0,0,0,0,1,31,1,31,1,40,0,0,0
0,0,0,0,0,0,0,0,0,0,0,0,0,0,0,0,40,0,0,0,0,0,0,0,0,0,0,0,0,26,0,0,61,0,50,1,40,0,0
0,0,0,0,0,0,0,0,0,0,0,0,0,0,0,0,40,0,0,0,0,0,0,0,0,0,0,0,0,0,0,64,26,63,62,1,40,0,0
0,0,0,0,0,0,0,0,0,0,0,0,0,0,0,0,40,0,0,0,0,0,0,0,0,0,0,0,0,0,0,0,0,0,37,1,40,0,0
0,0,0,0,0,0,0,0,0,0,0,0,0,0,0,0,40,40,40,0,0,0,0,0,0,0,0,0,0,0,0,0,0,0,0,1,40,0,0
0,0,0,0,0,0,23,0,0,23,0,0,0,0,0,0,0,0,40,0,0,0,0,0,0,0,0,0,0,0,0,0,0,0,0,1,40,0,0
0,0,0,0,0,0,0,0,0,0,0,0,0,0,0,0,0,0,40,40,40,40,40,40,40,40,40,0,0,0,0,0,0,0,0,1,40,0,0
0,0,0,0,0,0,0,0,0,0,0,0,0,0,0,0,0,0,0,0,0,0,0,0,0,0,40,0,0,26,33,4,4,4,42,26,40,0,0
0,0,0,0,0,0,0,0,0,0,0,0,0,0,0,0,0,0,0,0,0,0,0,0,0,0,40,40,40,40,1,37,1,37,1,40,40,0,0
0,0,0,0,0,0,0,0,0,0,0,0,0,0,0,0,0,0,0,0,0,0,0,0,0,0,0,0,0,0,0,0,0,0,0,0,0,0,0
0,0,0,0,0,0,0,0,0,0,0,0,0,0,0,0,0,0,0,0,0,0,0,0,0,0,0,0,0,0,0,0,0,0,0,0,0,0,0
0,0,0,0,0,0,0,0,0,0,0,0,0,0,0,0,0,0,0,0,0,0,0,0,0,0,0,0,0,0,0,0,0,0,0,0,0,0,0
endlayer

layer
0,0,0,0,0,0,0,0,0,0,0,0,0,0,0,0,0,0,0,0,0,0,0,0,0,0,0,0,0,0,0,0,0,0,0,0,0,0,0
0,0,0,0,0,0,0,0,0,0,0,0,0,0,0,0,0,0,0,0,0,0,0,0,0,0,0,0,0,0,0,0,0,0,0,0,0,0,0
0,0,0,0,0,0,0,0,0,0,0,0,0,0,0,0,0,0,0,0,0,0,0,0,0,0,0,0,0,0,0,0,0,0,0,0,0,0,0
0,0,0,0,0,0,0,0,0,0,0,0,0,0,0,0,0,0,0,0,0,0,0,0,0,0,0,0,0,0,0,0,0,0,0,0,0,0,0
0,0,0,0,0,0,0,0,0,0,0,0,0,0,0,0,0,0,0,0,0,0,0,0,0,0,0,0,0,0,0,0,0,0,0,0,0,0,0
0,0,0,0,0,0,0,0,0,0,0,0,0,0,0,0,0,0,0,0,0,0,0,0,0,0,0,0,0,0,0,0,0,0,0,0,0,0,0
0,0,0,0,0,0,0,0,0,0,0,0,0,0,0,0,0,0,0,0,0,0,0,0,0,0,0,0,0,49,1,31,1,31,1,49,0,0,0
0,0,0,0,0,0,0,0,0,0,0,0,0,0,0,0,0,0,0,0,0,0,0,0,0,0,0,0,52,26,0,0,1,1,1,26,51,0,0
0,0,0,0,0,0,0,0,0,0,0,0,0,0,0,0,0,0,0,0,0,0,0,0,0,0,0,0,0,0,0,0,64,1,1,33,0,0,0
0,0,0,0,0,0,0,0,0,0,0,0,0,0,0,0,0,0,0,0,0,0,0,0,0,0,0,0,0,0,0,0,1,1,1,1,0,0,0
0,0,0,0,0,0,0,0,0,0,0,0,0,0,0,0,0,0,0,0,0,0,0,0,0,0,0,0,0,0,0,0,0,0,0,43,3,0,0
0,0,0,0,0,0,0,0,0,0,0,0,0,0,0,0,0,0,0,0,0,0,0,0,0,0,0,0,0,0,0,0,0,0,0,1,0,0,0
0,0,0,0,0,0,0,0,0,0,0,0,0,0,0,0,0,0,0,0,0,0,0,0,0,0,0,0,0,0,0,0,0,0,0,33,0,0,0
0,0,0,0,0,0,0,0,0,0,0,0,0,0,0,0,0,0,0,0,0,0,0,0,0,0,0,0,52,26,33,4,4,4,42,26,51,0,0
0,0,0,0,0,0,0,0,0,0,0,0,0,0,0,0,0,0,0,0,0,0,0,0,0,0,0,0,0,38,1,37,1,37,1,38,0,0,0
0,0,0,0,0,0,0,0,0,0,0,0,0,0,0,0,0,0,0,0,0,0,0,0,0,0,0,0,0,0,0,0,0,0,0,0,0,0,0
0,0,0,0,0,0,0,0,0,0,0,0,0,0,0,0,0,0,0,0,0,0,0,0,0,0,0,0,0,0,0,0,0,0,0,0,0,0,0
0,0,0,0,0,0,0,0,0,0,0,0,0,0,0,0,0,0,0,0,0,0,0,0,0,0,0,0,0,0,0,0,0,0,0,0,0,0,0
endlayer

layer
0,0,0,0,0,0,0,0,0,0,0,0,0,0,0,0,0,0,0,0,0,0,0,0,0,0,0,0,0,0,0,0,0,0,0,0,0,0,0
0,0,0,0,0,0,0,0,0,0,0,0,0,0,0,0,0,0,0,0,0,0,0,0,0,0,0,0,0,0,0,0,0,0,0,0,0,0,0
0,0,0,0,0,0,0,0,0,0,0,0,0,0,0,0,0,0,0,0,0,0,0,0,0,0,0,0,0,0,0,0,0,0,0,0,0,0,0
0,0,0,0,0,0,0,0,0,0,0,0,0,0,0,0,0,0,0,0,0,0,0,0,0,0,0,0,0,0,0,0,0,0,0,0,0,0,0
0,0,0,0,0,0,0,0,0,0,0,0,0,0,0,0,0,0,0,0,0,0,0,0,0,0,0,0,0,0,0,0,0,0,0,0,0,0,0
0,0,0,0,0,0,0,0,0,0,0,0,0,0,0,0,0,0,0,0,0,0,0,0,0,0,0,0,0,0,0,0,0,0,0,0,0,0,0
0,0,0,0,0,0,0,0,0,0,0,0,0,0,0,0,0,0,0,0,0,0,0,0,0,0,0,0,0,49,1,31,1,31,1,49,0,0,0
0,0,0,0,0,0,0,0,0,0,0,0,0,0,0,0,0,0,0,0,0,0,0,0,0,0,0,0,52,26,0,0,65,65,65,26,51,0,0
0,0,0,0,0,0,0,0,0,0,0,0,0,0,0,0,0,0,0,0,0,0,0,0,0,0,0,0,0,0,0,0,0,9,11,66,0,0,0
0,0,0,0,0,0,0,0,0,0,0,0,0,0,0,0,0,0,0,0,0,0,0,0,0,0,0,0,0,0,0,0,67,67,67,1,0,0,0
0,0,0,0,0,0,0,0,0,0,0,0,0,0,0,0,0,0,0,0,0,0,0,0,0,0,0,0,0,0,0,0,0,0,0,43,3,0,0
0,0,0,0,0,0,0,0,0,0,0,0,0,0,0,0,0,0,0,0,0,0,0,0,0,0,0,0,0,0,0,0,0,0,0,1,0,0,0
0,0,0,0,0,0,0,0,0,0,0,0,0,0,0,0,0,0,0,0,0,0,0,0,0,0,0,0,0,0,0,0,0,0,0,66,0,0,0
0,0,0,0,0,0,0,0,0,0,0,0,0,0,0,0,0,0,0,0,0,0,0,0,0,0,0,0,52,26,0,0,0,0,0,26,51,0,0
0,0,0,0,0,0,0,0,0,0,0,0,0,0,0,0,0,0,0,0,0,0,0,0,0,0,0,0,0,38,1,37,1,37,1,38,0,0,0
0,0,0,0,0,0,0,0,0,0,0,0,0,0,0,0,0,0,0,0,0,0,0,0,0,0,0,0,0,0,0,0,0,0,0,0,0,0,0
0,0,0,0,0,0,0,0,0,0,0,0,0,0,0,0,0,0,0,0,0,0,0,0,0,0,0,0,0,0,0,0,0,0,0,0,0,0,0
0,0,0,0,0,0,0,0,0,0,0,0,0,0,0,0,0,0,0,0,0,0,0,0,0,0,0,0,0,0,0,0,0,0,0,0,0,0,0
endlayer

layer
0,0,0,0,0,0,0,0,0,0,0,0,0,0,0,0,0,0,0,0,0,0,0,0,0,0,0,0,0,0,0,0,0,0,0,0,0,0,0
0,0,0,0,0,0,0,0,0,0,0,0,0,0,0,0,0,0,0,0,0,0,0,0,0,0,0,0,0,0,0,0,0,0,0,0,0,0,0
0,0,0,0,0,0,0,0,0,0,0,0,0,0,0,0,0,0,0,0,0,0,0,0,0,0,0,0,0,0,0,0,0,0,0,0,0,0,0
0,0,0,0,0,0,0,0,0,0,0,0,0,0,0,0,0,0,0,0,0,0,0,0,0,0,0,0,0,0,0,0,0,0,0,0,0,0,0
0,0,0,0,0,0,0,0,0,0,0,0,0,0,0,0,0,0,0,0,0,0,0,0,0,0,0,0,0,0,0,0,0,0,0,0,0,0,0
0,0,0,0,0,0,0,0,0,0,0,0,0,0,0,0,0,0,0,0,0,0,0,0,0,0,0,0,0,0,0,0,0,0,0,0,0,0,0
0,0,0,0,0,0,0,0,0,0,0,0,0,0,0,0,0,0,0,0,0,0,0,0,0,0,0,0,0,49,1,31,1,31,1,49,0,0,0
0,0,0,0,0,0,0,0,0,0,0,0,0,0,0,0,0,0,0,0,0,0,0,0,0,0,0,0,52,26,0,0,69,69,68,26,51,0,0
0,0,0,0,0,0,0,0,0,0,0,0,0,0,0,0,0,0,0,0,0,0,0,0,0,0,0,0,0,0,0,0,0,0,0,66,0,0,0
0,0,0,0,0,0,0,0,0,0,0,0,0,0,0,0,0,0,0,0,0,0,0,0,0,0,0,0,0,0,0,0,68,68,69,43,3,0,0
0,0,0,0,0,0,0,0,0,0,0,0,0,0,0,0,0,0,0,0,0,0,0,0,0,0,0,0,0,0,0,0,0,0,0,43,3,0,0
0,0,0,0,0,0,0,0,0,0,0,0,0,0,0,0,0,0,0,0,0,0,0,0,0,0,0,0,0,0,0,0,0,0,0,43,3,0,0
0,0,0,0,0,0,0,0,0,0,0,0,0,0,0,0,0,0,0,0,0,0,0,0,0,0,0,0,0,0,0,0,0,0,0,66,0,0,0
0,0,0,0,0,0,0,0,0,0,0,0,0,0,0,0,0,0,0,0,0,0,0,0,0,0,0,0,52,26,0,0,0,0,0,26,51,0,0
0,0,0,0,0,0,0,0,0,0,0,0,0,0,0,0,0,0,0,0,0,0,0,0,0,0,0,0,0,38,1,37,1,37,1,38,0,0,0
0,0,0,0,0,0,0,0,0,0,0,0,0,0,0,0,0,0,0,0,0,0,0,0,0,0,0,0,0,0,0,0,0,0,0,0,0,0,0
0,0,0,0,0,0,0,0,0,0,0,0,0,0,0,0,0,0,0,0,0,0,0,0,0,0,0,0,0,0,0,0,0,0,0,0,0,0,0
0,0,0,0,0,0,0,0,0,0,0,0,0,0,0,0,0,0,0,0,0,0,0,0,0,0,0,0,0,0,0,0,0,0,0,0,0,0,0
endlayer

layer
0,0,0,0,0,0,0,0,0,0,0,0,0,0,0,0,0,0,0,0,0,0,0,0,0,0,0,0,0,0,0,0,0,0,0,0,0,0,0
0,0,0,0,0,0,0,0,0,0,0,0,0,0,0,0,0,0,0,0,0,0,0,0,0,0,0,0,0,0,0,0,0,0,0,0,0,0,0
0,0,0,0,0,0,0,0,0,0,0,0,0,0,0,0,0,0,0,0,0,0,0,0,0,0,0,0,0,0,0,0,0,0,0,0,0,0,0
0,0,0,0,0,0,0,0,0,0,0,0,0,0,0,0,0,0,0,0,0,0,0,0,0,0,0,0,0,0,0,0,0,0,0,0,0,0,0
0,0,0,0,0,0,0,0,0,0,0,0,0,0,0,0,0,0,0,0,0,0,0,0,0,0,0,0,0,0,0,0,0,0,0,0,0,0,0
0,0,0,0,0,0,0,0,0,0,0,0,0,0,0,0,0,0,0,0,0,0,0,0,0,0,0,0,0,0,0,0,0,0,0,0,0,0,0
0,0,0,0,0,0,0,0,0,0,0,0,0,0,0,0,0,0,0,0,0,0,0,0,0,0,0,0,0,49,1,31,1,31,1,49,0,0,0
0,0,0,0,0,0,0,0,0,0,0,0,0,0,0,0,0,0,0,0,0,0,0,0,0,0,0,0,52,26,0,0,26,26,26,26,51,0,0
0,0,0,0,0,0,0,0,0,0,0,0,0,0,0,0,0,0,0,0,0,0,0,0,0,0,0,0,0,0,0,0,0,53,0,70,0,0,0
0,0,0,0,0,0,0,0,0,0,0,0,0,0,0,0,0,0,0,0,0,0,0,0,0,0,0,0,0,0,0,0,0,0,0,1,0,0,0
0,0,0,0,0,0,0,0,0,0,0,0,0,0,0,0,0,0,0,0,0,0,0,0,0,0,0,0,0,0,0,0,0,0,0,43,3,0,0
0,0,0,0,0,0,0,0,0,0,0,0,0,0,0,0,0,0,0,0,0,0,0,0,0,0,0,0,0,0,0,0,0,0,0,1,0,0,0
0,0,0,0,0,0,0,0,0,0,0,0,0,0,0,0,0,0,0,0,0,0,0,0,0,0,0,0,0,0,0,0,0,0,0,70,0,0,0
0,0,0,0,0,0,0,0,0,0,0,0,0,0,0,0,0,0,0,0,0,0,0,0,0,0,0,0,52,26,0,0,0,0,0,26,51,0,0
0,0,0,0,0,0,0,0,0,0,0,0,0,0,0,0,0,0,0,0,0,0,0,0,0,0,0,0,0,38,1,37,1,37,1,38,0,0,0
0,0,0,0,0,0,0,0,0,0,0,0,0,0,0,0,0,0,0,0,0,0,0,0,0,0,0,0,0,0,0,0,0,0,0,0,0,0,0
0,0,0,0,0,0,0,0,0,0,0,0,0,0,0,0,0,0,0,0,0,0,0,0,0,0,0,0,0,0,0,0,0,0,0,0,0,0,0
0,0,0,0,0,0,0,0,0,0,0,0,0,0,0,0,0,0,0,0,0,0,0,0,0,0,0,0,0,0,0,0,0,0,0,0,0,0,0
endlayer

layer
0,0,0,0,0,0,0,0,0,0,0,0,0,0,0,0,0,0,0,0,0,0,0,0,0,0,0,0,0,0,0,0,0,0,0,0,0,0,0
0,0,0,0,0,0,0,0,0,0,0,0,0,0,0,0,0,0,0,0,0,0,0,0,0,0,0,0,0,0,0,0,0,0,0,0,0,0,0
0,0,0,0,0,0,0,0,0,0,0,0,0,0,0,0,0,0,0,0,0,0,0,0,0,0,0,0,0,0,0,0,0,0,0,0,0,0,0
0,0,0,0,0,0,0,0,0,0,0,0,0,0,0,0,0,0,0,0,0,0,0,0,0,0,0,0,0,0,0,0,0,0,0,0,0,0,0
0,0,0,0,0,0,0,0,0,0,0,0,0,0,0,0,0,0,0,0,0,0,0,0,0,0,0,0,0,0,0,0,0,0,0,0,0,0,0
0,0,0,0,0,0,0,0,0,0,0,0,0,0,0,0,0,0,0,0,0,0,0,0,0,0,0,0,0,0,0,0,0,0,0,0,0,0,0
0,0,0,0,0,0,0,0,0,0,0,0,0,0,0,0,0,0,0,0,0,0,0,0,0,0,0,0,71,71,71,71,71,71,71,71,70,0,0
0,0,0,0,0,0,0,0,0,0,0,0,0,0,0,0,0,0,0,0,0,0,0,0,0,0,0,0,72,0,0,0,0,0,0,0,70,0,0
0,0,0,0,0,0,0,0,0,0,0,0,0,0,0,0,0,0,0,0,0,0,0,0,0,0,0,0,72,0,0,0,0,0,0,0,70,0,0
0,0,0,0,0,0,0,0,0,0,0,0,0,0,0,0,0,0,0,0,0,0,0,0,0,0,0,0,72,0,0,0,0,0,0,0,70,0,0
0,0,0,0,0,0,0,0,0,0,0,0,0,0,0,0,0,0,0,0,0,0,0,0,0,0,0,0,72,0,0,0,0,0,0,0,70,0,0
0,0,0,0,0,0,0,0,0,0,0,0,0,0,0,0,0,0,0,0,0,0,0,0,0,0,0,0,72,0,0,0,0,0,0,0,70,0,0
0,0,0,0,0,0,0,0,0,0,0,0,0,0,0,0,0,0,0,0,0,0,0,0,0,0,0,0,72,0,0,0,0,0,0,0,70,0,0
0,0,0,0,0,0,0,0,0,0,0,0,0,0,0,0,0,0,0,0,0,0,0,0,0,0,0,0,72,0,0,0,0,0,0,0,70,0,0
0,0,0,0,0,0,0,0,0,0,0,0,0,0,0,0,0,0,0,0,0,0,0,0,0,0,0,0,73,73,73,73,73,73,73,73,73,0,0
0,0,0,0,0,0,0,0,0,0,0,0,0,0,0,0,0,0,0,0,0,0,0,0,0,0,0,0,0,0,0,0,0,0,0,0,0,0,0
0,0,0,0,0,0,0,0,0,0,0,0,0,0,0,0,0,0,0,0,0,0,0,0,0,0,0,0,0,0,0,0,0,0,0,0,0,0,0
0,0,0,0,0,0,0,0,0,0,0,0,0,0,0,0,0,0,0,0,0,0,0,0,0,0,0,0,0,0,0,0,0,0,0,0,0,0,0
endlayer

