
# Created by Ruins mod version 17.1 Ingame Parser
# authoring Player: Nemsun

# criterion expression specifying mod ids required to load template
# may include plus (AND), minus (AND NOT), comma (OR), and parentheses
# all required mods listed must be present; no prohibited mods can be
requiredMods=
# likelihood this template will be chosen relative to all others
# e.g., a weight=6 template is chosen 3X as often as one with weight=2
weight=1
# list of other biomes in which this template may spawn
# biome corresponding to directory is always assumed, listed or not
# generic templates should leave this list empty
biomesToSpawnIn=
# criterion expression specifying types of biome where template spawns
# this is in addition to those explicitly listed as biomesToSpawnIn
# generic templates should leave this list empty
biomeTypesToSpawnIn=
# list of biomes in which this template may not spawn
# takes precedence over biomeTypesToSpawnIn, but NOT biomesToSpawnIn
# should be empty if biomeTypesToSpawnIn is empty
biomesToNotSpawnIn=
# depth template is pushed down into the surface when built
# offset is min/max range of random additional bury depth
embed_into_distance=0
random_height_offset=0,0
# whitelist/blacklist of block types on which template may be built
# specify one, not both; leave the other empty (both empty = allow all)
acceptable_target_blocks=
unacceptable_target_blocks=flowing_water,water,flowing_lava,lava
# size of template (#layers, #rows per layer, #blocks per row)
dimensions=24,27,24
# max number of missing blocks allowed in surface beneath template
allowable_overhang=0
# depth/height limit affected by terrain leveling
# also maximum bumpiness tolerated in surface beneath template
max_leveling=2
# padding applied to all sides of template horizontal footprint
# expands area affected by terrain leveling (-1 = no leveling)
leveling_buffer=3
# do not rotate template randomly when built (1 = no rotation)
preventRotation=0
# treat water/lava blocks as air and protect them from rule0 (1 = yes)
preserve_water=0
preserve_lava=0
# minimum distance this template must have from instances of itself
uniqueMinDistance=0
# min/max distances this template can be from world spawn (0 = no limit)
# only applies to overworld--i.e., dimension 0
spawnMinDistance=0
spawnMaxDistance=0
# other template built nearby whenever this one is
# syntax: <name>;<relativeX>;<maxYdifference>;<relativeZ>[;<chance>]
# may be used more than once to specify multiple neighbors
adjoining_template=

rule1=0,100,minecraft:ladder-4
rule2=0,100,minecraft:stone-0
rule3=0,100,minecraft:log-0
rule4=0,100,minecraft:stone_brick_stairs-4
rule5=0,100,minecraft:log-4
rule6=0,100,minecraft:planks-0
rule7=0,100,minecraft:stonebrick-0
rule8=0,100,minecraft:log-8
rule9=0,100,minecraft:trapdoor-11
rule10=0,100,minecraft:cobblestone-0
rule11=0,100,minecraft:grass-0
rule12=0,100,minecraft:dirt-0
rule13=0,100,minecraft:trapdoor-8
rule14=0,100,minecraft:farmland-7
rule15=0,100,minecraft:water-0
rule16=0,100,minecraft:wool-0
rule17=0,100,minecraft:fence-0
rule18=0,100,minecraft:planks-2
rule19=0,100,minecraft:crafting_table-0
rule20=0,100,minecraft:stone_brick_stairs-6
rule21=0,100,minecraft:stone_brick_stairs-7
rule22=0,100,minecraft:cobblestone_wall-0
rule23=0,100,minecraft:stone_brick_stairs-1
rule24=0,100,contenttweaker:nb6-0
rule25=0,100,minecraft:stone_brick_stairs-5
rule26=0,100,minecraft:wooden_door-2
rule27=0,100,minecraft:carrots-7
rule28=0,100,minecraft:sapling-9
rule29=0,100,minecraft:log-1
rule30=0,100,minecraft:melon_stem-7
rule31=0,100,minecraft:melon_block-0
rule32=0,100,minecraft:pumpkin_stem-7
rule33=0,100,minecraft:pumpkin-0
rule34=0,100,minecraft:furnace-5
rule35=2,100,minecraft:torch-3
rule36=0,100,ChestGenHook:chests/simple_dungeon:5-3
rule37=1,100,minecraft:torch-5
rule38=2,100,minecraft:torch-4
rule39=2,100,WallSign:Deliver to:NemGo:Worldwide:null-3
rule40=0,100,ChestGenHook:chests/simple_dungeon:5-2
rule41=0,100,minecraft:wooden_door-8
rule42=2,100,minecraft:torch-1
rule43=0,100,minecraft:leaves-4
rule44=0,100,minecraft:leaves-12
rule45=0,100,minecraft:wooden_slab-8
rule46=0,100,minecraft:stone_stairs-6
rule47=0,100,minecraft:oak_stairs-6
rule48=0,100,minecraft:oak_stairs-7
rule49=0,100,minecraft:stone_stairs-1
rule50=0,100,minecraft:stone_stairs-5
rule51=0,100,minecraft:stone_stairs-7
rule52=0,100,minecraft:leaves-5
rule53=0,100,minecraft:stone_stairs-3
rule54=0,100,minecraft:stone_stairs-0
rule55=0,100,minecraft:glass_pane-0
rule56=0,100,minecraft:oak_stairs-5
rule57=0,100,minecraft:stone_brick_stairs-0
rule58=0,100,minecraft:stone_stairs-2
rule59=2,100,minecraft:torch-2
rule60=0,100,minecraft:oak_stairs-1
rule61=0,100,minecraft:oak_stairs-3
rule62=0,100,minecraft:oak_stairs-2
rule63=0,100,minecraft:log-6
rule64=0,100,minecraft:stone_brick_stairs-2
rule65=0,100,minecraft:stone_brick_stairs-3
rule66=0,100,minecraft:anvil-0
rule67=0,100,minecraft:oak_stairs-4
rule68=0,100,minecraft:stone_slab-3

layer
0,0,0,0,0,0,0,0,0,0,0,0,0,0,0,0,0,0,0,0,0,0,0,0
0,0,0,0,0,0,0,0,0,0,0,0,0,0,0,0,0,0,0,0,0,0,0,0
0,0,0,0,0,0,0,0,0,0,0,0,0,0,0,0,0,0,0,0,0,0,0,0
0,0,0,0,0,0,0,0,0,0,0,0,0,0,0,0,0,0,0,0,0,0,0,0
0,0,0,0,0,0,0,0,0,0,0,0,0,0,0,0,0,0,0,0,0,0,0,0
0,0,0,0,0,0,0,0,0,0,0,0,0,0,0,0,0,0,0,0,0,0,0,0
0,0,0,0,0,0,0,0,0,0,0,0,0,0,0,0,0,0,0,0,0,0,0,0
0,0,0,0,0,0,0,0,0,0,0,0,0,0,0,0,0,0,0,0,0,0,0,0
0,0,0,0,0,0,0,0,0,0,0,0,0,0,0,0,0,0,0,0,0,0,0,0
0,0,0,0,0,0,0,0,0,0,0,0,0,0,0,0,0,0,0,0,0,0,0,0
0,0,0,0,0,0,0,0,0,1,0,0,0,0,0,0,0,0,0,0,0,0,0,0
0,0,2,2,2,2,2,2,2,2,2,2,2,2,2,2,2,2,0,0,0,0,0,0
0,0,2,2,2,2,2,2,2,2,2,2,2,2,2,2,2,2,0,0,0,0,0,0
0,0,2,2,2,2,2,2,2,2,2,2,2,2,2,2,2,2,0,0,0,0,0,0
0,0,2,2,2,2,2,2,2,2,2,2,2,2,2,2,2,2,0,0,0,0,0,0
0,0,2,2,2,2,2,2,2,2,2,2,2,2,2,2,2,2,0,0,0,0,0,0
0,0,2,2,2,2,2,2,2,2,2,2,2,2,2,2,2,2,0,0,0,0,0,0
0,0,2,2,2,2,2,2,2,2,2,2,2,2,2,2,2,2,0,0,0,0,0,0
0,0,2,2,2,2,2,2,2,2,2,2,2,2,2,2,2,2,0,0,0,0,0,0
0,0,2,2,2,2,2,2,2,2,2,2,2,2,2,2,2,2,0,0,0,0,0,0
0,0,2,2,2,2,2,2,2,2,2,2,2,2,2,2,2,2,0,0,0,0,0,0
0,0,2,2,2,2,2,2,2,2,2,2,2,2,2,2,2,2,0,0,0,0,0,0
0,0,2,2,2,2,2,2,2,2,2,2,2,2,2,2,2,2,0,0,0,0,0,0
0,0,2,2,2,2,2,2,2,2,2,2,2,2,2,2,2,2,0,0,0,0,0,0
0,0,2,2,2,2,2,2,2,2,2,2,2,2,2,2,2,2,0,0,0,0,0,0
0,0,2,2,2,2,2,2,2,2,2,2,2,2,2,2,2,2,0,0,0,0,0,0
0,0,2,2,2,2,2,2,2,2,2,2,2,2,2,2,2,2,0,0,0,0,0,0
endlayer

layer
0,0,0,0,0,0,0,0,0,0,0,0,0,0,0,0,0,0,0,0,0,0,0,0
0,0,0,0,0,0,0,0,0,0,0,0,0,0,0,0,0,0,0,0,0,0,0,0
0,0,0,0,0,0,0,0,0,0,0,0,0,0,0,0,0,0,0,0,0,0,0,0
0,0,0,0,0,0,0,0,0,0,0,0,0,0,0,0,0,0,0,0,0,0,0,0
0,0,0,0,0,0,0,0,0,0,0,0,0,0,0,0,0,0,0,0,0,0,0,0
0,0,0,0,0,0,0,0,0,0,0,0,0,0,0,0,0,0,0,0,0,0,0,0
0,0,0,0,0,0,0,0,0,0,0,0,0,0,0,0,0,0,0,0,0,0,0,0
0,0,0,0,0,0,0,0,0,0,0,0,0,0,0,0,0,0,0,0,0,0,0,0
0,0,0,0,0,0,0,0,0,0,0,0,0,0,0,0,0,0,0,0,0,0,0,0
0,0,0,0,0,0,0,0,0,0,0,0,0,0,0,0,0,0,0,0,0,0,0,0
0,0,0,0,0,0,0,0,0,1,0,0,0,0,0,0,0,0,0,0,0,0,0,0
0,0,2,2,2,2,2,2,2,2,2,2,2,2,2,2,2,2,0,0,0,0,0,0
0,0,2,2,2,2,2,2,2,2,2,2,2,2,2,2,2,2,0,0,0,0,0,0
0,0,2,2,2,2,2,2,2,2,2,2,2,2,2,2,2,2,0,0,0,0,0,0
0,0,2,2,2,2,2,2,2,2,2,2,2,2,2,2,2,2,0,0,0,0,0,0
0,0,2,2,2,2,2,2,2,2,2,2,2,2,2,2,2,2,0,0,0,0,0,0
0,0,2,2,2,2,2,2,2,2,2,2,2,2,2,2,2,2,0,0,0,0,0,0
0,0,2,2,2,2,2,2,2,2,2,2,2,2,2,2,2,2,0,0,0,0,0,0
0,0,2,2,2,2,2,2,2,2,2,2,2,2,2,2,2,2,0,0,0,0,0,0
0,0,2,2,2,2,2,2,2,2,2,2,2,2,2,2,2,2,0,0,0,0,0,0
0,0,2,2,2,2,2,2,2,2,2,2,2,2,2,2,2,2,0,0,0,0,0,0
0,0,2,2,2,2,2,2,2,2,2,2,2,2,2,2,2,2,0,0,0,0,0,0
0,0,2,2,2,2,2,2,2,2,2,2,2,2,2,2,2,2,0,0,0,0,0,0
0,0,2,2,2,2,2,2,2,2,2,2,2,2,2,2,2,2,0,0,0,0,0,0
0,0,2,2,2,2,2,2,2,2,2,2,2,2,2,2,2,2,0,0,0,0,0,0
0,0,2,2,2,2,2,2,2,2,2,2,2,2,2,2,2,2,0,0,0,0,0,0
0,0,2,2,2,2,2,2,2,2,2,2,2,2,2,2,2,2,0,0,0,0,0,0
endlayer

layer
0,0,0,0,0,0,0,0,0,0,0,0,0,0,0,0,0,0,0,0,0,0,0,0
0,0,0,0,0,0,0,0,0,0,0,0,0,0,0,0,0,0,0,0,0,0,0,0
0,0,0,0,0,0,0,0,0,0,0,0,0,0,0,0,0,0,0,0,0,0,0,0
0,0,0,0,0,0,0,0,0,0,0,0,0,0,0,0,0,0,0,0,0,0,0,0
0,0,0,0,0,0,0,0,0,0,0,0,0,0,0,0,0,0,0,0,0,0,0,0
0,0,0,0,0,0,0,0,0,0,0,0,0,0,0,0,0,0,0,0,0,0,0,0
0,0,0,0,0,0,0,0,0,0,0,0,0,0,0,0,0,0,0,0,0,0,0,0
0,0,0,0,0,0,0,0,0,0,0,0,0,0,0,0,0,0,0,0,0,0,0,0
0,0,0,0,0,0,0,0,0,0,0,0,0,0,0,0,0,0,0,0,0,0,0,0
0,0,0,0,0,0,0,0,0,0,0,0,0,0,0,0,0,0,0,0,0,0,0,0
0,0,0,0,0,0,0,0,0,1,0,0,0,0,0,0,0,0,0,0,0,0,0,0
0,0,2,2,2,2,2,2,2,2,2,2,2,2,2,2,2,2,0,0,0,0,0,0
0,0,2,2,2,2,2,2,2,2,2,2,2,2,2,2,2,2,0,0,0,0,0,0
0,0,2,2,2,2,2,2,2,2,2,2,2,2,2,2,2,2,0,0,0,0,0,0
0,0,2,2,2,2,2,2,2,2,2,2,2,2,2,2,2,2,0,0,0,0,0,0
0,0,2,2,2,2,2,2,2,2,2,2,2,2,2,2,2,2,0,0,0,0,0,0
0,0,2,2,2,2,2,2,2,2,2,2,2,2,2,2,2,2,0,0,0,0,0,0
0,0,2,2,2,2,2,2,2,2,2,2,2,2,2,2,2,2,0,0,0,0,0,0
0,0,2,2,2,2,2,2,2,2,2,2,2,2,2,2,2,2,0,0,0,0,0,0
0,0,2,2,2,2,2,2,2,2,2,2,2,2,2,2,2,2,0,0,0,0,0,0
0,0,2,2,2,2,2,2,2,2,2,2,2,2,2,2,2,2,0,0,0,0,0,0
0,0,2,2,2,2,2,2,2,2,2,2,2,2,2,2,2,2,0,0,0,0,0,0
0,0,2,2,2,2,2,2,2,2,2,2,2,2,2,2,2,2,0,0,0,0,0,0
0,0,2,2,2,2,2,2,2,2,2,2,2,2,2,2,2,2,0,0,0,0,0,0
0,0,2,2,2,2,2,2,2,2,2,2,2,2,2,2,2,2,0,0,0,0,0,0
0,0,2,2,2,2,2,2,2,2,2,2,2,2,2,2,2,2,0,0,0,0,0,0
0,0,2,2,2,2,2,2,2,2,2,2,2,2,2,2,2,2,0,0,0,0,0,0
endlayer

layer
0,0,0,0,0,0,0,0,0,0,0,0,0,0,0,0,0,0,0,0,0,0,0,0
0,0,0,0,0,0,0,0,0,0,0,0,0,0,0,0,0,0,0,0,0,0,0,0
0,0,0,0,0,0,0,0,0,0,0,0,0,0,0,0,0,0,0,0,0,0,0,0
0,0,0,0,0,0,0,0,0,0,0,0,0,0,0,0,0,0,0,0,0,0,0,0
0,0,0,0,0,0,0,0,0,0,0,0,0,0,0,0,0,0,0,0,0,0,0,0
0,0,0,0,0,0,0,0,0,0,0,0,0,0,0,0,0,0,0,0,0,0,0,0
0,0,0,0,0,0,0,0,0,0,0,0,0,0,0,0,0,0,0,0,0,0,0,0
0,0,0,0,0,0,0,0,0,0,0,0,0,0,0,0,0,0,0,0,0,0,0,0
0,0,0,0,0,0,0,0,0,0,0,0,0,0,0,0,0,0,0,0,0,0,0,0
0,0,0,0,0,0,0,0,0,0,0,0,0,0,0,0,0,0,0,0,0,0,0,0
0,0,0,0,0,0,0,0,0,1,0,0,0,0,0,0,0,0,0,0,0,0,0,0
0,0,2,2,2,2,2,2,2,2,2,2,2,2,2,2,2,2,0,0,0,0,0,0
0,0,2,2,2,2,2,2,2,2,2,2,2,2,2,2,2,2,0,0,0,0,0,0
0,0,2,2,2,2,2,2,2,2,2,2,2,2,2,2,2,2,0,0,0,0,0,0
0,0,2,2,2,2,2,2,2,2,2,2,2,2,2,2,2,2,0,0,0,0,0,0
0,0,2,2,2,2,2,2,2,2,2,2,2,2,2,2,2,2,0,0,0,0,0,0
0,0,2,2,2,2,2,2,2,2,2,2,2,2,2,2,2,2,0,0,0,0,0,0
0,0,2,2,2,2,2,2,2,2,2,2,2,2,2,2,2,2,0,0,0,0,0,0
0,0,2,2,2,2,2,2,2,2,2,2,2,2,2,2,2,2,0,0,0,0,0,0
0,0,2,2,2,2,2,2,2,2,2,2,2,2,2,2,2,2,0,0,0,0,0,0
0,0,2,2,2,2,2,2,2,2,2,2,2,2,2,2,2,2,0,0,0,0,0,0
0,0,2,2,2,2,2,2,2,2,2,2,2,2,2,2,2,2,0,0,0,0,0,0
0,0,2,2,2,2,2,2,2,2,2,2,2,2,2,2,2,2,0,0,0,0,0,0
0,0,2,2,2,2,2,2,2,2,2,2,2,2,2,2,2,2,0,0,0,0,0,0
0,0,2,2,2,2,2,2,2,2,2,2,2,2,2,2,2,2,0,0,0,0,0,0
0,0,2,2,2,2,2,2,2,2,2,2,2,2,2,2,2,2,0,0,0,0,0,0
0,0,2,2,2,2,2,2,2,2,2,2,2,2,2,2,2,2,0,0,0,0,0,0
endlayer

layer
0,0,0,0,0,0,0,0,0,0,0,0,0,0,0,0,0,0,0,0,0,0,0,0
0,0,0,0,0,0,0,0,0,0,0,0,0,0,0,0,0,0,0,0,0,0,0,0
0,0,0,0,0,0,0,0,0,0,0,0,0,0,0,0,0,0,0,0,0,0,0,0
0,0,0,0,0,0,0,0,0,0,0,0,0,0,0,0,0,0,0,0,0,0,0,0
0,0,0,0,0,0,0,0,0,0,0,0,0,0,0,0,0,0,0,0,0,0,0,0
0,0,0,0,0,0,0,0,0,0,0,0,0,0,0,0,0,0,0,0,0,0,0,0
0,0,0,0,0,0,0,0,0,0,0,0,0,0,0,0,0,0,0,0,0,0,0,0
0,0,0,0,0,0,3,0,0,0,0,0,3,0,0,0,0,0,0,0,0,0,0,0
0,0,0,0,0,4,3,4,5,6,5,4,3,4,0,0,0,0,0,0,0,0,0,0
0,0,0,0,0,7,8,7,5,6,5,7,2,7,0,0,0,0,0,0,0,0,0,0
0,0,0,0,0,7,10,7,5,9,5,7,2,7,0,0,0,0,0,0,0,0,0,0
0,0,10,10,10,10,10,7,5,6,5,7,10,10,10,10,10,10,0,0,0,0,0,0
0,0,10,11,11,12,12,7,5,6,5,7,10,12,11,11,11,10,0,0,0,0,0,0
0,0,10,11,11,12,12,7,5,6,5,7,12,12,11,11,11,10,0,0,0,0,0,0
0,0,10,11,11,12,12,7,5,6,5,7,12,12,11,11,11,10,0,0,0,0,0,0
0,0,10,11,11,12,12,12,12,6,12,0,12,12,11,11,11,10,0,0,0,0,0,0
0,0,10,11,14,11,11,11,11,11,11,11,11,13,11,11,11,10,0,0,0,0,0,0
0,0,10,11,14,14,11,11,11,11,11,11,11,11,11,11,11,10,0,0,0,0,0,0
0,0,10,11,14,14,14,11,11,11,11,11,11,11,11,11,11,10,0,0,0,0,0,0
0,0,10,12,14,14,14,14,11,11,11,11,11,11,11,12,11,10,0,0,0,0,0,0
0,0,10,11,15,14,14,14,11,11,11,11,11,11,11,11,11,10,0,0,0,0,0,0
0,0,10,11,14,14,14,14,11,11,11,11,12,11,11,11,11,10,0,0,0,0,0,0
0,0,10,11,14,14,14,11,11,11,11,11,11,11,11,11,11,10,0,0,0,0,0,0
0,0,10,11,14,11,11,11,11,11,11,12,11,11,12,11,11,10,0,0,0,0,0,0
0,0,10,12,14,11,11,11,11,11,11,11,11,11,11,11,11,10,0,0,0,0,0,0
0,0,10,11,11,11,11,11,11,11,11,11,11,11,11,11,11,10,0,0,0,0,0,0
0,0,10,10,10,10,10,10,10,10,10,10,10,10,10,10,10,10,0,0,0,0,0,0
endlayer

layer
0,0,0,0,0,0,0,0,0,0,0,0,18,17,17,16,0,0,0,0,0,0,0,0
0,0,0,0,0,0,0,0,0,0,0,0,0,0,0,0,0,0,0,0,0,0,0,0
0,0,0,0,0,0,0,0,0,0,0,0,0,0,0,0,0,0,0,0,0,0,0,0
0,0,0,0,0,0,0,0,0,0,0,0,0,0,0,0,0,0,0,0,0,0,0,0
0,0,0,0,0,0,0,0,0,0,0,0,0,0,0,0,0,0,0,0,0,0,0,0
0,0,0,0,0,0,0,0,0,0,0,0,0,0,0,0,0,0,0,0,0,0,0,0
0,0,0,0,0,0,5,0,0,0,0,0,5,0,0,0,0,0,0,0,0,0,0,0
0,0,0,0,0,4,5,4,7,7,7,4,5,4,0,0,0,0,0,0,0,0,0,0
0,0,0,0,0,7,7,19,0,0,0,0,7,7,0,0,0,0,0,0,0,0,0,0
0,0,0,0,0,21,7,7,0,0,0,0,7,20,0,0,0,0,0,0,0,0,0,0
0,0,0,0,0,21,7,7,0,0,0,0,7,20,0,0,0,0,0,0,0,0,0,0
0,0,10,22,22,7,7,23,0,0,0,0,7,7,22,22,22,10,0,0,0,0,0,0
0,0,22,0,0,7,7,0,0,0,0,24,7,7,0,0,0,22,0,0,0,0,0,0
0,0,22,0,0,7,7,0,0,0,0,24,7,7,0,0,0,22,0,0,0,0,0,0
0,0,22,0,0,7,7,0,0,0,0,24,7,7,0,0,0,22,0,0,0,0,0,0
0,0,22,0,0,25,7,7,7,26,7,7,7,25,0,0,0,22,0,0,0,0,0,0
0,0,22,0,27,0,0,0,0,0,0,0,0,0,0,0,0,22,0,0,0,0,0,0
0,0,22,0,27,27,0,0,0,0,0,0,0,0,0,28,0,22,0,0,0,0,0,0
0,0,22,0,27,27,27,0,0,0,0,0,0,0,0,0,0,22,0,0,0,0,0,0
0,0,22,31,30,27,27,27,0,0,0,0,0,0,0,29,0,22,0,0,0,0,0,0
0,0,22,0,0,27,27,27,0,0,0,0,0,0,0,0,0,22,0,0,0,0,0,0
0,0,22,0,27,27,27,27,0,0,0,0,3,0,0,0,0,22,0,0,0,0,0,0
0,0,22,0,27,27,27,0,0,0,0,0,0,0,0,0,0,22,0,0,0,0,0,0
0,0,22,0,27,0,0,0,0,0,0,3,0,0,3,0,0,22,0,0,0,0,0,0
0,0,22,33,32,0,0,0,0,0,0,0,0,0,0,0,0,22,0,0,0,0,0,0
0,0,22,0,0,0,0,0,0,0,0,0,0,0,0,0,0,22,0,0,0,0,0,0
0,0,10,22,22,22,22,22,22,22,22,22,22,22,22,22,22,10,0,0,0,0,0,0
endlayer

layer
0,0,0,0,0,0,0,0,0,0,0,0,18,17,17,16,0,0,0,0,0,0,0,0
0,0,0,0,0,0,0,0,0,0,0,0,0,0,0,0,0,0,0,0,0,0,0,0
0,0,0,0,0,0,0,0,0,0,0,0,0,0,0,0,0,0,0,0,0,0,0,0
0,0,0,0,0,0,0,0,0,0,0,0,0,0,0,0,0,0,0,0,0,0,0,0
0,0,0,0,0,0,0,0,0,0,0,0,0,0,0,0,0,0,0,0,0,0,0,0
0,0,0,0,0,0,0,0,0,0,0,0,0,0,0,0,0,0,0,0,0,0,0,0
0,0,0,0,0,10,10,10,10,10,10,10,10,10,0,0,0,0,0,0,0,0,0,0
0,0,0,0,0,22,7,34,34,34,34,34,7,22,0,0,0,0,0,0,0,0,0,0
0,0,0,0,0,22,7,0,0,0,0,0,7,22,22,22,0,0,0,0,0,0,0,0
0,0,0,0,0,22,7,4,0,0,0,35,7,22,0,0,0,0,0,0,0,0,0,0
0,0,0,0,0,22,7,23,0,0,0,0,36,22,0,0,0,0,0,0,0,0,0,0
0,0,22,0,0,22,7,0,0,0,0,0,36,22,0,0,0,37,0,0,0,0,0,0
0,0,0,0,0,22,7,38,0,0,0,35,7,22,22,22,0,0,0,0,0,0,0,0
0,0,0,0,0,22,40,0,0,0,39,24,7,22,0,0,0,0,0,0,0,0,0,0
0,0,0,0,0,22,40,0,0,0,0,0,7,22,0,0,0,0,0,0,0,0,0,0
0,0,0,0,0,10,22,22,6,41,6,22,22,10,0,0,0,0,0,0,0,0,0,0
0,0,37,0,0,0,0,0,0,0,42,0,0,0,0,0,0,37,0,0,0,0,0,0
0,0,0,0,0,0,0,0,0,0,0,0,0,0,0,0,0,0,0,0,0,0,0,0
0,0,0,0,0,0,0,0,0,0,0,0,0,0,0,0,0,0,0,0,0,0,0,0
0,0,0,0,0,0,0,0,0,0,0,43,43,43,0,29,0,0,0,0,0,0,0,0
0,0,0,0,0,0,0,0,0,0,43,43,43,43,0,0,0,0,0,0,0,0,0,0
0,0,37,0,0,0,0,0,0,43,43,43,3,43,43,0,0,37,0,0,0,0,0,0
0,0,0,0,0,0,0,0,0,43,43,43,43,43,43,0,0,0,0,0,0,0,0,0
0,0,0,0,0,0,0,0,0,43,43,3,43,43,3,0,0,0,0,0,0,0,0,0
0,0,0,0,0,0,0,0,0,44,44,43,43,43,0,0,0,0,0,0,0,0,0,0
0,0,0,0,0,0,0,0,0,43,44,43,43,43,0,0,0,0,0,0,0,0,0,0
0,0,37,0,0,0,0,0,0,0,0,0,37,0,0,0,0,37,0,0,0,0,0,0
endlayer

layer
0,0,0,0,0,0,0,0,0,0,0,18,17,17,16,0,0,0,0,0,0,0,0,0
0,0,0,0,0,0,0,0,0,0,0,0,0,0,0,0,0,0,0,0,0,0,0,0
0,0,0,0,0,0,0,0,0,0,0,0,0,0,0,0,0,0,0,0,0,0,0,0
0,0,0,0,0,0,0,0,0,0,0,0,0,0,0,0,0,0,0,0,0,0,0,0
0,0,0,0,0,0,0,0,0,0,0,0,0,0,0,0,0,0,0,0,0,0,0,0
0,0,0,0,5,0,0,0,0,0,0,0,0,0,5,0,0,0,0,0,0,0,0,0
0,0,0,0,5,22,3,22,3,22,3,22,3,22,5,0,0,0,0,0,0,0,0,0
0,0,0,0,5,10,45,6,6,6,6,6,6,10,5,0,0,0,0,0,0,0,0,0
0,0,0,0,5,10,45,6,6,6,6,6,47,10,5,10,46,0,0,0,0,0,0,0
0,0,0,0,5,10,6,23,6,6,6,6,6,10,5,0,0,0,0,0,0,0,0,0
0,0,0,0,5,10,48,0,6,6,6,6,47,10,5,0,0,0,0,0,0,0,0,0
0,0,37,0,5,10,48,0,6,6,6,6,47,10,5,0,0,0,0,0,0,0,0,0
0,0,0,0,5,10,6,0,6,6,6,6,6,10,5,10,46,0,0,0,0,0,0,0
0,0,0,0,5,10,48,6,6,6,6,6,47,10,5,0,0,0,0,0,0,0,0,0
0,0,0,0,5,10,48,6,6,6,6,6,47,10,5,0,0,0,0,0,0,0,0,0
0,0,0,0,5,3,49,3,6,6,6,3,49,3,5,0,0,0,0,0,0,0,0,0
0,0,0,0,0,0,0,51,50,50,50,46,0,0,0,0,0,0,0,0,0,0,0,0
0,0,0,0,0,0,0,0,0,0,0,0,0,0,52,52,52,0,0,0,0,0,0,0
0,0,0,0,0,0,0,0,0,0,0,0,0,52,52,52,52,52,0,0,0,0,0,0
0,0,0,0,0,0,0,0,0,0,43,43,43,43,52,29,52,52,0,0,0,0,0,0
0,0,0,0,0,0,0,0,0,0,43,43,43,43,43,52,52,52,0,0,0,0,0,0
0,0,0,0,0,0,0,0,43,43,43,43,3,43,43,43,43,0,0,0,0,0,0,0
0,0,0,0,0,0,0,0,43,43,43,43,43,43,43,43,43,0,0,0,0,0,0,0
0,0,0,0,0,0,0,0,0,43,43,3,43,43,3,43,43,0,0,0,0,0,0,0
0,0,0,0,0,0,0,0,44,44,44,43,43,43,43,43,43,0,0,0,0,0,0,0
0,0,0,0,0,0,0,0,0,44,44,43,43,43,43,43,43,0,0,0,0,0,0,0
0,0,0,0,0,0,0,0,0,0,0,0,0,0,0,0,0,0,0,0,0,0,0,0
endlayer

layer
16,16,0,0,0,0,0,0,0,0,0,18,17,17,16,0,0,0,0,0,0,0,0,0
0,0,0,0,0,0,0,0,0,0,0,0,0,0,0,0,0,0,0,0,0,0,0,0
0,0,0,0,0,0,0,0,0,0,0,0,0,0,0,0,0,0,0,0,0,0,0,0
0,0,0,0,0,0,0,0,0,0,0,0,0,0,0,0,0,0,0,0,0,0,0,0
0,0,0,0,0,0,0,0,0,0,0,0,0,0,0,0,0,0,0,0,0,0,0,0
0,0,0,0,0,0,0,0,0,0,0,0,0,0,0,0,0,0,0,0,0,0,0,0
0,0,0,0,3,7,3,7,3,7,3,7,3,7,3,0,0,0,0,0,0,0,0,0
0,0,0,0,0,7,0,0,0,0,0,0,0,7,0,0,0,0,0,0,0,0,0,0
0,0,0,0,3,7,0,0,0,0,0,0,0,7,3,0,53,46,0,0,0,0,0,0
0,0,0,0,0,7,0,0,0,0,0,0,0,7,0,0,0,0,0,0,0,0,0,0
0,0,0,0,3,7,0,0,0,0,0,0,0,7,3,0,0,0,0,0,0,0,0,0
0,0,0,0,0,7,0,0,0,0,0,0,0,7,0,0,0,0,0,0,0,0,0,0
0,0,0,0,3,7,0,0,0,0,0,0,0,7,3,0,53,46,0,0,0,0,0,0
0,0,0,0,0,7,0,0,0,0,0,0,0,7,0,0,0,0,0,0,0,0,0,0
0,0,0,0,3,7,0,0,0,0,0,0,0,7,3,0,0,0,0,0,0,0,0,0
0,0,0,0,22,3,55,3,22,0,54,3,0,3,22,0,0,0,0,0,0,0,0,0
0,0,0,0,0,0,0,22,10,10,10,22,0,0,0,0,0,0,0,0,0,0,0,0
0,0,0,0,0,0,0,56,51,56,46,56,0,0,0,0,0,0,0,0,0,0,0,0
0,0,0,0,0,0,0,0,0,0,0,0,0,0,0,52,0,0,0,0,0,0,0,0
0,0,0,0,0,0,0,0,0,0,0,0,0,0,52,29,52,0,0,0,0,0,0,0
0,0,0,0,0,0,0,0,0,0,0,43,43,43,0,52,0,0,0,0,0,0,0,0
0,0,0,0,0,0,0,0,0,43,0,43,3,43,43,43,0,0,0,0,0,0,0,0
0,0,0,0,0,0,0,0,43,43,43,43,43,43,43,43,43,0,0,0,0,0,0,0
0,0,0,0,0,0,0,0,0,43,43,3,43,43,3,43,43,0,0,0,0,0,0,0
0,0,0,0,0,0,0,0,0,43,43,43,43,43,43,43,43,0,0,0,0,0,0,0
0,0,0,0,0,0,0,0,0,0,0,0,0,43,43,43,0,0,0,0,0,0,0,0
0,0,0,0,0,0,0,0,0,0,0,0,0,0,0,0,0,0,0,0,0,0,0,0
endlayer

layer
17,17,16,16,0,0,0,0,0,0,18,17,17,16,0,0,0,0,0,0,0,0,0,0
0,0,0,0,0,0,0,0,0,0,0,0,0,0,0,0,0,0,0,0,0,0,0,0
0,0,0,0,0,0,0,0,0,0,0,0,0,0,0,0,0,0,0,0,0,0,0,0
0,0,0,0,0,0,0,0,0,0,0,0,0,0,0,0,0,0,0,0,0,0,0,0
0,0,0,0,0,0,0,0,0,0,0,0,0,0,0,0,0,0,0,0,0,0,0,0
0,0,0,0,0,0,0,0,0,0,0,0,0,0,0,0,0,0,0,0,0,0,0,0
0,0,0,0,3,57,3,55,3,55,3,55,3,57,3,0,0,0,0,0,0,0,0,0
0,0,0,0,0,7,0,0,0,0,0,0,0,7,0,0,0,0,0,0,0,0,0,0
0,0,0,0,3,10,0,0,0,0,0,0,0,10,3,0,0,53,46,0,0,0,0,0
0,0,0,0,0,7,0,0,0,0,0,0,0,7,0,0,0,0,0,0,0,0,0,0
0,0,0,0,3,10,0,0,0,0,0,0,0,10,3,0,0,0,0,0,0,0,0,0
0,0,0,0,0,7,0,0,0,0,0,0,0,7,0,0,0,0,0,0,0,0,0,0
0,0,0,0,3,10,0,0,0,0,0,0,0,10,3,0,0,53,46,0,0,0,0,0
0,0,0,0,0,7,0,0,0,0,0,0,0,7,0,0,0,0,0,0,0,0,0,0
0,0,0,0,3,10,0,0,0,0,0,0,0,10,3,0,0,0,0,0,0,0,0,0
0,0,0,0,22,3,55,3,22,0,0,3,55,3,22,0,0,0,0,0,0,0,0,0
0,0,0,0,0,0,0,22,10,58,0,22,0,0,0,0,0,0,0,0,0,0,0,0
0,0,0,0,0,0,0,3,46,3,51,3,0,0,52,52,52,0,0,0,0,0,0,0
0,0,0,0,0,0,0,0,0,0,0,0,0,52,52,52,52,52,0,0,0,0,0,0
0,0,0,0,0,0,0,0,0,0,0,0,0,52,52,29,52,52,0,0,0,0,0,0
0,0,0,0,0,0,0,0,0,0,0,0,43,52,52,52,52,52,0,0,0,0,0,0
0,0,0,0,0,0,0,0,0,0,0,43,43,43,52,52,52,0,0,0,0,0,0,0
0,0,0,0,0,0,0,0,0,43,0,43,43,0,43,43,0,0,0,0,0,0,0,0
0,0,0,0,0,0,0,0,0,43,43,43,43,43,3,43,0,0,0,0,0,0,0,0
0,0,0,0,0,0,0,0,0,0,0,43,0,0,43,0,0,0,0,0,0,0,0,0
0,0,0,0,0,0,0,0,0,0,0,0,0,0,0,0,0,0,0,0,0,0,0,0
0,0,0,0,0,0,0,0,0,0,0,0,0,0,0,0,0,0,0,0,0,0,0,0
endlayer

layer
17,17,17,17,16,16,0,0,0,0,18,17,17,16,0,0,0,0,0,0,0,0,0,0
0,0,0,0,0,0,0,0,0,0,0,0,0,0,0,0,0,0,0,0,0,0,0,0
0,0,0,0,0,0,0,0,0,0,0,0,0,0,0,0,0,0,0,0,0,0,0,0
0,0,0,0,0,0,0,0,0,0,0,0,0,0,0,0,0,0,0,0,0,0,0,0
0,0,0,0,0,0,0,0,0,0,0,0,0,0,0,0,0,0,0,0,0,0,0,0
0,0,0,0,0,0,0,0,0,0,0,0,0,0,0,0,0,0,0,0,0,0,0,0
0,0,0,0,3,4,3,55,3,55,3,55,3,4,3,0,0,0,0,0,0,0,0,0
0,0,0,0,0,7,42,0,42,0,42,0,42,7,0,0,0,0,0,0,0,0,0,0
0,0,0,0,3,10,0,0,0,0,0,0,0,10,3,0,0,0,53,10,46,0,0,0
0,0,0,0,0,7,38,0,0,0,0,0,35,7,0,0,0,0,0,0,0,0,0,0
0,0,0,0,3,10,0,0,0,0,0,0,0,10,3,0,0,0,0,0,0,0,0,0
0,0,0,0,0,7,38,0,0,0,0,0,35,7,0,0,0,0,0,0,0,0,0,0
0,0,0,0,3,10,0,0,0,0,0,0,0,10,3,0,0,0,53,10,46,0,0,0
0,0,0,0,0,7,38,0,0,0,0,0,35,7,0,0,0,0,0,0,0,0,0,0
0,0,0,0,3,10,0,59,0,0,0,59,0,10,3,0,0,0,0,0,0,0,0,0
0,0,0,0,22,3,50,3,49,0,0,3,50,3,22,0,0,0,0,0,0,0,0,0
0,0,0,0,0,0,0,55,0,0,0,55,0,0,0,0,0,0,0,0,0,0,0,0
0,0,0,0,0,0,0,3,55,3,55,3,0,0,0,0,0,0,0,0,0,0,0,0
0,0,0,0,0,0,0,0,0,0,0,0,0,0,0,52,0,0,0,0,0,0,0,0
0,0,0,0,0,0,0,0,0,0,0,0,0,0,52,29,52,0,0,0,0,0,0,0
0,0,0,0,0,0,0,0,0,0,0,0,0,0,0,52,0,0,0,0,0,0,0,0
0,0,0,0,0,0,0,0,0,0,0,0,0,0,0,0,0,0,0,0,0,0,0,0
0,0,0,0,0,0,0,0,0,0,0,0,0,0,43,0,0,0,0,0,0,0,0,0
0,0,0,0,0,0,0,0,0,0,0,0,0,43,43,43,0,0,0,0,0,0,0,0
0,0,0,0,0,0,0,0,0,0,0,0,0,0,43,0,0,0,0,0,0,0,0,0
0,0,0,0,0,0,0,0,0,0,0,0,0,0,0,0,0,0,0,0,0,0,0,0
0,0,0,0,0,0,0,0,0,0,0,0,0,0,0,0,0,0,0,0,0,0,0,0
endlayer

layer
18,18,17,17,17,17,16,16,0,18,17,17,16,0,0,0,0,0,0,0,0,0,0,0
0,0,0,0,0,0,0,0,0,0,0,0,0,0,0,0,0,0,0,0,0,0,0,0
0,0,0,0,0,0,0,0,0,0,0,0,0,0,0,0,0,0,0,0,0,0,0,0
0,0,0,0,0,0,0,0,0,0,0,0,0,0,0,0,0,0,0,0,0,0,0,0
0,0,0,0,0,0,0,0,0,0,0,0,0,0,0,0,0,0,0,0,0,0,0,0
0,0,0,0,0,0,0,0,0,0,0,0,0,0,0,0,0,0,0,0,0,0,0,0
0,0,0,0,3,7,3,7,3,7,3,7,3,7,3,0,0,0,0,0,0,0,0,0
0,0,0,0,7,0,5,0,0,0,0,0,5,6,7,0,0,0,0,0,0,0,0,0
0,0,0,0,3,0,5,0,0,0,0,0,5,6,3,8,8,8,8,8,8,8,0,0
0,0,0,0,7,0,5,0,0,0,0,0,5,6,7,0,0,0,0,0,0,0,0,0
0,0,0,0,3,0,5,0,0,0,0,0,5,6,3,0,0,0,0,0,0,0,0,0
0,0,0,0,7,0,5,0,0,0,0,0,5,6,7,0,0,0,0,0,0,0,0,0
0,0,0,0,3,0,5,0,0,0,0,0,5,6,3,8,8,8,8,8,8,8,0,0
0,0,0,0,7,0,5,0,0,0,0,0,5,6,7,0,0,0,0,0,0,0,0,0
0,0,0,0,3,0,5,6,60,6,6,6,5,6,3,0,0,0,0,0,0,0,0,0
0,0,0,0,22,3,7,3,0,0,0,3,7,3,22,0,0,0,0,0,0,0,0,0
0,0,0,0,0,0,0,55,0,0,0,55,0,0,0,0,0,0,0,0,0,0,0,0
0,0,0,0,0,0,0,3,55,3,55,3,0,0,52,52,52,0,0,0,0,0,0,0
0,0,0,0,0,0,0,0,0,0,0,0,0,52,52,52,52,52,0,0,0,0,0,0
0,0,0,0,0,0,0,0,0,0,0,0,0,52,52,29,52,52,0,0,0,0,0,0
0,0,0,0,0,0,0,0,0,0,0,0,0,52,52,52,52,52,0,0,0,0,0,0
0,0,0,0,0,0,0,0,0,0,0,0,0,0,52,52,52,0,0,0,0,0,0,0
0,0,0,0,0,0,0,0,0,0,0,0,0,0,0,0,0,0,0,0,0,0,0,0
0,0,0,0,0,0,0,0,0,0,0,0,0,0,0,0,0,0,0,0,0,0,0,0
0,0,0,0,0,0,0,0,0,0,0,0,0,0,0,0,0,0,0,0,0,0,0,0
0,0,0,0,0,0,0,0,0,0,0,0,0,0,0,0,0,0,0,0,0,0,0,0
0,0,0,0,0,0,0,0,0,0,0,0,0,0,0,0,0,0,0,0,0,0,0,0
endlayer

layer
0,0,18,18,17,17,17,17,16,18,17,17,16,0,0,0,0,0,0,0,0,0,0,0
0,0,0,0,0,0,0,0,0,0,0,0,0,0,0,0,0,0,0,0,0,0,0,0
0,0,0,0,0,0,0,6,6,17,6,6,0,0,0,0,0,0,0,0,0,0,0,0
0,0,0,0,0,0,0,6,6,17,6,6,0,0,0,0,0,0,0,0,0,0,0,0
0,0,0,0,0,0,0,6,6,17,6,6,0,0,0,0,0,0,0,0,0,0,0,0
0,0,0,5,8,8,8,8,8,8,8,8,8,8,8,8,8,8,8,5,0,0,0,0
0,0,0,5,6,6,6,6,6,6,6,6,6,6,6,6,6,6,6,5,0,0,0,0
0,0,0,5,6,6,6,6,6,6,6,6,6,6,6,6,6,6,6,5,8,8,8,0
0,0,0,5,6,6,6,6,6,6,6,6,6,6,6,6,6,6,6,5,6,6,5,0
0,0,0,5,6,6,6,6,6,6,6,6,6,6,6,6,6,6,6,5,6,6,5,0
0,0,0,5,6,6,6,6,6,6,6,6,6,6,6,6,6,6,6,5,6,6,5,0
0,0,0,5,6,6,6,6,6,6,6,6,6,6,6,6,6,6,6,5,6,6,5,0
0,0,0,5,6,6,6,6,6,6,6,6,6,6,6,6,6,6,6,5,6,6,5,0
0,0,0,5,6,6,6,62,60,61,6,6,6,6,6,6,6,6,6,5,8,8,8,0
0,0,0,5,6,6,6,62,0,61,6,6,6,6,6,6,6,6,6,5,0,0,0,0
0,0,0,5,8,8,7,3,0,0,0,3,7,8,8,8,8,8,8,5,0,0,0,0
0,0,0,0,0,0,0,55,0,0,0,55,0,0,0,0,0,0,0,0,0,0,0,0
0,0,0,0,0,0,0,3,55,3,55,3,0,0,0,0,0,0,0,0,0,0,0,0
0,0,0,0,0,0,0,0,0,0,0,0,0,0,0,52,0,0,0,0,0,0,0,0
0,0,0,0,0,0,0,0,0,0,0,0,0,0,52,52,52,0,0,0,0,0,0,0
0,0,0,0,0,0,0,0,0,0,0,0,0,0,0,52,0,0,0,0,0,0,0,0
0,0,0,0,0,0,0,0,0,0,0,0,0,0,0,0,0,0,0,0,0,0,0,0
0,0,0,0,0,0,0,0,0,0,0,0,0,0,0,0,0,0,0,0,0,0,0,0
0,0,0,0,0,0,0,0,0,0,0,0,0,0,0,0,0,0,0,0,0,0,0,0
0,0,0,0,0,0,0,0,0,0,0,0,0,0,0,0,0,0,0,0,0,0,0,0
0,0,0,0,0,0,0,0,0,0,0,0,0,0,0,0,0,0,0,0,0,0,0,0
0,0,0,0,0,0,0,0,0,0,0,0,0,0,0,0,0,0,0,0,0,0,0,0
endlayer

layer
0,0,0,0,18,18,17,17,17,18,17,16,0,0,0,0,0,0,0,0,0,0,0,0
0,0,0,0,0,0,0,0,0,63,0,0,0,0,0,0,0,0,0,0,0,0,0,0
0,0,0,0,0,0,17,17,37,5,37,17,17,0,0,0,0,0,0,0,0,0,0,0
0,0,0,0,0,0,17,0,0,5,0,0,17,0,0,0,0,0,0,0,0,0,0,0
0,0,0,0,0,0,17,0,37,5,37,0,17,0,0,0,0,0,0,0,0,0,0,0
0,0,0,3,7,3,7,0,0,5,0,0,7,3,7,3,57,3,7,3,0,0,0,0
0,0,0,7,0,0,0,0,37,5,37,0,0,0,0,0,0,0,0,7,0,0,0,0
0,0,0,3,0,0,0,0,0,5,0,0,0,0,0,0,0,0,0,3,57,57,3,0
0,0,0,65,0,0,0,0,51,10,46,0,0,0,0,0,0,0,0,0,0,0,64,0
0,0,0,3,0,0,0,0,0,0,0,0,0,0,0,0,0,0,0,0,0,0,3,0
0,0,0,65,0,0,0,0,0,0,0,0,0,0,0,0,0,0,0,0,0,0,64,0
0,0,0,3,0,0,0,0,0,0,0,0,0,0,0,0,0,0,0,0,0,0,3,0
0,0,0,65,0,0,0,0,0,0,0,0,0,0,0,0,0,0,0,0,0,0,64,0
0,0,0,3,0,0,0,0,0,0,0,0,0,0,0,0,0,0,0,3,23,23,3,0
0,0,0,7,0,0,0,0,0,0,0,0,0,0,0,0,0,0,0,7,0,0,0,0
0,0,0,3,7,3,7,3,0,0,0,3,7,3,7,3,23,3,7,3,0,0,0,0
0,0,0,0,0,0,0,55,0,59,0,55,0,0,0,0,0,0,0,0,0,0,0,0
0,0,0,0,0,0,0,3,55,3,55,3,0,0,0,0,0,0,0,0,0,0,0,0
0,0,0,0,0,0,0,0,0,0,0,0,0,0,0,0,0,0,0,0,0,0,0,0
0,0,0,0,0,0,0,0,0,0,0,0,0,0,0,52,0,0,0,0,0,0,0,0
0,0,0,0,0,0,0,0,0,0,0,0,0,0,0,0,0,0,0,0,0,0,0,0
0,0,0,0,0,0,0,0,0,0,0,0,0,0,0,0,0,0,0,0,0,0,0,0
0,0,0,0,0,0,0,0,0,0,0,0,0,0,0,0,0,0,0,0,0,0,0,0
0,0,0,0,0,0,0,0,0,0,0,0,0,0,0,0,0,0,0,0,0,0,0,0
0,0,0,0,0,0,0,0,0,0,0,0,0,0,0,0,0,0,0,0,0,0,0,0
0,0,0,0,0,0,0,0,0,0,0,0,0,0,0,0,0,0,0,0,0,0,0,0
0,0,0,0,0,0,0,0,0,0,0,0,0,0,0,0,0,0,0,0,0,0,0,0
endlayer

layer
0,0,0,0,0,0,18,18,18,17,18,18,18,0,0,0,0,0,0,0,0,0,0,0
0,0,0,0,0,0,0,0,63,0,63,0,0,0,0,0,0,0,0,0,0,0,0,0
0,0,0,0,0,0,0,0,5,0,5,0,0,0,0,0,0,0,0,0,0,0,0,0
0,0,0,0,0,0,0,0,5,0,5,0,0,0,0,0,0,0,0,0,0,0,0,0
0,0,0,0,0,0,0,0,5,0,5,0,0,0,0,0,0,0,0,0,0,0,0,0
0,0,0,3,7,3,7,0,5,0,5,0,7,3,7,3,55,3,7,3,0,0,0,0
0,0,0,7,0,0,0,0,5,0,5,0,0,0,0,0,0,0,0,7,0,0,0,0
0,0,0,3,0,0,0,0,5,0,5,0,0,0,0,0,0,0,0,3,55,55,3,0
0,0,0,55,0,0,0,0,10,66,10,0,0,0,0,0,0,0,0,0,0,0,55,0
0,0,0,3,0,0,0,0,0,0,0,0,0,0,0,0,0,0,0,0,0,0,3,0
0,0,0,55,0,0,0,0,0,0,0,0,0,0,0,0,0,0,0,0,0,0,55,0
0,0,0,3,0,0,0,0,0,0,0,0,0,0,0,0,0,0,0,0,0,0,3,0
0,0,0,55,0,0,0,0,0,0,0,0,0,0,0,0,0,0,0,0,0,0,55,0
0,0,0,3,0,0,0,0,0,0,0,0,0,0,0,0,0,0,0,3,55,55,3,0
0,0,0,7,0,0,0,0,0,0,0,0,0,0,0,0,0,0,0,7,0,0,0,0
0,0,0,3,7,3,7,3,0,0,0,3,7,3,7,3,55,3,7,3,0,0,0,0
0,0,0,0,0,0,0,55,0,0,0,55,0,0,0,0,0,0,0,0,0,0,0,0
0,0,0,0,0,0,0,3,55,3,55,3,0,0,0,0,0,0,0,0,0,0,0,0
0,0,0,0,0,0,0,0,0,0,0,0,0,0,0,52,0,0,0,0,0,0,0,0
0,0,0,0,0,0,0,0,0,0,0,0,0,0,52,52,52,0,0,0,0,0,0,0
0,0,0,0,0,0,0,0,0,0,0,0,0,0,0,52,0,0,0,0,0,0,0,0
0,0,0,0,0,0,0,0,0,0,0,0,0,0,0,0,0,0,0,0,0,0,0,0
0,0,0,0,0,0,0,0,0,0,0,0,0,0,0,0,0,0,0,0,0,0,0,0
0,0,0,0,0,0,0,0,0,0,0,0,0,0,0,0,0,0,0,0,0,0,0,0
0,0,0,0,0,0,0,0,0,0,0,0,0,0,0,0,0,0,0,0,0,0,0,0
0,0,0,0,0,0,0,0,0,0,0,0,0,0,0,0,0,0,0,0,0,0,0,0
0,0,0,0,0,0,0,0,0,0,0,0,0,0,0,0,0,0,0,0,0,0,0,0
endlayer

layer
0,0,0,0,0,0,0,16,17,18,17,17,17,18,18,0,0,0,0,0,0,0,0,0
0,0,0,0,0,0,0,0,0,63,0,0,0,0,0,0,0,0,0,0,0,0,0,0
0,0,0,0,0,0,0,0,0,5,0,0,0,0,0,0,0,0,0,0,0,0,0,0
0,0,0,0,0,0,0,0,0,5,0,0,0,0,0,0,0,0,0,0,0,0,0,0
0,0,0,0,0,0,0,59,0,5,0,59,0,0,0,0,0,0,0,0,0,0,0,0
0,0,0,3,7,3,7,7,0,5,0,7,7,3,7,3,55,3,7,3,0,0,0,0
0,0,0,7,0,42,0,0,0,5,0,0,0,42,0,42,0,42,0,7,0,0,0,0
0,0,0,3,38,0,0,0,0,5,0,0,0,0,0,0,0,0,35,3,55,55,3,0
0,0,0,55,0,0,0,0,53,10,58,0,0,0,0,0,0,0,0,0,0,0,55,0
0,0,0,3,38,0,0,0,0,0,0,0,0,0,0,0,0,0,0,0,0,35,3,0
0,0,0,55,0,0,0,0,0,0,0,0,0,0,0,0,0,0,0,0,0,0,55,0
0,0,0,3,38,0,0,0,0,0,0,0,0,0,0,0,0,0,0,0,0,35,3,0
0,0,0,55,0,0,0,0,0,0,0,0,0,0,0,0,0,0,0,0,0,0,55,0
0,0,0,3,38,0,0,0,0,0,0,0,0,0,0,0,0,0,35,3,55,55,3,0
0,0,0,7,0,59,0,59,0,0,0,59,0,59,0,59,0,59,0,7,0,0,0,0
0,0,0,3,7,3,7,3,0,0,0,3,7,3,7,3,55,3,7,3,0,0,0,0
0,0,0,0,0,0,0,55,0,59,0,55,0,0,0,0,0,0,0,0,0,0,0,0
0,0,0,0,0,0,0,3,55,3,55,3,0,0,0,0,0,0,0,0,0,0,0,0
0,0,0,0,0,0,0,0,0,0,0,0,0,0,0,0,0,0,0,0,0,0,0,0
0,0,0,0,0,0,0,0,0,0,0,0,0,0,0,0,0,0,0,0,0,0,0,0
0,0,0,0,0,0,0,0,0,0,0,0,0,0,0,0,0,0,0,0,0,0,0,0
0,0,0,0,0,0,0,0,0,0,0,0,0,0,0,0,0,0,0,0,0,0,0,0
0,0,0,0,0,0,0,0,0,0,0,0,0,0,0,0,0,0,0,0,0,0,0,0
0,0,0,0,0,0,0,0,0,0,0,0,0,0,0,0,0,0,0,0,0,0,0,0
0,0,0,0,0,0,0,0,0,0,0,0,0,0,0,0,0,0,0,0,0,0,0,0
0,0,0,0,0,0,0,0,0,0,0,0,0,0,0,0,0,0,0,0,0,0,0,0
0,0,0,0,0,0,0,0,0,0,0,0,0,0,0,0,0,0,0,0,0,0,0,0
endlayer

layer
0,0,0,0,0,0,16,17,17,18,16,17,17,17,17,18,18,0,0,0,0,0,0,0
0,0,0,0,0,0,0,0,0,37,0,0,0,0,0,0,0,0,0,0,0,0,0,0
0,0,0,0,0,0,0,0,0,0,0,0,0,0,0,0,0,0,0,0,0,0,0,0
0,0,0,0,0,0,0,0,0,0,0,0,0,0,0,0,0,0,0,0,0,0,0,0
0,0,0,0,0,0,0,0,0,0,0,0,0,0,0,0,0,0,0,0,0,0,0,0
0,0,0,3,7,3,7,3,7,3,7,3,7,3,7,3,4,3,7,3,0,0,0,0
0,0,0,7,0,0,0,0,0,0,0,0,0,0,0,0,0,0,0,7,0,0,0,0
0,0,0,3,0,0,0,0,0,0,0,0,0,0,0,0,0,0,0,3,4,4,3,0
0,0,0,21,0,0,0,0,0,0,0,0,0,0,0,0,0,0,0,0,0,0,20,0
0,0,0,3,0,0,0,0,0,0,0,0,0,0,0,0,0,0,0,0,0,0,3,0
0,0,0,21,0,0,0,0,0,0,0,0,0,0,0,0,0,0,0,0,0,0,20,0
0,0,0,3,0,0,0,0,0,0,0,0,0,0,0,0,0,0,0,0,0,0,3,0
0,0,0,21,0,0,0,0,0,0,0,0,0,0,0,0,0,0,0,0,0,0,20,0
0,0,0,3,0,0,0,0,0,0,0,0,0,0,0,0,0,0,0,3,25,25,3,0
0,0,0,7,0,0,0,0,0,0,0,0,0,0,0,0,0,0,0,7,0,0,0,0
0,0,0,3,7,3,7,3,0,0,0,3,7,3,7,3,25,3,7,3,0,0,0,0
0,0,0,0,0,0,0,21,0,0,0,20,0,0,0,0,0,0,0,0,0,0,0,0
0,0,0,0,0,0,0,3,25,3,25,3,0,0,0,0,0,0,0,0,0,0,0,0
0,0,0,0,0,0,0,0,0,0,0,0,0,0,0,0,0,0,0,0,0,0,0,0
0,0,0,0,0,0,0,0,0,0,0,0,0,0,0,0,0,0,0,0,0,0,0,0
0,0,0,0,0,0,0,0,0,0,0,0,0,0,0,0,0,0,0,0,0,0,0,0
0,0,0,0,0,0,0,0,0,0,0,0,0,0,0,0,0,0,0,0,0,0,0,0
0,0,0,0,0,0,0,0,0,0,0,0,0,0,0,0,0,0,0,0,0,0,0,0
0,0,0,0,0,0,0,0,0,0,0,0,0,0,0,0,0,0,0,0,0,0,0,0
0,0,0,0,0,0,0,0,0,0,0,0,0,0,0,0,0,0,0,0,0,0,0,0
0,0,0,0,0,0,0,0,0,0,0,0,0,0,0,0,0,0,0,0,0,0,0,0
0,0,0,0,0,0,0,0,0,0,0,0,0,0,0,0,0,0,0,0,0,0,0,0
endlayer

layer
0,0,0,0,0,0,16,17,17,18,0,16,16,17,17,17,17,18,18,0,0,0,0,0
0,0,0,0,0,0,0,0,0,0,0,0,0,0,0,0,0,0,0,0,0,0,0,0
0,0,0,0,0,0,0,0,0,0,0,0,0,0,0,0,0,0,0,0,0,0,0,0
0,0,0,0,0,0,0,0,0,0,0,0,0,0,0,0,0,0,0,0,0,0,0,0
0,0,53,46,0,0,0,0,0,0,51,5,46,0,0,0,0,0,0,51,58,0,0,0
0,0,53,3,7,3,7,3,7,3,7,5,7,3,7,3,7,3,7,3,58,0,0,0
0,0,53,7,0,0,0,0,0,0,0,5,0,0,0,0,0,0,0,7,54,54,54,58
0,0,53,3,0,0,0,0,0,0,0,5,0,0,0,0,0,0,0,3,7,7,3,58
0,0,53,7,0,0,0,0,0,0,35,5,38,0,0,0,0,0,0,0,0,0,7,58
0,0,53,3,0,0,0,0,0,0,0,5,0,0,0,0,0,0,0,0,0,0,3,58
0,0,53,7,0,0,0,0,0,0,35,5,38,0,0,0,0,0,0,0,0,0,7,58
0,0,53,3,0,0,0,0,0,0,0,5,0,0,0,0,0,0,0,0,0,0,3,58
0,0,53,7,0,0,0,0,0,0,35,5,38,0,0,0,0,0,0,0,0,0,7,58
0,0,53,3,0,0,0,0,0,0,0,5,0,0,0,0,0,0,0,3,7,7,3,58
0,0,53,7,0,0,0,0,0,0,35,5,0,0,0,0,0,0,0,7,49,49,49,49
0,0,53,3,7,3,7,3,0,0,0,5,7,3,7,3,7,3,7,3,58,0,0,0
0,0,53,46,0,0,0,7,0,0,0,5,46,0,0,0,0,0,0,51,58,0,0,0
0,0,0,0,0,0,0,3,7,3,7,5,0,0,0,0,0,0,0,0,0,0,0,0
0,0,0,0,0,0,0,0,0,0,51,5,0,0,0,0,0,0,0,0,0,0,0,0
0,0,0,0,0,0,0,0,0,0,0,0,0,0,0,0,0,0,0,0,0,0,0,0
0,0,0,0,0,0,0,0,0,0,0,0,0,0,0,0,0,0,0,0,0,0,0,0
0,0,0,0,0,0,0,0,0,0,0,0,0,0,0,0,0,0,0,0,0,0,0,0
0,0,0,0,0,0,0,0,0,0,0,0,0,0,0,0,0,0,0,0,0,0,0,0
0,0,0,0,0,0,0,0,0,0,0,0,0,0,0,0,0,0,0,0,0,0,0,0
0,0,0,0,0,0,0,0,0,0,0,0,0,0,0,0,0,0,0,0,0,0,0,0
0,0,0,0,0,0,0,0,0,0,0,0,0,0,0,0,0,0,0,0,0,0,0,0
0,0,0,0,0,0,0,0,0,0,0,0,0,0,0,0,0,0,0,0,0,0,0,0
endlayer

layer
0,0,0,0,0,16,17,17,18,0,0,0,0,16,16,17,17,17,17,0,0,0,0,0
0,0,0,0,0,0,0,0,0,0,0,0,0,0,0,0,0,0,0,0,0,0,0,0
0,0,0,0,0,0,0,0,0,0,0,0,0,0,0,0,0,0,0,0,0,0,0,0
0,0,0,0,0,0,0,0,0,0,0,0,0,0,0,0,0,0,0,0,0,0,0,0
0,0,0,53,46,0,0,0,0,51,58,0,53,46,0,0,0,0,51,58,0,0,0,0
0,0,0,61,7,3,7,3,7,3,62,0,61,3,7,3,7,3,7,62,0,0,0,0
0,0,0,61,0,0,0,0,0,0,62,0,61,0,0,0,0,0,48,62,0,0,0,0
0,0,0,61,0,0,0,0,0,0,62,0,61,0,0,0,0,0,48,58,54,54,54,0
0,0,0,61,0,0,0,0,0,0,62,0,61,0,0,0,0,0,48,56,56,56,58,0
0,0,0,61,0,0,0,0,0,0,62,0,61,0,0,0,0,0,0,0,0,0,58,0
0,0,0,61,0,0,0,0,0,0,62,0,61,0,0,0,0,0,0,0,0,0,58,0
0,0,0,61,0,0,0,0,0,0,62,0,61,0,0,0,0,0,0,0,0,0,58,0
0,0,0,61,0,0,0,0,0,0,62,0,61,0,0,0,0,0,48,67,67,67,58,0
0,0,0,61,0,0,0,0,0,0,62,0,61,0,0,0,0,0,48,58,49,49,58,0
0,0,0,61,0,0,0,0,0,0,62,0,61,0,0,0,0,0,48,62,0,0,0,0
0,0,0,61,7,3,7,3,0,0,62,0,61,3,7,3,7,3,7,62,0,0,0,0
0,0,0,53,46,0,0,7,0,0,62,0,53,46,0,0,0,0,51,58,0,0,0,0
0,0,0,0,0,0,0,3,7,3,62,0,0,0,0,0,0,0,0,0,0,0,0,0
0,0,0,0,0,0,0,0,0,51,58,0,0,0,0,0,0,0,0,0,0,0,0,0
0,0,0,0,0,0,0,0,0,0,0,0,0,0,0,0,0,0,0,0,0,0,0,0
0,0,0,0,0,0,0,0,0,0,0,0,0,0,0,0,0,0,0,0,0,0,0,0
0,0,0,0,0,0,0,0,0,0,0,0,0,0,0,0,0,0,0,0,0,0,0,0
0,0,0,0,0,0,0,0,0,0,0,0,0,0,0,0,0,0,0,0,0,0,0,0
0,0,0,0,0,0,0,0,0,0,0,0,0,0,0,0,0,0,0,0,0,0,0,0
0,0,0,0,0,0,0,0,0,0,0,0,0,0,0,0,0,0,0,0,0,0,0,0
0,0,0,0,0,0,0,0,0,0,0,0,0,0,0,0,0,0,0,0,0,0,0,0
0,0,0,0,0,0,0,0,0,0,0,0,0,0,0,0,0,0,0,0,0,0,0,0
endlayer

layer
0,0,0,0,0,16,17,17,18,0,0,0,0,0,0,16,16,17,17,0,0,0,0,0
0,0,0,0,0,0,0,0,0,0,0,0,0,0,0,0,0,0,0,0,0,0,0,0
0,0,0,0,0,0,0,0,0,0,0,0,0,0,0,0,0,0,0,0,0,0,0,0
0,0,0,0,0,0,0,0,0,0,0,0,0,0,0,0,0,0,0,0,0,0,0,0
0,0,0,0,53,46,0,0,51,58,0,0,0,53,46,0,0,51,58,0,0,0,0,0
0,0,0,0,61,3,7,3,7,62,0,0,0,61,7,3,7,3,62,0,0,0,0,0
0,0,0,0,61,0,0,0,0,62,0,0,0,61,0,0,0,0,62,0,0,0,0,0
0,0,0,0,61,0,0,0,0,62,0,0,0,61,0,0,0,0,62,0,0,0,0,0
0,0,0,0,61,0,0,0,0,62,0,0,0,61,0,0,0,0,62,68,68,68,0,0
0,0,0,0,61,0,0,0,0,62,0,0,0,61,0,0,0,0,62,68,68,68,0,0
0,0,0,0,61,0,0,0,0,62,0,0,0,61,0,0,0,0,62,68,68,68,0,0
0,0,0,0,61,0,0,0,0,62,0,0,0,61,0,0,0,0,62,68,68,68,0,0
0,0,0,0,61,0,0,0,0,62,0,0,0,61,0,0,0,0,62,68,68,68,0,0
0,0,0,0,61,0,0,0,0,62,0,0,0,61,0,0,0,0,62,0,0,0,0,0
0,0,0,0,61,0,0,0,0,62,0,0,0,61,0,0,0,0,62,0,0,0,0,0
0,0,0,0,61,3,7,3,0,62,0,0,0,61,7,3,7,3,62,0,0,0,0,0
0,0,0,0,53,46,0,7,0,62,0,0,0,53,46,0,0,51,58,0,0,0,0,0
0,0,0,0,0,0,0,3,7,62,0,0,0,0,0,0,0,0,0,0,0,0,0,0
0,0,0,0,0,0,0,0,51,58,0,0,0,0,0,0,0,0,0,0,0,0,0,0
0,0,0,0,0,0,0,0,0,0,0,0,0,0,0,0,0,0,0,0,0,0,0,0
0,0,0,0,0,0,0,0,0,0,0,0,0,0,0,0,0,0,0,0,0,0,0,0
0,0,0,0,0,0,0,0,0,0,0,0,0,0,0,0,0,0,0,0,0,0,0,0
0,0,0,0,0,0,0,0,0,0,0,0,0,0,0,0,0,0,0,0,0,0,0,0
0,0,0,0,0,0,0,0,0,0,0,0,0,0,0,0,0,0,0,0,0,0,0,0
0,0,0,0,0,0,0,0,0,0,0,0,0,0,0,0,0,0,0,0,0,0,0,0
0,0,0,0,0,0,0,0,0,0,0,0,0,0,0,0,0,0,0,0,0,0,0,0
0,0,0,0,0,0,0,0,0,0,0,0,0,0,0,0,0,0,0,0,0,0,0,0
endlayer

layer
0,0,0,0,16,17,17,18,0,0,0,0,0,0,0,0,0,16,16,0,0,0,0,0
0,0,0,0,0,0,0,0,0,0,0,0,0,0,0,0,0,0,0,0,0,0,0,0
0,0,0,0,0,0,0,0,0,0,0,0,0,0,0,0,0,0,0,0,0,0,0,0
0,0,0,0,0,0,0,0,0,0,0,0,0,0,0,0,0,0,0,0,0,0,0,0
0,0,0,0,0,10,0,0,10,0,0,0,0,0,10,46,0,10,0,0,0,0,0,0
0,0,0,0,0,6,7,3,6,0,0,0,0,0,6,3,7,6,0,0,0,0,0,0
0,0,0,0,0,6,0,0,6,0,0,0,0,0,6,0,0,6,0,0,0,0,0,0
0,0,0,0,0,6,0,0,6,0,0,0,0,0,6,0,0,6,0,0,0,0,0,0
0,0,0,0,0,6,0,0,6,0,0,0,0,0,6,0,0,6,0,0,0,0,0,0
0,0,0,0,0,6,0,0,6,0,0,0,0,0,6,0,0,6,0,0,0,0,0,0
0,0,0,0,0,6,0,0,6,0,0,0,0,0,6,0,0,6,0,0,0,0,0,0
0,0,0,0,0,6,0,0,6,0,0,0,0,0,6,0,0,6,0,0,0,0,0,0
0,0,0,0,0,6,0,0,6,0,0,0,0,0,6,0,0,6,0,0,0,0,0,0
0,0,0,0,0,6,0,0,6,0,0,0,0,0,6,0,0,6,0,0,0,0,0,0
0,0,0,0,0,6,0,0,6,0,0,0,0,0,6,0,0,6,0,0,0,0,0,0
0,0,0,0,0,6,7,3,6,0,0,0,0,0,6,3,7,6,0,0,0,0,0,0
0,0,0,0,0,10,0,7,6,0,0,0,0,0,10,0,0,10,0,0,0,0,0,0
0,0,0,0,0,0,0,3,6,0,0,0,0,0,0,0,0,0,0,0,0,0,0,0
0,0,0,0,0,0,0,0,10,0,0,0,0,0,0,0,0,0,0,0,0,0,0,0
0,0,0,0,0,0,0,0,0,0,0,0,0,0,0,0,0,0,0,0,0,0,0,0
0,0,0,0,0,0,0,0,0,0,0,0,0,0,0,0,0,0,0,0,0,0,0,0
0,0,0,0,0,0,0,0,0,0,0,0,0,0,0,0,0,0,0,0,0,0,0,0
0,0,0,0,0,0,0,0,0,0,0,0,0,0,0,0,0,0,0,0,0,0,0,0
0,0,0,0,0,0,0,0,0,0,0,0,0,0,0,0,0,0,0,0,0,0,0,0
0,0,0,0,0,0,0,0,0,0,0,0,0,0,0,0,0,0,0,0,0,0,0,0
0,0,0,0,0,0,0,0,0,0,0,0,0,0,0,0,0,0,0,0,0,0,0,0
0,0,0,0,0,0,0,0,0,0,0,0,0,0,0,0,0,0,0,0,0,0,0,0
endlayer

layer
0,0,0,0,16,17,17,18,0,0,0,0,0,0,0,0,0,0,0,0,0,0,0,0
0,0,0,0,0,0,0,0,0,0,0,0,0,0,0,0,0,0,0,0,0,0,0,0
0,0,0,0,0,0,0,0,0,0,0,0,0,0,0,0,0,0,0,0,0,0,0,0
0,0,0,0,0,0,0,0,0,0,0,0,0,0,0,0,0,0,0,0,0,0,0,0
0,0,0,0,0,53,46,51,58,0,0,0,0,0,53,10,51,58,0,0,0,0,0,0
0,0,0,0,0,61,7,5,62,0,0,0,0,0,61,5,7,62,0,0,0,0,0,0
0,0,0,0,0,61,0,5,62,0,0,0,0,0,61,5,0,62,0,0,0,0,0,0
0,0,0,0,0,61,0,5,62,0,0,0,0,0,61,5,0,62,0,0,0,0,0,0
0,0,0,0,0,61,0,5,62,0,0,0,0,0,61,5,0,62,0,0,0,0,0,0
0,0,0,0,0,61,0,5,62,0,0,0,0,0,61,5,0,62,0,0,0,0,0,0
0,0,0,0,0,61,0,5,62,0,0,0,0,0,61,5,0,62,0,0,0,0,0,0
0,0,0,0,0,61,0,5,62,0,0,0,0,0,61,5,0,62,0,0,0,0,0,0
0,0,0,0,0,61,0,5,62,0,0,0,0,0,61,5,0,62,0,0,0,0,0,0
0,0,0,0,0,61,0,5,62,0,0,0,0,0,61,5,0,62,0,0,0,0,0,0
0,0,0,0,0,61,0,5,62,0,0,0,0,0,61,5,0,62,0,0,0,0,0,0
0,0,0,0,0,61,7,5,62,0,0,0,0,0,61,5,7,62,0,0,0,0,0,0
0,0,0,0,0,53,46,6,62,0,0,0,0,0,53,46,51,58,0,0,0,0,0,0
0,0,0,0,0,0,0,6,62,0,0,0,0,0,0,0,0,0,0,0,0,0,0,0
0,0,0,0,0,0,0,51,58,0,0,0,0,0,0,0,0,0,0,0,0,0,0,0
0,0,0,0,0,0,0,0,0,0,0,0,0,0,0,0,0,0,0,0,0,0,0,0
0,0,0,0,0,0,0,0,0,0,0,0,0,0,0,0,0,0,0,0,0,0,0,0
0,0,0,0,0,0,0,0,0,0,0,0,0,0,0,0,0,0,0,0,0,0,0,0
0,0,0,0,0,0,0,0,0,0,0,0,0,0,0,0,0,0,0,0,0,0,0,0
0,0,0,0,0,0,0,0,0,0,0,0,0,0,0,0,0,0,0,0,0,0,0,0
0,0,0,0,0,0,0,0,0,0,0,0,0,0,0,0,0,0,0,0,0,0,0,0
0,0,0,0,0,0,0,0,0,0,0,0,0,0,0,0,0,0,0,0,0,0,0,0
0,0,0,0,0,0,0,0,0,0,0,0,0,0,0,0,0,0,0,0,0,0,0,0
endlayer

layer
0,0,0,16,17,17,18,0,0,0,0,0,0,0,0,0,0,0,0,0,0,0,0,0
0,0,0,0,0,0,0,0,0,0,0,0,0,0,0,0,0,0,0,0,0,0,0,0
0,0,0,0,0,0,0,0,0,0,0,0,0,0,0,0,0,0,0,0,0,0,0,0
0,0,0,0,0,0,0,0,0,0,0,0,0,0,0,0,0,0,0,0,0,0,0,0
0,0,0,0,0,0,53,58,0,0,0,0,0,0,0,53,58,0,0,0,0,0,0,0
0,0,0,0,0,0,61,62,0,0,0,0,0,0,0,61,62,0,0,0,0,0,0,0
0,0,0,0,0,0,61,62,0,0,0,0,0,0,0,61,62,0,0,0,0,0,0,0
0,0,0,0,0,0,61,62,0,0,0,0,0,0,0,61,62,0,0,0,0,0,0,0
0,0,0,0,0,0,61,62,0,0,0,0,0,0,0,61,62,0,0,0,0,0,0,0
0,0,0,0,0,0,61,62,0,0,0,0,0,0,0,61,62,0,0,0,0,0,0,0
0,0,0,0,0,0,61,62,0,0,0,0,0,0,0,61,62,0,0,0,0,0,0,0
0,0,0,0,0,0,61,62,0,0,0,0,0,0,0,61,62,0,0,0,0,0,0,0
0,0,0,0,0,0,61,62,0,0,0,0,0,0,0,61,62,0,0,0,0,0,0,0
0,0,0,0,0,0,61,62,0,0,0,0,0,0,0,61,62,0,0,0,0,0,0,0
0,0,0,0,0,0,61,62,0,0,0,0,0,0,0,61,62,0,0,0,0,0,0,0
0,0,0,0,0,0,61,62,0,0,0,0,0,0,0,61,62,0,0,0,0,0,0,0
0,0,0,0,0,0,53,62,0,0,0,0,0,0,0,53,58,0,0,0,0,0,0,0
0,0,0,0,0,0,0,62,0,0,0,0,0,0,0,0,0,0,0,0,0,0,0,0
0,0,0,0,0,0,0,58,0,0,0,0,0,0,0,0,0,0,0,0,0,0,0,0
0,0,0,0,0,0,0,0,0,0,0,0,0,0,0,0,0,0,0,0,0,0,0,0
0,0,0,0,0,0,0,0,0,0,0,0,0,0,0,0,0,0,0,0,0,0,0,0
0,0,0,0,0,0,0,0,0,0,0,0,0,0,0,0,0,0,0,0,0,0,0,0
0,0,0,0,0,0,0,0,0,0,0,0,0,0,0,0,0,0,0,0,0,0,0,0
0,0,0,0,0,0,0,0,0,0,0,0,0,0,0,0,0,0,0,0,0,0,0,0
0,0,0,0,0,0,0,0,0,0,0,0,0,0,0,0,0,0,0,0,0,0,0,0
0,0,0,0,0,0,0,0,0,0,0,0,0,0,0,0,0,0,0,0,0,0,0,0
0,0,0,0,0,0,0,0,0,0,0,0,0,0,0,0,0,0,0,0,0,0,0,0
endlayer

layer
0,0,0,16,17,17,18,0,0,0,0,0,0,0,0,0,0,0,0,0,0,0,0,0
0,0,0,0,0,0,0,0,0,0,0,0,0,0,0,0,0,0,0,0,0,0,0,0
0,0,0,0,0,0,0,0,0,0,0,0,0,0,0,0,0,0,0,0,0,0,0,0
0,0,0,0,0,0,0,0,0,0,0,0,0,0,0,0,0,0,0,0,0,0,0,0
0,0,0,0,0,0,0,0,0,0,0,0,0,0,0,0,0,0,0,0,0,0,0,0
0,0,0,0,0,0,0,0,0,0,0,0,0,0,0,0,0,0,0,0,0,0,0,0
0,0,0,0,0,0,0,0,0,0,0,0,0,0,0,0,0,0,0,0,0,0,0,0
0,0,0,0,0,0,0,0,0,0,0,0,0,0,0,0,0,0,0,0,0,0,0,0
0,0,0,0,0,0,0,0,0,0,0,0,0,0,0,0,0,0,0,0,0,0,0,0
0,0,0,0,0,0,0,0,0,0,0,0,0,0,0,0,0,0,0,0,0,0,0,0
0,0,0,0,0,0,0,0,0,0,0,0,0,0,0,0,0,0,0,0,0,0,0,0
0,0,0,0,0,0,0,0,0,0,0,0,0,0,0,0,0,0,0,0,0,0,0,0
0,0,0,0,0,0,0,0,0,0,0,0,0,0,0,0,0,0,0,0,0,0,0,0
0,0,0,0,0,0,0,0,0,0,0,0,0,0,0,0,0,0,0,0,0,0,0,0
0,0,0,0,0,0,0,0,0,0,0,0,0,0,0,0,0,0,0,0,0,0,0,0
0,0,0,0,0,0,0,0,0,0,0,0,0,0,0,0,0,0,0,0,0,0,0,0
0,0,0,0,0,0,0,0,0,0,0,0,0,0,0,0,0,0,0,0,0,0,0,0
0,0,0,0,0,0,0,0,0,0,0,0,0,0,0,0,0,0,0,0,0,0,0,0
0,0,0,0,0,0,0,0,0,0,0,0,0,0,0,0,0,0,0,0,0,0,0,0
0,0,0,0,0,0,0,0,0,0,0,0,0,0,0,0,0,0,0,0,0,0,0,0
0,0,0,0,0,0,0,0,0,0,0,0,0,0,0,0,0,0,0,0,0,0,0,0
0,0,0,0,0,0,0,0,0,0,0,0,0,0,0,0,0,0,0,0,0,0,0,0
0,0,0,0,0,0,0,0,0,0,0,0,0,0,0,0,0,0,0,0,0,0,0,0
0,0,0,0,0,0,0,0,0,0,0,0,0,0,0,0,0,0,0,0,0,0,0,0
0,0,0,0,0,0,0,0,0,0,0,0,0,0,0,0,0,0,0,0,0,0,0,0
0,0,0,0,0,0,0,0,0,0,0,0,0,0,0,0,0,0,0,0,0,0,0,0
0,0,0,0,0,0,0,0,0,0,0,0,0,0,0,0,0,0,0,0,0,0,0,0
endlayer

